Workbook

Sheet תחשיב לפי שווי שומה (2)
D1: כולל מעמ ופיתוח | E1: ללא מעמ ופיתוח
I5: פיצול בית שלישי
I6: לפני - חצר | J6: =500*B12*0.25 -> 687500
A7: מ"ר אקו' נחלה היוון מלא 3 דונם | B7: ='מ"ר אקו'' נחלה'!I16 -> 1122.5 | I7: אחרי בית שלישי מפוצל | J7: =B12*435 -> 2392500
A8: מ"ר אקו' נחלה היוון מלא 2.5 דונם | B8: ='מ"ר אקו'' נחלה'!D16 -> 1366.5 | I8: השבחה | J8: =J7-J6 -> 1705000
A9: מ"ר אקו' פוטנציאל | B9: ='מ"ר אקו'' נחלה'!D30 -> 149 | I9: היטל | J9: =J8*50% -> 852500
A10: מ"ר אקו' נחלה 3.75% | B10: ='מ"ר אקו'' נחלה'!D58 -> 806.25
A11: מ"ר אקו' מגרש מפוצל | B11: ='מ"ר אקו'' נחלה'!D45 -> 354.3 | C11: מ"ר ל-29.75% | D11: ='מ"ר אקו'' נחלה'!I38 -> 245
A12: שווי מ"ר אקו' מגורים | B12: ='ניתוח איזור לעסקאות דמה'!M14 -> 5500 | C12: שווי מ"ר משרדים | D12: 2500
C13: שווי מ"ר אחסנה | D13: ='ניתוח איזור לעסקאות דמה'!#REF! -> #REF! | E13: 1.17
B14: מ"ר אקו' | C14: דמי חכירה/ פיצול | D14: עלות אקו' | E14: מע"מ | F14: בש"ח | G14: בניכוי פיתוח
A15: היוון 3.75% | B15: =B10 -> 806.25 | C15: 0.0375 | D15: =C15*B15 -> 30.234375 | E15: 1 | F15: =D15*$B$12*E15 -> 166289.06 | G15: ='מ"ר אקו'' נחלה'!D59*-3.75% -> -6562.5 | H15: =SUM(F15:G15) -> 159726.56
A16: פיצול - חלק בהנחה | B16: =D11 -> 245 | C16: 0.2925 | D16: =C16*B16 -> 71.6625 | E16: 1 | F16: =D16*$B$12*E16 -> 394143.75 | G16: =-'מ"ר אקו'' נחלה'!D46*C16 -> -29250 | H16: =SUM(F16:G16) -> 364893.75
A17: פיצול חלק ללא הנחה | B17: =B11-B16 -> 109.3 | C17: 0.33 | D17: =C17*B17 -> 36.069 | E17: 1 | F17: =D17*$B$12*E17 -> 198379.5 | G17: =G16*53/245 -> -6327.551 | H17: =SUM(F17:G17) -> 192051.95
A18: סה"כ פיצול | B18: =SUM(B16:B17) -> 354.3 | F18: =SUM(F16:F17) -> 592523.25 | H18: =SUM(H16:H17) -> 556945.7
A19: היטל השבחה על פיצול | B19: ='מ"ר אקו'' נחלה'!I38 -> 245 | C19: =30%*50% -> 0.15 | D19: =B19*C19 -> 36.75 | E19: 1 | F19: =D19*$B$12 -> 202125
A20: דמי רכישה | B20: =B8+B9 -> 1515.5 | C20: 0.33 | D20: =C20*B20 -> 500.115 | E20: 1 | F20: =D20*$B$12*E20 -> 2750632.5 | G20: =-'מ"ר אקו'' נחלה'!D17*C20 -> -81510 | H20: =SUM(F20:G20) -> 2669122.5 | K20: =H20/1.17 -> 2281301.3
A21: דמי היתר 1 מ"ר מגורים | B21: 1 | C21: 0.91 | D21: =C21*B21 -> 0.91 | E21: 1 | F21: 1486
A22: דמי היתר 1 מ"ר שירות | B22: 0.5 | C22: 0.91 | D22: =C22*B22 -> 0.455 | E22: 1 | F22: =F21/2 -> 743 | G22: =F22*G33*5%*1.17 -> 0
A23: דמי היתר 1 מ"ר מרתף | B23: 0.7 | C23: 0.91 | D23: =C23*B23 -> 0.637 | E23: 1 | F23: =D23*$B$12*E23 -> 3503.5
A24: היוון 1 מ"ר חצר נוספים | B24: 0.075 | C24: 0.91 | D24: =C24*B24 -> 0.06825 | E24: 1 | F24: =D24*$B$12*E24 -> 375.375 | J24: =F24*500 -> 187687.5
A25: דמי שימוש משרדים 1 מ"ר לשנה | B25: 1 | C25: 0.05 | D25: =C25*B25 -> 0.05 | E25: 1 | F25: =D25*$D$12*E25 -> 125
A26: דמי היתר בריכה 1 מ"ר | B26: 0.3 | C26: 0.91 | D26: =C26*B26 -> 0.273 | E26: 1 | F26: =D26*$B$12*E26 -> 1501.5
A27: דמי היתר משרד פלח | B27: 1 | C27: 0.91 | D27: =C27*B27 -> 0.91 | E27: 1 | F27: =E27*D27*$D$12 -> 2275
A28: דמי שימוש 1 מ"ר למגורים | B28: 1 | C28: 0.05 | D28: =C28*B28 -> 0.05 | E28: 1 | F28: =D28*E28*B12 -> 275
K30: =14157-310-15-191 -> 13641
A31: מחשבון רמ"י | B31: 4631 | C31: =B31*80 -> 370480 | D31: =B12*50%*5%*15 -> 2062.5 | I31: =B31*53 -> 245443
A32: דמי היתר | B32: ='חישוב גדלי בתים'!B2 -> מבנה 1 - בית ראשן גדול | C32: ='חישוב גדלי בתים'!C2 -> מבנה 2 - בית שני קטן | D32: ='חישוב גדלי בתים'!D2 -> מבנה 3 - מחסן | E32: ='חישוב גדלי בתים'!E2 -> 0 | F32: ='חישוב גדלי בתים'!F2 -> 0 | G32: ='חישוב גדלי בתים'!G2 -> 0 | H32: ='חישוב גדלי בתים'!#REF! -> #REF! | I32: =B31*0.7*32 -> 103734.4
A33: גודל בית | B33: ='חישוב גדלי בתים'!B5 -> 197.5 | C33: ='חישוב גדלי בתים'!C13 -> 100 | D33: ='חישוב גדלי בתים'!D13 -> 15.5 | E33: ='חישוב גדלי בתים'!E13 -> 0 | F33: ='חישוב גדלי בתים'!F13 -> 0 | G33: ='חישוב גדלי בתים'!G13 -> 0 | H33: ='חישוב גדלי בתים'!#REF! -> #REF!
A34: פטור | B34: 160 | C34: 160 | D34: 0 | E34: 0 | F34: 0 | G34: 0 | H34: 0
A35: מ"ר לתשלום | B35: =IF(B33-B34<0,0,B33-B34) -> 37.5 | C35: 0 | D35: =D33-D34 -> 15.5 | E35: =E33-E34 -> 0 | F35: =F33-F34 -> 0 | G35: =G33-G34 -> 0 | H35: =H33-H34 -> #REF!
A36: דמי היתר | B36: =B35*F21 -> 55725 | C36: =C35*F21 -> 0 | D36: =D35*F27 -> 35262.5 | E36: =E33*D12*91%*1.17 -> 0 | F36: =F27*F35 -> 0 | G36: =G35*G24 -> 0 | H36: =H35*H24 -> #REF!
A37: ע"פ מחשבון רמי | I37: =107*B12*5% -> 29425
A40: דמי שימוש | B40: ='חישוב גדלי בתים'!B2 -> מבנה 1 - בית ראשן גדול | C40: ='חישוב גדלי בתים'!C2 -> מבנה 2 - בית שני קטן | D40: ='חישוב גדלי בתים'!D2 -> מבנה 3 - מחסן | E40: ='חישוב גדלי בתים'!E2 -> 0 | F40: ='חישוב גדלי בתים'!F2 -> 0 | G40: ='חישוב גדלי בתים'!G2 -> 0 | H40: ='חישוב גדלי בתים'!#REF! -> #REF!
A41: גודל מבנה | B41: =B33 -> 197.5 | C41: =C33 -> 100 | D41: =D33 -> 15.5 | E41: =E33 -> 0 | F41: =F33 -> 0 | G41: =G33 -> 0 | H41: =H33 -> #REF!
A42: פטור | B42: 0 | C42: 0 | D42: 0 | E42: 0 | F42: 0 | G42: 0 | H42: =H34 -> 0
A43: מ"ר לתשלום | B43: =B41-B42 -> 197.5 | C43: =IF(C41-C42<0,0,C41-C42) -> 100 | D43: =IF(D41-D42<0,0,D41-D42) -> 15.5 | E43: =E41-E42 -> 0 | F43: =F41-F42 -> 0 | G43: =G41-G42 -> 0 | H43: =H41-H42 -> #REF!
A44: מס' שנים | B44: 2 | C44: 2 | D44: 7 | E44: 7
A45: סה"כ | C45: =C54+C53 -> 53690.476 | D45: =D55 -> 13148.598
A47: שווי 2014 | B47: =B48/1.05 -> 38598.88 | C47: =C48/1.05 -> 19543.737 | D47: =D48/1.05 -> 1376.9451 | E47: =E48/1.05 -> 0 | F47: =F48/1.05 -> #REF! | G47: =G48/1.05 -> 0 | H47: =H48/1.05 -> #REF!
...

Sheet מ"ר אקו' נחלה
A2: גודל חלקת מגורים (להיוון) | B2: 2000 | C2: ,תבע חדשה | F2: גודל חלקת מגורים (להיוון) | G2: 3000
B3: מ"ר | C3: מקדם | D3: אקו' | G3: מ"ר | H3: מקדם | I3: אקו'
A4: עיקרי | B4: 655 | C4: 1 | D4: =C4*B4 -> 655 | F4: =A4 -> עיקרי | G4: =B4 -> 655 | H4: =C4 -> 1 | I4: =H4*G4 -> 655
A5: מרחבים מוגנים | B5: 45 | C5: 0.9 | D5: =C5*B5 -> 40.5 | F5: =A5 -> מרחבים מוגנים | G5: =B5 -> 45 | H5: =C5 -> 0.9 | I5: =H5*G5 -> 40.5
A6: יתרת ש"ש | B6: =162-B5 -> 117 | C6: 0.5 | D6: =C6*B6 -> 58.5 | F6: =A6 -> יתרת ש"ש | G6: =B6 -> 117 | H6: =C6 -> 0.5 | I6: =H6*G6 -> 58.5
A7: מרתף | B7: 420 | C7: 0.7 | D7: =C7*B7 -> 294
A8: בריכת שחייה | B8: 70 | C8: 0.35 | D8: =C8*B8 -> 24.5 | F8: =A8 -> בריכת שחייה | G8: =B8 -> 70 | H8: =C8 -> 0.35 | I8: =H8*G8 -> 24.5
A9: מבנה עזר - יתרת שטח | C9: 0.5 | D9: =C9*B9 -> 0 | F9: =A9 -> מבנה עזר - יתרת שטח | G9: =B9 -> 0 | H9: =C9 -> 0.5 | I9: =H9*G9 -> 0
A10: סה"כ תכסית | B10: =SUM(B4:B9) -> 1307 | F10: סה"כ תכסית | G10: =SUM(G4:G9) -> 887
A11: סה"כ חצר | B11: =B2*61% -> 1220 | F11: סה"כ חצר | G11: =G2-G10 -> 2113
A12: חצר אפקטיבית | B12: 1000 | C12: 0.25 | D12: =C12*B12 -> 250 | F12: חצר אפקטיבית | G12: =B12 -> 1000 | H12: 0.25 | I12: =H12*G12 -> 250
A13: יתרת חצר | B13: 220 | C13: 0.2 | D13: =C13*B13 -> 44 | F13: יתרת חצר | G13: =B13 -> 220 | H13: 0.2 | I13: =H13*G13 -> 44
F14: חצר רחוקה מאוד | G14: 500 | H14: 0.1 | I14: =G14*H14 -> 50
A15: סה"כ מ"ר אקו' | B15: =SUM(B4:B13) -> 5054 | D15: =SUM(D4:D13) -> 1366.5 | F15: סה"כ מ"ר אקו' | G15: =SUM(G4:G13) -> 5107 | I15: =SUM(I4:I14) -> 1122.5
A16: סה"כ מ"ר אקו' מעוגל | D16: =D15 -> 1366.5 | F16: סה"כ מ"ר אקו' מעוגל | I16: =I15 -> 1122.5
A17: עלויות פיתוח | D17: 247000 | F17: עלויות פיתוח | I17: 263000
A19: פוטנציאל | B19: 2500 | C19: לפי ברנס
B20: מ"ר | C20: מקדם | D20: אקו'
A21: עיקרי | B21: 85 | C21: 1 | D21: =C21*B21 -> 85
A22: ממ"ד | B22: 12 | C22: 0.9 | D22: =C22*B22 -> 10.8
A23: ש"ש עיליים | B23: 47.5 | C23: 0.5 | D23: =C23*B23 -> 23.75
A24: ש"ש תת"ק | B24: 180 | C24: 0.3 | D24: =C24*B24 -> 54
H26: =876+73 -> 949
A27: הפסד חצר שולית | B27: -145 | C27: 0.2 | D27: =B27*C27 -> -29 | H27: =H26+137 -> 1086
A29: דחיה למימוש
A30: סה"כ מ"ר אקו' מעוגל | D30: 149
A34: מגרש מפוצל
A35: גודל מגרש | B35: 500 | C35: לפי שומת זיו כהן בשפיר | F35: חלק ה29.25% | J35: שויי מ"ר
A36: מגורים עיקרי בהרחבה | B36: 220 | C36: 1 | D36: =B36*C36 -> 220 | F36: =A36 -> מגורים עיקרי בהרחבה | G36: 160 | H36: 1 | I36: =G36*H36 -> 160
A37: שירות - מרתף | B37: 70 | C37: 0.7 | D37: =B37*C37 -> 49 | F37: חצר | G37: =500-G36 -> 340 | H37: 0.25 | I37: =G37*H37 -> 85
A38: מרחבים מוגנים | B38: 12 | C38: 0.9 | D38: =B38*C38 -> 10.8 | F38: מ"ר אקו' שנכלל בהנחה | I38: =I36+I37 -> 245 | J38: ='תחשיב לפי שווי שומה (2)'!B12 -> 5500 | K38: =I38*J38 -> 1347500 | L38: 0.2925 | M38: =K38*L38 -> 394143.75
A39: מסחן | C39: 0.5 | D39: =B39*C39 -> 0 | F39: מ"ר אקו' שלא נכלל בהנחה | I39: =D45-I38 -> 109.3 | J39: =J38 -> 5500 | K39: =I39*J39 -> 601150 | L39: 0.33 | M39: =K39*L39 -> 198379.5
A40: סככת חניה | C40: 0.3 | D40: =B40*C40 -> 0 | M40: =SUM(M38:M39) -> 592523.25
A41: מבנה עזר - יתרת שטח | B41: 30 | C41: 0.5 | D41: =B41*C41 -> 15
A42: סה"כ תכסית | B42: =SUM(B36:B41)-B37 -> 262
A43: סה"כ חצר | B43: =B35-B42 -> 238
A44: חצר אפקטיבית | B44: =B43 -> 238 | C44: 0.25 | D44: =B44*C44 -> 59.5
A45: סה"כ מ"ר אקו' | D45: =SUM(D36:D44) -> 354.3
A46: הוצאות פיתוח | D46: 100000
A48: לפי שומת הררי 2021 | B48: 2500 | F48: =A48 -> לפי שומת הררי 2021 | G48: 3000
...

Sheet ניתוח איזור לעסקאות דמה
B2: שומות
B3: שווי מ"ר אקו'
B4: אחוז שנתי
B5: שנים להיוון
B6: שווי עדכני
B9: תחשיב לפי מכירות בהרחבה
B10: תאריך | C10: גו"ח | D10: מחיר עסקה | E10: שטח המגרש | F10: שטח בנוי | G10: שנת בניה | H10: התאמה למועד קובע | I10: בניכוי יזמי 15% | J10: עלויות בניה למ"ר | K10: יתרה לקרע כולל | L10: שטח אקו' | M10: שווי מתואם כולל מעמ ופיתוח
B11: 44725 | C11: 5986-54 | D11: 3550000 | E11: 500 | F11: 143 | G11: 2018 | H11: =D11*1.05 -> 3727500 | I11: =H11*0.85 -> 3168375 | J11: =F11*7000 -> 1001000 | K11: =I11-J11 -> 2167375 | L11: =E25 -> 435 | M11: =K11/L11 -> 4982.4713
B12: 44340 | C12: 5986-85 | D12: 3200000 | E12: 500 | F12: 240 | G12: 2012 | H12: =D12*1.1 -> 3520000 | I12: =H12*0.85 -> 2992000 | J12: =F12*5000 -> 1200000 | K12: =I12-J12 -> 1792000 | L12: =E33 -> 435 | M12: =K12/L12 -> 4119.5402
L14: לשומה | M14: 5500
E16: שווי פל"ח לפי שומה מייצגת באביגדור
B19: תבע בר/4/282 | C19: 5986-54
B20: גודל מגרש | C20: =E11 -> 500
B21: עיקרי | C21: 200 | D21: 1 | E21: =C21*D21 -> 200
B22: שרות | C22: 40 | D22: 0.5 | E22: =C22*D22 -> 20
B23: מרתף | C23: 200 | D23: 0.7 | E23: =C23*D23 -> 140
B24: חצר | C24: =C20*60% -> 300 | D24: 0.25 | E24: =C24*D24 -> 75
B25: סה"כ | E25: =SUM(E21:E24) -> 435
B27: תבע בר/4/282 | C27: =C12 -> 5986-85
B28: גודל מגרש | C28: =E12 -> 500
B29: עיקרי | C29: 200 | D29: 1 | E29: =C29*D29 -> 200
B30: שרות | C30: 40 | D30: 0.5 | E30: =C30*D30 -> 20
B31: מרתף | C31: 200 | D31: 0.7 | E31: =C31*D31 -> 140
B32: חצר | C32: =C28*60% -> 300 | D32: 0.25 | E32: =C32*D32 -> 75
B33: סה"כ | E33: =SUM(E29:E32) -> 435

Sheet חישוב גדלי בתים
A2: קיים | B2: מבנה 1 - בית ראשן גדול | C2: מבנה 2 - בית שני קטן | D2: מבנה 3 - מחסן
A3: מפת מדידה - קונטור | B3: 197.5 | C3: 100 | D3: 15.5
A4: קומת עמודים
A5: שטחי מגורים - קרקע | B5: 197.5
A6: פרגלה אחורית | B6: 41
A7: פרגולה קדמית | B7: 14
A8: פרגולה צידית | B8: 6
A9: סככה
A10: שרות (ממ"ד)
A11: קומת עמודים בהיתר
A12: קומת עמודים ללא היתר
A13: סה"כ מבנה | B13: =SUM(B4:B12) -> 258.5 | C13: =SUM(C3:C12) -> 100 | D13: =SUM(D3:D12) -> 15.5 | G13: =SUM(G3:G12) -> 0 | H13: =SUM(H3:H12) -> 0 | I13: =SUM(I3:I12) -> 0 | J13: =SUM(J3:J12) -> 0 | K13: =SUM(K3:K12) -> 0 | L13: =SUM(L3:L12) -> 0 | M13: =SUM(M3:M12) -> 0 | N13: =SUM(N3:N12) -> 0 | ... Q13: =SUM(Q3:Q12) -> 0
A14: בהיתר
A16: 2009 - בית מגוים | B16: 200
A17: 2009 - בית מגוים קומה ב' | B17: 52
A18: בית מגורים ומחסן 2011 | C18: =90+12 -> 102 | D18: 15
A24: בהתר | B24: =SUM(B16:B23) -> 252 | C24: =SUM(C17:C23) -> 102 | D24: =SUM(D15:D23) -> 15 | E24: =SUM(E15:E23) -> 0 | F24: =SUM(F15:F23) -> 0 | G24: =SUM(G15:G23) -> 0 | H24: =SUM(H15:H23) -> 0 | I24: =SUM(I15:I23) -> 0 | J24: =SUM(J15:J23) -> 0 | K24: =SUM(K15:K23) -> 0 | ... Q24: =SUM(Q15:Q23) -> 0
A25: פערים | B25: =B13-B24 -> 6.5 | C25: =C13-C24 -> -2 | D25: =D13-D24 -> 0.5 | E25: =E13-E24 -> 0 | F25: =F13-F24 -> 0 | G25: =G13-G24 -> 0 | H25: =H13-H24 -> 0 | I25: =I13-I24 -> 0 | ... Q25: =Q13-Q24 -> 0
C26: חרגיה מקו בנין צידי | E26: חרגיה מקו בנין צידי | F26: חרגיה מקו בנין צידי | G26: חרגיה מקו בנין צידי
A27: פער מרפסות | B27: =B8+B7 -> 20
C28: =C3*9300*5%*7 -> 325500 | E28: =E3*9300*5%*2 -> 0 | F28: =F3*9300*5%*7 -> 0 | I28: =100*9300*5%*7 -> 325500
C29: =375-C24-D24-G24 -> 258 | E29: =E9*9300*5%*2/2 -> 0 | F29: =F9*9300*5%*7/2 -> 0
I30: =375-208 -> 167 | L30: =375-B3-E3 -> 177.5 | M30: =100-L30 -> -77.5
A31: דמי היתר ששולמו | L31: =6605*(100-31) -> 455745
A32: בית 1 | C32: =-B13 -> -258.5 | F32: =375-B13-C13 -> 16.5
A33: בית 2 | C33: =-C13 -> -100 | E33: =375-240 -> 135
A34: מחסן | C34: =G24 -> 0
A35: סה"כ | C35: =SUM(C31:C34) -> -358.5
A36: היוון 3.75 | C36: 375 | J36: =1500*0.5*5%*1000 -> 37500
A37: סה"כ מטרים | C37: =SUM(C35:C36) -> 16.5
A38: קיים | C38: =-C24-D24-G24 -> -117
A39: נותרו לבניה | C39: =SUM(C37:C38) -> -100.5
E40: בר-רשות | F40: בית 1 | G40: בית 2
F41: 308 | G41: 160
E42: פטור | F42: -201 | G42: -160
A43: פערים בית מגורים | E43: לתשלום | F43: =SUM(F41:F42) -> 107 | G43: =SUM(G41:G42) -> 0
A44: קומה תחתונה | B44: היתר | C44: בפועל | D44: הפרש | E44: בכסף | F44: =F43*'תחשיב לפי שווי שומה (2)'!$B$31 -> 495517 | G44: =G43*'תחשיב לפי שווי שומה (2)'!C31 -> 0
A45: מגורים | B45: =105.54 -> 105.54 | C45: 130 | D45: =C45-B45 -> 24.46
A46: מקלט | C46: 0 | D46: =C46-B46 -> 0 | E46: חוכר ושילם | F46: בית 1 | G46: בית 2 | H46: סה"כ
A47: סה"כ קומת קרקע | B47: =SUM(B45:B46) -> 105.54 | C47: =SUM(C45:C46) -> 130 | D47: =C47-B47 -> 24.46 | F47: 308 | G47: 160 | H47: =SUM(F47:G47) -> 468
...

Sheet גיליון1
B2: טבלאת סיכום עלויות דמי שימוש
B3: דמי שימוש | C3: מגורים | E3: פרגולות
B4: בית ראשון - מבנה 1 | C4: 0 | E4: 0
B5: בית שני - מבנה 4 | C5: 140000 | E5: =6000*2 -> 12000
B6: בית שלישי - מבנה 1 עבור 100 מ"ר | C6: =46500*7 -> 325500 | E6: 0
B7: בית רביעי - מבנה 2 | C7: =13000*7 -> 91000 | E7: =4000*7 -> 28000
B8: בית חמישי - מבנה 5 | C8: =65000*7 -> 455000 | E8: 50000
B9: טבלאת סיכום עלויות הסדרה
B10: דמי היתר - להסדרה | C10: מ"ר לתש' עיקרי | D10: תשלום עיקרי | E10: מ"ר פרגולות | F10: תשלום פרגולות
B11: בית ראשון - מבנה 1 | C11: =197-160 -> 37 | D11: =C11*6605 -> 244385 | E11: 35 | F11: =E11*6605/2 -> 115587.5
B12: בית שני - מבנה 4 | C12: 0 | D12: 0 | E12: =147+24-160 -> 11 | F12: =E12*6605/2 -> 36327.5
B13: בית שלישי - מבנה 1 | C13: יוסדר כמבנה אחד עם הבית הראשון
B14: בית רביעי - מבנה 2 | C14: מומלץ לפינוי / הסרה
B15: בית חמישי - מבנה 5 | C15: יוסדר כבית שלישי - יוצג מטה
B17: טבלאת סיכום עלויות
B18: דמי שימוש - 7 שנים | C18: מגורים | E18: פרגולות
B19: בית ראשון - מבנה 1 | C19: 0 | E19: 0
B20: בית שני - מבנה 4 | C20: 70000 | E20: =6000*7 -> 42000
B21: בית שלישי - מבנה 1 | C21: =46500*7 -> 325500 | E21: 0
B22: בית רביעי - מבנה 2 | C22: =13000*7 -> 91000 | E22: =4000*7 -> 28000
B23: בית חמישי - מבנה 5 | C23: =65000*7 -> 455000 | E23: =7000*7 -> 49000
B25: דמי היתר - להסדרה | C25: מ"ר לתש' עיקרי | D25: תשלום עיקרי | E25: מ"ר פרגולות | F25: תשלום פרגולות
B26: בית ראשון - מבנה 1 | C26: =197-160 -> 37 | D26: =C26*6605 -> 244385 | E26: 35 | F26: =E26*6605/2 -> 115587.5
B27: בית שני - מבנה 4 | C27: 0 | D27: =C27*6605 -> 0 | E27: =147+24-160 -> 11 | F27: =E27*6605/2 -> 36327.5
B28: בית שלישי - מבנה 1 | C28: יוסדר כמבנה אחד עם הבית הראשון
B29: בית רביעי - מבנה 2 | C29: 0 | D29: 0 | E29: 0 | F29: 0
B30: בית חמישי - מבנה 5 | C30: 0 | D30: 0 | E30: =139+31-160 -> 10 | F30: =E30*6605/2 -> 33025
B35: טבלאת סיכום עלויות בית שלישי
B36: הדרך אל הבית השלישי | C36: מגורים | E36: פרגולות
B37: עלויות הסדרה | C37: ע"פ שלב 1 - 1,100,000 ₪
B38: היוון 3.75% דמי חכירה | C38: ע"פ שלב 2 - 260,000 ₪
B39: תב"ע | C39: שכ"ט בעלי מקצוע
B40: היתר בניה - דמי היתר | C40: דמי היתר 455,000 ₪ + היטל השבחה
