Workbook

Sheet תחשיב לפי שווי שומה (2)
A2: מ"ר אקו' נחלה היוון מלא 3 דונם | B2: ='מ"ר אקו'' נחלה'!I15 -> 905
A3: מ"ר אקו' נחלה היוון מלא 2.5 דונם | B3: ='מ"ר אקו'' נחלה'!D15 -> 910
A4: מ"ר אקו' פוטנציאל | B4: ='מ"ר אקו'' נחלה'!D28 -> 164.26834
A5: מ"ר אקו' נחלה 3.75% | B5: ='מ"ר אקו'' נחלה'!D56 -> 806.25
A6: מ"ר אקו' מגרש מפוצל | B6: ='מ"ר אקו'' נחלה'!D43 -> 286.8 | C6: מ"ר ל-29.75% | D6: ='מ"ר אקו'' נחלה'!I36 -> 245
A7: שווי מ"ר אקו' מגורים | B7: 8000 | C7: שווי מ"ר משרדים | D7: 2500
C8: שווי מ"ר אחסנה | D8: ='ניתוח איזור לעסקאות דמה'!#REF! -> #REF! | E8: 1.17
B9: מ"ר אקו' | C9: דמי חכירה/ פיצול | D9: עלות אקו' | E9: מע"מ | F9: בש"ח | G9: בניכוי פיתוח
A10: היוון 3.75% | B10: =B5 -> 806.25 | C10: 0.0375 | D10: =C10*B10 -> 30.234375 | E10: 1 | F10: =D10*$B$7*E10 -> 241875 | G10: ='מ"ר אקו'' נחלה'!D57*-3.75% -> -6562.5 | H10: =SUM(F10:G10) -> 235312.5
A11: פיצול - חלק בהנחה | B11: =D6 -> 245 | C11: 0.2925 | D11: =C11*B11 -> 71.6625 | E11: 1 | F11: =D11*$B$7*E11 -> 573300 | G11: =-'מ"ר אקו'' נחלה'!D44*C11 -> -29250 | H11: =SUM(F11:G11) -> 544050
A12: פיצול חלק ללא הנחה | B12: =B6-B11 -> 41.8 | C12: 0.33 | D12: =C12*B12 -> 13.794 | E12: 1 | F12: =D12*$B$7*E12 -> 110352 | G12: =G11*53/245 -> -6327.551 | H12: =SUM(F12:G12) -> 104024.45
A13: סה"כ פיצול | B13: =SUM(B11:B12) -> 286.8 | F13: =SUM(F11:F12) -> 683652 | H13: =SUM(H11:H12) -> 648074.45
A14: היטל השבחה על פיצול | B14: ='מ"ר אקו'' נחלה'!I36 -> 245 | C14: =C35 -> 0.425 | D14: =B14*C14 -> 104.125 | E14: 1 | F14: =D14*$B$7 -> 833000
A15: דמי רכישה | B15: =B3+B4 -> 1074.2683 | C15: 0.33 | D15: =C15*B15 -> 354.50855 | E15: 1 | F15: =D15*$B$7*E15 -> 2836068.4 | G15: =-'מ"ר אקו'' נחלה'!D16*C15 -> -81510 | H15: =SUM(F15:G15) -> 2754558.4
A16: דמי רכישה 20% | B16: =B4+B3 -> 1074.2683 | C16: 0.2 | D16: =C16*B16 -> 214.85367 | E16: 1 | F16: =D16*$B$7*E16 -> 1718829.4 | G16: =-C16*'מ"ר אקו'' נחלה'!D16 -> -49400 | H16: =SUM(F16:G16) -> 1669429.4
A17: דמי היתר 1 מ"ר מגורים | B17: 1 | C17: 0.91 | D17: =C17*B17 -> 0.91 | E17: 1 | F17: 1486
A18: דמי היתר 1 מ"ר שירות | B18: 0.5 | C18: 0.91 | D18: =C18*B18 -> 0.455 | E18: 1 | F18: =F17/2 -> 743 | G18: =F18*#REF!*5%*1.17 -> #REF!
A19: דמי היתר 1 מ"ר מרתף | B19: 0.7 | C19: 0.91 | D19: =C19*B19 -> 0.637 | E19: 1 | F19: =D19*$B$7*E19 -> 5096
A20: היוון 1 מ"ר חצר נוספים | B20: 0.075 | C20: 0.91 | D20: =C20*B20 -> 0.06825 | E20: 1 | F20: =D20*$B$7*E20 -> 546
A21: דמי שימוש משרדים 1 מ"ר לשנה | B21: 1 | C21: 0.05 | D21: =C21*B21 -> 0.05 | E21: 1 | F21: =D21*$D$7*E21 -> 125
A22: דמי היתר בריכה 1 מ"ר | B22: 0.3 | C22: 0.91 | D22: =C22*B22 -> 0.273 | E22: 1 | F22: =D22*$B$7*E22 -> 2184
A23: דמי היתר משרד פלח | B23: 1 | C23: 0.91 | D23: =C23*B23 -> 0.91 | E23: 1 | F23: =E23*D23*$D$7 -> 2275
A24: דמי שימוש 1 מ"ר למגורים | B24: 1 | C24: 0.05 | D24: =C24*B24 -> 0.05 | E24: 1 | F24: =D24*E24*B7 -> 400
A27: מחשבון רמ"י
A29: היטל השבחה פיצול בית שלישי (מגרש ראשון)
B30: עבור מגרש 350 | C30: מקדם | D30: עבור 1 מ"ר אקו'
A31: אחרי מגרש מפוצל | B31: ='מ"ר אקו'' נחלה'!D43*'תחשיב לפי שווי שומה (2)'!$B$7 -> 2294400 | C31: 1 | D31: =C31*$B$7 -> 8000
A32: לפני חצר שולית | B32: =350*$B$7*C32 -> 420000 | C32: 0.15 | D32: =C32*$B$7 -> 1200
A34: השבחה | B34: =B31-B32 -> 1874400 | C34: =C31-C32 -> 0.85 | D34: =C34*$B$7 -> 6800
A35: היטל | B35: =B34*50% -> 937200 | C35: =C34*50% -> 0.425 | D35: =C35*$B$7 -> 3400
A37: היטל השבחה פיצול בית שני (מגרש שני)
B38: עבור מגרש 350 | C38: מקדם | D38: עבור 1 מ"ר אקו'
A39: אחרי מגרש מפוצל | B39: ='מ"ר אקו'' נחלה'!D43*'תחשיב לפי שווי שומה (2)'!$B$7 -> 2294400 | C39: 1 | D39: =C39*$B$7 -> 8000
A40: לפני מגרש לא מפוצל | B40: =B39*70% -> 1606080 | C40: 0.7 | D40: =C40*$B$7 -> 5600
A42: השבחה | B42: =B39-B40 -> 688320 | C42: =C39-C40 -> 0.3 | D42: =C42*$B$7 -> 2400
A43: היטל | B43: =B42*50% -> 344160 | C43: =C42*50% -> 0.15 | D43: =C43*$B$7 -> 1200

Sheet מ"ר אקו' נחלה
A2: גודל חלקת מגורים (להיוון) | B2: 2500 | C2: לפי שומת חכמון | F2: גודל חלקת מגורים (להיוון) | G2: 3000
B3: מ"ר | C3: מקדם | D3: אקו' | G3: מ"ר | H3: מקדם | I3: אקו'
A4: עיקרי | B4: 345 | C4: 1 | D4: =C4*B4 -> 345 | F4: =A4 -> עיקרי | G4: =B4 -> 345 | H4: =C4 -> 1 | I4: =H4*G4 -> 345
A5: יחידת הורים | B5: 55 | C5: 1 | D5: =C5*B5 -> 55
A6: מרחבים מוגנים | B6: 25 | C6: 0.9 | D6: =C6*B6 -> 22.5 | F6: =A6 -> מרחבים מוגנים | G6: =B6 -> 25 | H6: =C6 -> 0.9 | I6: =H6*G6 -> 22.5
A7: יתרת ש"ש | B7: 90 | C7: 0.45 | D7: =C7*B7 -> 40.5 | F7: =A7 -> יתרת ש"ש | G7: =B7 -> 90 | H7: =C7 -> 0.45 | I7: =H7*G7 -> 40.5
A8: מבנה עזר - יתרת שטח | C8: 0.5 | D8: =C8*B8 -> 0 | F8: =A8 -> מבנה עזר - יתרת שטח | G8: =B8 -> 0 | H8: =C8 -> 0.5 | I8: =H8*G8 -> 0
A9: סה"כ תכסית | B9: =SUM(B4:B8) -> 515 | F9: סה"כ תכסית | G9: =SUM(G4:G8) -> 460
A10: סה"כ חצר | B10: =B2-B9 -> 1985 | F10: סה"כ חצר | G10: =G2-G9 -> 2540
A11: חצר אפקטיבית | B11: 1000 | C11: 0.25 | D11: =C11*B11 -> 250 | F11: חצר אפקטיבית | G11: =B11 -> 1000 | H11: 0.25 | I11: =H11*G11 -> 250
A12: יתרת חצר | B12: =B10-B11 -> 985 | C12: 0.2 | D12: =C12*B12 -> 197 | F12: יתרת חצר | G12: =B12 -> 985 | H12: 0.2 | I12: =H12*G12 -> 197
F13: חצר רחוקה מאוד | G13: 500 | H13: 0.1 | I13: =G13*H13 -> 50
A14: סה"כ מ"ר אקו' | B14: =SUM(B4:B12) -> 5000 | D14: =SUM(D4:D13) -> 910 | F14: סה"כ מ"ר אקו' | G14: =SUM(G4:G12) -> 5445 | I14: =SUM(I4:I13) -> 905
A15: סה"כ מ"ר אקו' מעוגל | D15: =D14 -> 910 | F15: סה"כ מ"ר אקו' מעוגל | I15: =I14 -> 905
A16: עלויות פיתוח | D16: 247000 | F16: עלויות פיתוח | I16: 263000
A18: פוטנציאל | B18: 2500 | D18: 350
B19: מ"ר | C19: מקדם | D19: אקו'
A20: עיקרי | B20: 220 | C20: 1 | D20: =C20*B20 -> 220
A21: ממ"ד | B21: 12 | C21: 0.9 | D21: =C21*B21 -> 10.8
A22: ש"ש עיליים | B22: 38 | C22: 0.5 | D22: =C22*B22 -> 19
A23: תכסית 45% | B23: =D18*-0.45 -> -157.5 | C23: 0.2 | D23: =C23*B23 -> -31.5
A24: חצר | H24: =876+73 -> 949
A25: סה"כ מ"ר אקו' מעוגל | D25: =SUM(D20:D24) -> 218.3
A26: דחיה למימוש | D26: =1/1.06^4 -> 0.79209366
A27: עורפיות | D27: 0.95
A28: סה"כ מ"ר אקו' מעוגל | D28: =D25*D26*D27 -> 164.26834
A32: מגרש מפוצל הרחבת אביגדור רק במקום 180 220 עיקרי
A33: גודל מגרש | B33: 350 | C33: לפי שומת זיו כהן בשפיר | F33: חלק ה29.25% | J33: שויי מ"ר
A34: מגורים עיקרי בהרחבה | B34: 220 | C34: 1 | D34: =B34*C34 -> 220 | F34: =A34 -> מגורים עיקרי בהרחבה | G34: 160 | H34: 1 | I34: =G34*H34 -> 160
A35: שירות - מרתף | B35: 40 | C35: 0.5 | D35: =B35*C35 -> 20 | F35: חצר | G35: =500-G34 -> 340 | H35: 0.25 | I35: =G35*H35 -> 85
A36: מרחבים מוגנים | B36: 12 | C36: 0.9 | D36: =B36*C36 -> 10.8 | F36: מ"ר אקו' שנכלל בהנחה | I36: =I34+I35 -> 245 | J36: ='תחשיב לפי שווי שומה (2)'!B7 -> 8000 | K36: =I36*J36 -> 1960000 | L36: 0.2925 | M36: =K36*L36 -> 573300
A37: מסחן | B37: 11 | C37: 0.5 | D37: =B37*C37 -> 5.5 | F37: מ"ר אקו' שלא נכלל בהנחה | I37: =D43-I36 -> 41.8 | J37: =J36 -> 8000 | K37: =I37*J37 -> 334400 | L37: 0.33 | M37: =K37*L37 -> 110352
A38: סככת חניה | B38: 30 | C38: 0.35 | D38: =B38*C38 -> 10.5 | M38: =SUM(M36:M37) -> 683652
A39: מבנה עזר - יתרת שטח | C39: 0.5 | D39: =B39*C39 -> 0
A40: סה"כ תכסית | B40: =SUM(B34:B39)-B35 -> 273
A41: סה"כ חצר | B41: =B33-B40 -> 77
A42: חצר אפקטיבית | B42: 80 | C42: 0.25 | D42: =B42*C42 -> 20
A43: סה"כ מ"ר אקו' | D43: =SUM(D34:D42) -> 286.8
A44: הוצאות פיתוח | D44: 100000
A46: לפי שומת הררי 2021 | B46: 2500 | F46: =A46 -> לפי שומת הררי 2021 | G46: 3000
...

Sheet ניתוח איזור לעסקאות דמה
B2: שומת
B3: שווי מ"ר אקו' | C3: =E27 -> 6850
B4: אחוז שנתי
B5: שנים להיוון
B6: שווי עדכני | C6: =E28 -> 6165
B7: שווי לשומה | C7: =E29 -> 7500
B9: תחשיב לפי מכירות בהרחבה
B10: תאריך | C10: גו"ח | D10: מחיר עסקה | E10: שטח המגרש | F10: שטח בנוי | G10: שנת בניה | H10: התאמה למועד קובע | I10: בניכוי יזמי 5% | J10: עלויות בניה למ"ר | K10: יתרה לקרע כולל | L10: שטח אקו' | M10: שווי מתואם כולל מעמ ופיתוח
C25: שווי למועד קובע 07/23 | E25: 6400
C26: מקדם זמן 7% | E26: =E25*1.07 -> 6848
C27: במעוגל | E27: 6850
C28: עדכני | E28: =E27*0.9 -> 6165
C29: לשומה | E29: 7500
B39: מסד | C39: גוש חלקה | D39: יום מכירה | E39: תמורה מוצהרת בש"ח | F39: בניכוי יזמות שחוקה 3% | G39: מהות | H39: חלק נמכר | I39: ישוב | J39: שנת בניה | K39: שטח | L39: שטח חלקה | M39: תרומת הבנוי | N39: שווי יתרת מגרש | O39: שווי מ"ר מבונה אקו'
B40: 1 | C40: 000884-0045-000-00 | D40: 45615 | E40: 3700000 | F40: =E40/1.03 -> 3592233 | G40: קוטג' חד משפחתי | H40: 1 | I40: גן הדרום | J40: 1985 | K40: 155 | L40: 755 | M40: =K40*5000 -> 775000 | N40: =F40-M40 -> 2817233 | O40: =F56 -> 7101.6713
B41: 2 | C41: 000883-0119-000-00 | D41: 45532 | E41: 2790000 | F41: =E41 -> 2790000 | G41: ללא תיכנון | H41: 1 | I41: גן הדרום | J41: 0 | K41: 500 | L41: 500 | M41: 0 | N41: =F41-M41 -> 2790000 | O41: =F70 -> 7261.8428
N42: ממוצע | O42: =AVERAGE(O40:O41) -> 7181.7571
N43: לנחלה | O43: =O42*0.85 -> 6104.4935
N44: לשומה | O44: 7000
C47: ניתוח שטח אקו' מס"ד 1
C48: מהות | D48: שטח | E48: מקדם | F48: סה"כ | G48: שטח מגרש
C49: עיקרי ק.ק | D49: =220/2-6 -> 104 | E49: 1 | F49: =E49*D49 -> 104 | G49: =L40 -> 755
C50: ממ"ד | D50: 12 | E50: 1 | F50: =E50*D50 -> 12
C51: עיקרי ק.א | D51: =220-D49 -> 116 | E51: 1 | F51: =E51*D51 -> 116
C52: יתרת ש"ש | D52: =45-D50 -> 33 | E52: 0.4 | F52: =E52*D52 -> 13.2
C53: חצר | D53: =G49-D49-D50-D52 -> 606 | E53: 0.25 | F53: =E53*D53 -> 151.5
C54: סה"כ שטח אקו' | F54: =SUM(F49:F53) -> 396.7
C55: שווי מגרש | F55: =N40 -> 2817233
C56: שווי מ"ר | F56: =F55/F54 -> 7101.6713
C60: ניתוח שטח אקו' מס"ד 1
C61: מהות | D61: שטח | E61: מקדם | F61: סה"כ | G61: שטח מגרש
C62: עיקרי ק.ק | D62: =220/2-6 -> 104 | E62: 1 | F62: =E62*D62 -> 104 | G62: =L41 -> 500
C63: ממ"ד | D63: 12 | E63: 1 | F63: =E63*D63 -> 12
C64: עיקרי ק.א | D64: =220-D62 -> 116 | E64: 1 | F64: =E64*D64 -> 116
C65: יתרת ש"ש | D65: =60-D63 -> 48 | E65: 0.4 | F65: =E65*D65 -> 19.2
C66: מרתף | D66: 70 | E66: 0.7 | F66: =E66*D66 -> 49
C67: חצר | D67: =G62-D62-D63-D65 -> 336 | E67: 0.25 | F67: =E67*D67 -> 84
C68: סה"כ שטח אקו' | F68: =SUM(F62:F67) -> 384.2
C69: שווי מגרש | F69: =N41 -> 2790000
C70: שווי מ"ר | F70: =F69/F68 -> 7261.8428

Sheet סיכום עלויות הסדרה
E3: תשלומים לרשות מקרקעי ישראל בעת הסדרה
E4: סוג תשלום | F4: אפשרות א' | J4: אפשרות ב'
F5: הסדרת בית ראשון במצבו הנוכחי | H5: הסדרת בית שני במצבו הנוכחי | J5: הסדרת הבית הראשון כשני בתים | L5: הסדרת בית שני נוכחי כמבנה חקלאי
E7: דמי היתר | F7: 400000 | H7: - | J7: - | L7: -
E9: חשיפה לדמי שימוש | F9: - | H9: =40000*2 -> 80000 | J9: - | L9: =40000*2 -> 80000
E11: פתרון מיגון | F11: V | H11: V | J11: V | L11: X
E13: סה"כ | F13: =H9+F7 -> 480000 | J13: =L9 -> 80000

Sheet חישוב תשלום דמי הסכמה
D37: חלופה א' | S37: חלופה ב'
G38: מדד המחירים לצרכן | S38: שווי מ"ר בנוי 2017 | T38: =6500/1.07^7 -> 4047.8733
D39: תאריך רכישה | E39: מחיר רכישה | F39: מחיר רכישה בשקל | G39: מדד ל-09/06/2017 | H39: מחיר רכישה ממודד | S39: 375 מ"ר בנוי | T39: =T38*375 -> 1517952.5
D40: 38147 | E40: 410000 | F40: =E40*4.524 -> 1854840 | G40: 1.23 | H40: =F40*G40 -> 2281453.2 | S40: שווי יתרת חצר | T40: =54600 -> 54600
S41: מבני מגורים | T41: =200000 -> 200000
D42: תאריך מכירה | H42: מחיר מכירה | S42: 27 דונם חקלאי | T42: =27*6000 -> 162000
D43: 42895 | H43: 5000000 | S43: סה"כ | T43: =SUM(T39:T42) -> 1934552.5
D45: עליית ערך המקרקעין | H45: =H43-H40 -> 2718546.8 | S45: מחיר מכירה | T45: =5000000 -> 5000000
D46: תשלום דמי הסכמה 1/3 מעליית ערך המקרקעין | H46: =H45/3 -> 906182.27 | S46: פער | T46: =T45-T43 -> 3065447.5
D47: שווי היסודי של הנחלה במקדם 2% | H47: =615000*0.02 -> 12300 | S47: תשלום 33% | T47: =T46/3 -> 1021815.8
D48: סה"כ | H48: =H47+H46 -> 918482.27 | S48: שווי יסודי של הנחלה במקדם 2% | T48: =615000*0.02 -> 12300
S49: סה"כ | T49: =T48+T47 -> 1034115.8
D56: התמורה | E56: 5000000
D57: התמורה הקודמת | E57: =H40 -> 2281453.2
D58: מחיר יסודי | E58: אין
D59: מחיר יסודי מזערי | E59: 614600
E62: תמורה | F62: יסודי מזערי
D63: ה1 | E63: =E56 -> 5000000 | F63: =E59 -> 614600 | G63: לא קורה
E65: תמורה | F65: יסודי מזערי
D66: ה2 | E66: =E56 -> 5000000 | F66: =E59 -> 614600 | G66: תנאי 1 מוץ 2 קורה
E68: תמורה | F68: תמורה קודמת
E69: =E56 -> 5000000 | F69: =E57 -> 2281453.2 | G69: תנאי 2 מתוך 2 לא קורה
E71: תמורה | F71: מחיר יסודי
E72: =E56 -> 5000000 | F72: אין | G72: לא ניתן לדעת
D74: ה3 | E74: תמורה | F74: יסודי מזערי
E75: =E56 -> 5000000 | F75: =E59 -> 614600 | G75: קורה 1/3
E77: תמורה | F77: תמורה קודמת
E78: =$E$56 -> 5000000 | F78: =E57 -> 2281453.2 | G78: קורה 2/3
E80: תמורה | F80: מחיר יסודי
E81: =$E$56 -> 5000000 | F81: אין | G81: לא ניתן לדעת | H81: הנחנו שכן
D83: אז: | E83: מחיר יסודי
D84: 0.02 | E84: =E59 -> 614600 | F84: =D84*E84 -> 12292
D86: +
E88: תמורה | F88: תמורה קודמת | G88: הפרש | H88: שיעור תשלון
E89: =E56 -> 5000000 | F89: =E57 -> 2281453.2 | G89: =E89-F89 -> 2718546.8 | H89: =1/3 -> 0.33333333 | I89: =H89*G89 -> 906182.27
E92: סה"כ | H92: תשלום דמי הסכמה | I92: =I89+F84 -> 918474.27

Sheet דמי הסכמה
C3: נוהל רמ"י לחישוב דמי הסכמה 37.02B שמפנה לנספח 5 בו
G6: ערכים
G7: התמורה | H7: 5000000
G8: התמורה הקודמת | H8: ='חישוב תשלום דמי הסכמה'!H40 -> 2281453.2
G9: מחיר יסודי | H9: X
G10: מחיר יסודי מזערי | H10: 615000
Q12: החלטה 534 רמ"י
G15: ביאור ה.1
G16: התמורה | H16: 5000000
G17: מחיר יסודי מזערי | H17: =H10 -> 615000
G18: לא מתקיים
G20: ביאור ה.2
G21: התמורה | H21: 5000000
G22: מחיר יסודי | H22: לא ידוע
G23: מחיר יסודי מזערי | H23: =H10 -> 615000
G24: תמורה קודמת | H24: =H8 -> 2281453.2
G25: לא מתקיים
G27: ביאור ה.3
G28: התמורה | H28: 5000000
G29: מחיר יסודי | H29: לא ידוע
G30: מחיר יסודי מזערי | H30: =H17 -> 615000
G31: תמורה קודמת | H31: =H8 -> 2281453.2
G32: מניח שמתקיים
G34: סיכום תשלום דמי הסכמה ע"פ סעיף ה.3
J35: מדד המחירים לצרכן
G36: תאריך רכישה | H36: מחיר רכישה | I36: מחיר רכישה בשקל | J36: מדד ל-09/06/2017 | K36: מחיר רכישה ממודד
G37: 38147 | H37: 410000 | I37: =H37*4.524 -> 1854840 | J37: 1.23 | K37: =I37*J37 -> 2281453.2
G38: תאריך מכירה | K38: מחיר מכירה
G39: 42895 | K39: 5000000
G40: עליית ערך המקרקעין | K40: =K39-K37 -> 2718546.8
G41: תשלום דמי הסכמה 1/3 מעליית ערך המקרקעין | K41: =K40/3 -> 906182.27
G42: שווי היסודי של הנחלה במקדם 2% | K42: =615000*0.02 -> 12300
G43: סה"כ | K43: =K42+K41 -> 918482.27
G44: במעוגל | K44: 950000
G45: מדד המחירים לצרכן מיום 09/06/2017 | K45: =1.16 -> 1.16
G46: סה"כ תשלום ממודד | K46: =K44*K45 -> 1102000
K47: =K46*1.18 -> 1300360

Sheet חישוב גדלי בתים
A2: קיים | B2: חתימת רמ"י | C2: חתימת ועדה | D2: מבנה 1 - בית מגורים
A3: מפת מדידה - מפרט רמ"י
A4: קומת עמודים
A5: שטחי מגורים - קרקע
A6: פרגולה + מרפסת אחורית
A7: פרגולה קדמית
A8: פרגולה צידית
A9: בליטת גג
A10: שרות (ממ"ד)
A11: קומת עמודים בהיתר
A12: קומת עמודים ללא היתר
A13: סה"כ מבנה | E13: =SUM(E4:E12) -> 0 | F13: =SUM(F3:F12) -> 0 | G13: =SUM(G3:G12) -> 0 | H13: =SUM(H3:H12) -> 0 | I13: =SUM(I3:I12) -> 0 | J13: =SUM(J3:J12) -> 0 | K13: =SUM(K3:K12) -> 0 | L13: =SUM(L3:L12) -> 0 | M13: =SUM(M3:M12) -> 0 | ... S13: =SUM(S3:S12) -> 0
A14: בהיתר | B14: חתימת רמ"י | C14: חתימת ועדה
A15: 71 | B15: V | C15: V | D15: =28+155 -> 183
A19: בהתר | D19: =SUM(D16:D18) -> 0 | E19: =SUM(E16:E18) -> 0 | F19: =SUM(F15:F18) -> 0 | G19: =SUM(G15:G18) -> 0 | H19: =SUM(H15:H18) -> 0 | I19: =SUM(I15:I18) -> 0 | J19: =SUM(J15:J18) -> 0 | K19: =SUM(K15:K18) -> 0 | L19: =SUM(L15:L18) -> 0 | M19: =SUM(M15:M18) -> 0 | ... S19: =SUM(S15:S18) -> 0
A20: פערים | D20: =D13-D19 -> 0 | E20: =E13-E19 -> 0 | F20: =F13-F19 -> 0 | G20: =G13-G19 -> 0 | H20: =H13-H19 -> 0 | I20: =I13-I19 -> 0 | J20: =J13-J19 -> 0 | K20: =K13-K19 -> 0 | ... S20: =S13-S19 -> 0
A22: פער מרפסות | D22: =D8+D7 -> 0
E23: =E3*9300*5%*7 -> 0
E24: =375-E19-F19-I19 -> 375
A26: דמי היתר ששולמו
A27: בית 1 | E27: =-D13 -> 0
A28: בית 2 | E28: =-E13 -> 0
A29: מחסן | E29: =I19 -> 0
A30: סה"כ | E30: =SUM(E26:E29) -> 0
A31: היוון 3.75 | E31: 375
A32: סה"כ מטרים | E32: =SUM(E30:E31) -> 375
A33: קיים | E33: =-E19-F19-I19 -> 0
A34: נותרו לבניה | E34: =SUM(E32:E33) -> 375
A38: פערים בית מגורים
A39: קומה תחתונה | D39: היתר | E39: בפועל | F39: הפרש
A40: עיקרי | F40: =E40-D40 -> 0
A41: מרפסת | F41: =E41-D41 -> 0
A42: סה"כ קומת קרקע | D42: =SUM(D40:D41) -> 0 | E42: =SUM(E40:E41) -> 0 | F42: =E42-D42 -> 0
A44: קומה עליונה | D44: היתר | E44: בפועל | F44: הפרש
A45: עיקרי | D45: 156 | E45: 167 | F45: =E45-D45 -> 11
A46: מרפסת | D46: 25 | E46: 16 | F46: =E46-D46 -> -9
A47: סה"כ קומת קרקע | D47: =SUM(D45:D46) -> 181 | E47: =SUM(E45:E46) -> 183 | F47: =E47-D47 -> 2
A49: סה"כ | D49: =D47+D42 -> 181 | E49: =E47+E42 -> 183 | F49: =F47+F42 -> 2

Sheet תבעות
A2: מקור | B2: מס' תבע | C2: תאריך | D2: זכויות
A3: XPLAN | B3: 634-0829846 | C3: 45344 | D3: 500 | E3: פל"ח
A4: גובמאפ | B4: 634-0454967 | C4: 44271 | D4: 3.5 | E4: בתים | F4: פיצול
A5: גובמאפ | B5: 3/222/06/6 | C5: 40000 | D5: 2.5 | E5: בתים
A6: גובמאפ | B6: 222/03/6 | C6: 33248 | D6: 2 | E6: בתים

Sheet גיליון1
B2: טבלאת סיכום עלויות דמי שימוש
B3: דמי שימוש | C3: מגורים | E3: פרגולות
B4: בית ראשון - מבנה 1 | C4: 0 | E4: 0
B5: בית שני - מבנה 4 | C5: 140000 | E5: =6000*2 -> 12000
B6: בית שלישי - מבנה 1 עבור 100 מ"ר | C6: =46500*7 -> 325500 | E6: 0
B7: בית רביעי - מבנה 2 | C7: =13000*7 -> 91000 | E7: =4000*7 -> 28000
B8: בית חמישי - מבנה 5 | C8: =65000*7 -> 455000 | E8: 50000 | J8: V
B9: טבלאת סיכום עלויות הסדרה | J9: X
B10: דמי היתר - להסדרה | C10: מ"ר לתש' עיקרי | D10: תשלום עיקרי | E10: מ"ר פרגולות | F10: תשלום פרגולות
B11: בית ראשון - מבנה 1 | C11: =197-160 -> 37 | D11: =C11*6605 -> 244385 | E11: 35 | F11: =E11*6605/2 -> 115587.5
B12: בית שני - מבנה 4 | C12: 0 | D12: 0 | E12: =147+24-160 -> 11 | F12: =E12*6605/2 -> 36327.5
B13: בית שלישי - מבנה 1 | C13: יוסדר כמבנה אחד עם הבית הראשון
B14: בית רביעי - מבנה 2 | C14: מומלץ לפינוי / הסרה
B15: בית חמישי - מבנה 5 | C15: יוסדר כבית שלישי - יוצג מטה
B17: טבלאת סיכום עלויות
B18: דמי שימוש - 7 שנים | C18: מגורים | E18: פרגולות
B19: בית ראשון - מבנה 1 | C19: 0 | E19: 0
B20: בית שני - מבנה 4 | C20: 70000 | E20: =6000*7 -> 42000
B21: בית שלישי - מבנה 1 | C21: =46500*7 -> 325500 | E21: 0
B22: בית רביעי - מבנה 2 | C22: =13000*7 -> 91000 | E22: =4000*7 -> 28000
B23: בית חמישי - מבנה 5 | C23: =65000*7 -> 455000 | E23: =7000*7 -> 49000
B25: דמי היתר - להסדרה | C25: מ"ר לתש' עיקרי | D25: תשלום עיקרי | E25: מ"ר פרגולות | F25: תשלום פרגולות
B26: בית ראשון - מבנה 1 | C26: =197-160 -> 37 | D26: =C26*6605 -> 244385 | E26: 35 | F26: =E26*6605/2 -> 115587.5
B27: בית שני - מבנה 4 | C27: 0 | D27: =C27*6605 -> 0 | E27: =147+24-160 -> 11 | F27: =E27*6605/2 -> 36327.5
B28: בית שלישי - מבנה 1 | C28: יוסדר כמבנה אחד עם הבית הראשון
B29: בית רביעי - מבנה 2 | C29: 0 | D29: 0 | E29: 0 | F29: 0
B30: בית חמישי - מבנה 5 | C30: 0 | D30: 0 | E30: =139+31-160 -> 10 | F30: =E30*6605/2 -> 33025
B35: טבלאת סיכום עלויות בית שלישי
B36: הדרך אל הבית השלישי | C36: מגורים | E36: פרגולות
B37: עלויות הסדרה | C37: ע"פ שלב 1 - 1,100,000 ₪
B38: היוון 3.75% דמי חכירה | C38: ע"פ שלב 2 - 260,000 ₪
B39: תב"ע | C39: שכ"ט בעלי מקצוע
B40: היתר בניה - דמי היתר | C40: דמי היתר 455,000 ₪ + היטל השבחה

Sheet בקרה
A2: תב"עות | B2: פלח
B3: מגורים
N7: חריגה מקו
A8: עדיפות לאומית | N8: גבול
A9: סיווג | D9: קישור לפרק 4.2 סימן א רשימת איזורי עדיפות | N9: בניין
N10: לא
A15: מיפוי | B15: חריגה מקווים
A19: מבנים | B19: חריגה מקו | C19: היתר | D19: גודל קיים | E19: גודל בהיתר | F19: שימוש | G19: מקדם | H19: שווי שימוש | I19: שיעור דמי שימוש | J19: דמי שימוש לשנה | K19: שיעור דמי היתר | L19: דמי היתר
A20: מבנה 1 - בית ראשון | H20: ='תחשיב לפי שווי שומה (2)'!B7 -> 8000 | I20: 0 | J20: =D20*G20*H20*I20 -> 0 | K20: 0.51 | L20: ='[1]תחשיב לפי שווי שומה (2)'!$B$26*G20 -> 0
A21: מבנה 1 - פרגולה | H21: =H20 -> 8000 | I21: 0 | J21: =D21*G21*H21*I21 -> 0 | K21: 0.51 | L21: ='[1]תחשיב לפי שווי שומה (2)'!$B$26*G21 -> 0
A22: מבנה 7 - יח"ד שניה | H22: =H21 -> 8000 | I22: 0.05 | J22: =D22*G22*H22*I22 -> 0 | K22: 0.51 | L22: ='[1]תחשיב לפי שווי שומה (2)'!$B$26*G22 -> 0
A23: מבנה 4 - יח"ד שלישית | H23: =H22 -> 8000 | I23: 0.05 | J23: =D23*G23*H23*I23 -> 0 | K23: 0.51 | L23: ='[1]תחשיב לפי שווי שומה (2)'!$B$26*G23 -> 0
A24: מבנה 4 - פל"ח | I24: 0.05 | J24: =D24*G24*H24*I24 -> 0 | K24: 0.51 | L24: =H24*K24 -> 0
