Workbook

Sheet תחשיב לפי שווי שומה (2)
A2: מ"ר אקו' נחלה היוון מלא 3 דונם | B2: ='מ"ר אקו'' נחלה'!I15 -> 967.5
A3: מ"ר אקו' נחלה היוון מלא 2.5 דונם | B3: ='מ"ר אקו'' נחלה'!D15 -> 997.5
A4: מ"ר אקו' פוטנציאל | B4: ='מ"ר אקו'' נחלה'!D27 -> 186.58892
A5: דמי היתר שנרכשו | B5: ='מ"ר אקו'' נחלה'!D37 -> 14
A6: מ"ר אקו' נחלה 3.75% | B6: ='מ"ר אקו'' נחלה'!D69 -> 806.25
A7: מ"ר אקו' מגרש מפוצל | B7: ='מ"ר אקו'' נחלה'!D56 -> 286.8 | C7: מ"ר ל-29.75% | D7: ='מ"ר אקו'' נחלה'!I49 -> 207.5
A8: שווי מ"ר אקו' מגורים | B8: ='ניתוח איזור לעסקאות דמה'!C7 -> 12000 | C8: שווי מ"ר משרדים | D8: 2500
C9: שווי מ"ר אחסנה | D9: ='ניתוח איזור לעסקאות דמה'!#REF! -> #REF! | E9: 1.17
B10: מ"ר אקו' | C10: דמי חכירה/ פיצול | D10: עלות אקו' | E10: מע"מ | F10: בש"ח | G10: בניכוי פיתוח
A11: היוון 3.75% | B11: =B6 -> 806.25 | C11: 0.0375 | D11: =C11*B11 -> 30.234375 | E11: 1 | F11: =D11*$B$8*E11 -> 362812.5 | G11: ='מ"ר אקו'' נחלה'!D70*-3.75% -> -6562.5 | H11: =SUM(F11:G11) -> 356250
A12: פיצול - חלק בהנחה | B12: =D7 -> 207.5 | C12: 0.2925 | D12: =C12*B12 -> 60.69375 | E12: 1 | F12: =D12*$B$8*E12 -> 728325 | G12: =-'מ"ר אקו'' נחלה'!D57*C12 -> -29250 | H12: =SUM(F12:G12) -> 699075
A13: פיצול חלק ללא הנחה | B13: =B7-B12 -> 79.3 | C13: 0.33 | D13: =C13*B13 -> 26.169 | E13: 1 | F13: =D13*$B$8*E13 -> 314028 | G13: =G12*53/245 -> -6327.551 | H13: =SUM(F13:G13) -> 307700.45
A14: סה"כ פיצול | B14: =SUM(B12:B13) -> 286.8 | F14: =SUM(F12:F13) -> 1042353 | H14: =SUM(H12:H13) -> 1006775.4
A15: היטל השבחה על פיצול | B15: ='מ"ר אקו'' נחלה'!I49 -> 207.5 | C15: =C35 -> 0.425 | D15: =B15*C15 -> 88.1875 | E15: 1 | F15: =D15*$B$8 -> 1058250
A16: דמי רכישה | B16: =B3+B4-B5 -> 1170.0889 | C16: 0.33 | D16: =C16*B16 -> 386.12934 | E16: 1 | F16: =D16*$B$8*E16 -> 4633552.1 | G16: =-'מ"ר אקו'' נחלה'!D16*C16 -> -81510 | H16: =SUM(F16:G16) -> 4552042.1
A17: דמי היתר 1 מ"ר מגורים | B17: 1 | C17: 0.91 | D17: =C17*B17 -> 0.91 | E17: 1 | F17: 1486
A18: דמי היתר 1 מ"ר שירות | B18: 0.5 | C18: 0.91 | D18: =C18*B18 -> 0.455 | E18: 1 | F18: =F17/2 -> 743 | G18: =F18*#REF!*5%*1.17 -> #REF!
A19: דמי היתר 1 מ"ר מרתף | B19: 0.7 | C19: 0.91 | D19: =C19*B19 -> 0.637 | E19: 1 | F19: =D19*$B$8*E19 -> 7644
A20: היוון 1 מ"ר חצר נוספים | B20: 0.075 | C20: 0.91 | D20: =C20*B20 -> 0.06825 | E20: 1 | F20: =D20*$B$8*E20 -> 819
A21: דמי שימוש משרדים 1 מ"ר לשנה | B21: 1 | C21: 0.05 | D21: =C21*B21 -> 0.05 | E21: 1 | F21: =D21*$D$8*E21 -> 125
A22: דמי היתר בריכה 1 מ"ר | B22: 0.3 | C22: 0.91 | D22: =C22*B22 -> 0.273 | E22: 1 | F22: =D22*$B$8*E22 -> 3276
A23: דמי היתר משרד פלח | B23: 1 | C23: 0.91 | D23: =C23*B23 -> 0.91 | E23: 1 | F23: =E23*D23*$D$8 -> 2275
A24: דמי שימוש 1 מ"ר למגורים | B24: 1 | C24: 0.05 | D24: =C24*B24 -> 0.05 | E24: 1 | F24: =D24*E24*B8 -> 600
A27: מחשבון רמ"י
A29: היטל השבחה פיצול בית שלישי (מגרש ראשון)
B30: עבור מגרש 350 | C30: מקדם | D30: עבור 1 מ"ר אקו'
A31: אחרי מגרש מפוצל | B31: ='מ"ר אקו'' נחלה'!D56*'תחשיב לפי שווי שומה (2)'!$B$8 -> 3441600 | C31: 1 | D31: =C31*$B$8 -> 12000
A32: לפני חצר שולית | B32: =350*$B$8*C32 -> 630000 | C32: 0.15 | D32: =C32*$B$8 -> 1800
A34: השבחה | B34: =B31-B32 -> 2811600 | C34: =C31-C32 -> 0.85 | D34: =C34*$B$8 -> 10200
A35: היטל | B35: =B34*50% -> 1405800 | C35: =C34*50% -> 0.425 | D35: =C35*$B$8 -> 5100
A37: היטל השבחה פיצול בית שני (מגרש שני)
B38: עבור מגרש 350 | C38: מקדם | D38: עבור 1 מ"ר אקו'
A39: אחרי מגרש מפוצל | B39: ='מ"ר אקו'' נחלה'!D56*'תחשיב לפי שווי שומה (2)'!$B$8 -> 3441600 | C39: 1 | D39: =C39*$B$8 -> 12000
A40: לפני מגרש לא מפוצל | B40: =B39*70% -> 2409120 | C40: 0.7 | D40: =C40*$B$8 -> 8400
A42: השבחה | B42: =B39-B40 -> 1032480 | C42: =C39-C40 -> 0.3 | D42: =C42*$B$8 -> 3600
A43: היטל | B43: =B42*50% -> 516240 | C43: =C42*50% -> 0.15 | D43: =C43*$B$8 -> 1800

Sheet סיכום עלויות פיצולים
I9: סיכום עלויות פיצול/ים לאחר הסדרה
I10: סוג תשלום | K10: פיצול בית קיים | M10: פיצול מגרש ריק + בית קיים | O10: דמי רכישה
I12: דמי היוון 3.75%/33% | K12: =240000 -> 240000 | M12: =240000 -> 240000 | O12: 2700000
I14: תשלום בעבור פיצול | K14: =1000000 -> 1000000 | M14: 1730000 | O14: -
I16: מס רכישה | K16: =(K14+K12)*0.06 -> 74400 | M16: =(M14+M12)*0.06 -> 118200 | O16: =O12*0.06 -> 162000
I18: דמי היתר לרכוש במשק | K18: - | M18: 144000 | O18: -
I20: סה"כ | K20: =SUM(K12:L19) -> 1314400 | M20: =SUM(M12:N19) -> 2232200 | O20: =SUM(O12:P19) -> 2862000
I22: היטל השבחה - בעת מכר | K22: 500000 | M22: 1500000 | O22: כמפורט בכל אפשרות
A26: נרכשו | B26: =209-160 -> 49
A28: בנוי כיום | B28: מס' מבנה | C28: שם מבנה | D28: גודל | E28: דמי היתר | F28: היטל השבחה | G28: סה"כ | H28: דמי שימוש | I28: שכ"ט
A29: 250 | B29: מבנה 1 | C29: בית ראשון של אורית | D29: 155 | E29: =10800*12 -> 129600 | F29: 0 | G29: =SUM(E29:F29) -> 129600 | H29: 0
C30: בית צמוד קיר של ליאור הבן | D30: 55 | E30: 0 | F30: =D30*1250 -> 68750 | G30: =SUM(E30:F30) -> 68750 | H30: 130000
A31: 42 | B31: מבנה 2 | C31: בית של רפי שלישי | D31: =42+12 -> 54 | E31: =10*10800 -> 108000 | F31: =(D31-10)*5100 -> 224400 | G31: =SUM(E31:F31) -> 332400 | H31: 0 | J31: התוספת היא של ממ"ד
A32: 60 | B32: מבנה 6 | C32: בית שני של נטע הבת | D32: 160 | E32: 0 | F32: 0 | G32: =SUM(E32:F32) -> 0 | H32: 200000
B33: 3,4,5,7,8,9,10 | C33: כלל מבני החקלאות | D33: להריסה | G33: =SUM(E33:F33) -> 0
B34: תכנון חדש | C34: מבנה לגידול תוכים וכלבים | D34: 700 | E34: 0 | F34: 0 | G34: =SUM(E34:F34) -> 0 | P34: 5
D35: =SUM(D29:D32) -> 424 | E35: =SUM(E29:E32) -> 237600 | F35: =SUM(F29:F32) -> 293150 | G35: =SUM(E35:F35) -> 530750 | H35: =SUM(H29:H32) -> 330000 | P35: 49
F36: היוון | G36: =380000 -> 380000 | P36: =SUM(P34:P35) -> 54
F37: תב"ע
A41: רוי
A42: בנוי כיום | B42: מס' מבנה | C42: שם מבנה | D42: גודל | E42: דמי היתר | F42: היטל השבחה | G42: סה"כ | H42: דמי שימוש | I42: הערות | R42: חישוב היטל השבחה בית שני
A43: 223 | B43: מבנה 1 | C43: בית ראשון של אורית | D43: 155 | E43: - | F43: 0 | G43: =SUM(E43:F43) -> 0 | H43: 133000 | I43: לא יחול תשלום דמי היתר יוסדר בית ראשון בשטח קטן מ-160 מ"ר, גם ממ"ד בנוסף ל-155 יהיה פטור | R43: שווי מ"ר מבונה | S43: מועד קובע | T43: מדד | U43: שווי מ"ר ממודד
C44: בית צמוד קיר של ליאור הבן | D44: 55 | E44: 5400 | F44: 69000 | G44: =SUM(E44:F44) -> 74400 | R44: 2.3 | S44: 30246 | T44: 455.7 | U44: =T44*R44 -> 1048.11
A45: 42 | B45: מבנה 2 | C45: בית של רפי שלישי | D45: =42+12 -> 54 | E45: - | F45: 225000 | G45: =SUM(E45:F45) -> 225000 | H45: 0 | I45: לא יחול תשלום דמי היתר, היום הבית מאושר כבית שני ובמסגרת ההיוון וההסדרה מוסיפים ממד למבנה קיים או תוספת לבית שלישי שמתכנס בסל הזכויות | R45: מקדם השבחה | U45: 0.8
A46: 60 | B46: מבנה 6 | C46: בית שני של נטע הבת | D46: 160 | E46: 0 | F46: 70000 | G46: =SUM(E46:F46) -> 70000 | H46: 200000 | R46: סה"כ השבחה למ"ר | U46: =U44*U45 -> 838.488
B47: 3,4,5,7,8,9,10 | C47: כלל מבני החקלאות | D47: להריסה | G47: =SUM(E47:F47) -> 0 | R47: היטל | U47: =U46/2 -> 419.244
B48: תכנון חדש | C48: מבנה לגידול תוכים וכלבים | D48: 700 | E48: 0 | F48: 0 | G48: =SUM(E48:F48) -> 0 | R48: לבית 160 מ"ר | U48: =U47*160 -> 67079.04
E49: =SUM(E43:E46) -> 5400 | F49: =SUM(F43:F46) -> 364000 | G49: =SUM(E49:F49) -> 369400 | H49: =SUM(H43:H46) -> 333000
F50: היוון | G50: =380000 -> 380000
F51: תב"ע

Sheet מ"ר אקו' נחלה
A2: גודל חלקת מגורים (להיוון) | B2: 2500 | C2: לפי שומת חכמון | F2: גודל חלקת מגורים (להיוון) | G2: 3000
B3: מ"ר | C3: מקדם | D3: אקו' | G3: מ"ר | H3: מקדם | I3: אקו'
A4: עיקרי | B4: 450 | C4: 1 | D4: =C4*B4 -> 450 | F4: =A4 -> עיקרי | G4: =B4 -> 450 | H4: =C4 -> 1 | I4: =H4*G4 -> 450
A5: מרחבים מוגנים | B5: 25 | C5: 0.9 | D5: =C5*B5 -> 22.5 | F5: =A5 -> מרחבים מוגנים | G5: =B5 -> 25 | H5: =C5 -> 0.9 | I5: =H5*G5 -> 22.5
A6: יתרת ש"ש | B6: 100 | C6: 0.5 | D6: =C6*B6 -> 50 | F6: =A6 -> יתרת ש"ש | G6: =B6 -> 100 | H6: =C6 -> 0.5 | I6: =H6*G6 -> 50
A7: מרתפים | B7: 200 | C7: 0.4 | D7: =C7*B7 -> 80
A8: מבנה עזר - יתרת שטח | C8: 0.5 | D8: =C8*B8 -> 0 | F8: =A8 -> מבנה עזר - יתרת שטח | G8: =B8 -> 0 | H8: =C8 -> 0.5 | I8: =H8*G8 -> 0
A9: סה"כ תכסית | B9: =SUM(B4:B8) -> 775 | F9: סה"כ תכסית | G9: =SUM(G4:G8) -> 575
A10: סה"כ חצר | B10: =B2-B9 -> 1725 | F10: סה"כ חצר | G10: =G2-G9 -> 2425
A11: חצר אפקטיבית | B11: 1000 | C11: 0.25 | D11: =C11*B11 -> 250 | F11: חצר אפקטיבית | G11: =B11 -> 1000 | H11: 0.25 | I11: =H11*G11 -> 250
A12: יתרת חצר | B12: =B10-B11 -> 725 | C12: 0.2 | D12: =C12*B12 -> 145 | F12: יתרת חצר | G12: =B12 -> 725 | H12: 0.2 | I12: =H12*G12 -> 145
F13: חצר רחוקה מאוד | G13: 500 | H13: 0.1 | I13: =G13*H13 -> 50
A14: סה"כ מ"ר אקו' | B14: =SUM(B4:B12) -> 5000 | D14: =SUM(D4:D13) -> 997.5 | F14: סה"כ מ"ר אקו' | G14: =SUM(G4:G12) -> 5300 | I14: =SUM(I4:I13) -> 967.5
A15: סה"כ מ"ר אקו' מעוגל | D15: =D14 -> 997.5 | F15: סה"כ מ"ר אקו' מעוגל | I15: =I14 -> 967.5
A16: עלויות פיתוח | D16: 247000 | F16: עלויות פיתוח | I16: 263000
A18: פוטנציאל | B18: 2500 | C18: לפי ברנס
B19: מ"ר | C19: מקדם | D19: אקו'
A20: עיקרי | B20: 220 | C20: 1 | D20: =C20*B20 -> 220
A21: ממ"ד | B21: 12 | C21: 0.9 | D21: =C21*B21 -> 10.8
A22: חצר עיקרית | B22: =500-B20/2-B21/2 -> 384 | C22: 0.25 | D22: =C22*B22 -> 96
A24: הפסד חצר שולית | B24: -500 | C24: 0.2 | D24: =B24*C24 -> -100
A25: סה"כ | D25: =SUM(D20:D24) -> 226.8 | H25: =876+73 -> 949
A26: דחיה למימוש | D26: =1/1.05^4 -> 0.82270247 | H26: =H25+137 -> 1086
A27: סה"כ מ"ר אקו' מעוגל | D27: =D25*D26 -> 186.58892
A29: דמי היתר שנרכשו
A30: גודל בית ראשון בהיתר | D30: 174
A31: שטח פטור | D31: 160
A32: שטח שנרכש | D32: =D30-D31 -> 14
A33: גודל בית שני בהיתר | D33: 240
A34: שטח פטור | D34: 160
A35: שטח שנרכש
A37: סה"כ שטח שנרכש | D37: =D32 -> 14
A40: סה"כ שטח אקו' לחישוב דמי רכישה | D40: =D15+D27-D37 -> 1170.0889
A45: מגרש מפוצל הרחבת אביגדור רק במקום 180 220 עיקרי | O45: תחשיבי פיצול | P45: סעיף | Q45: מ"ר בנוי | R45: פטור | S45: זכויות חוזיות | T45: עלות לרמ"י ליח' | U45: סה"כ רמ"י | V45: עלות ליח' | W45: היטל השבחה | X45: עלות ליח' | Y45: מס רכישה
A46: גודל מגרש | B46: 350 | C46: לפי שומת זיו כהן בשפיר | F46: חלק ה29.25% | J46: שויי מ"ר | O46: הסדרה | P46: בית 1 | Q46: 300 | R46: 160 | S46: =Q46-R46 -> 140 | T46: 3000 | U46: =S46*T46 -> 420000 | V46: 0 | W46: =S46*V46 -> 0 | X46: 0 | Y46: 0
A47: מגורים עיקרי בהרחבה | B47: 220 | C47: 1 | D47: =B47*C47 -> 220 | F47: =A47 -> מגורים עיקרי בהרחבה | G47: 160 | H47: 1 | I47: =G47*H47 -> 160 | P47: בית 2 | Q47: 197 | R47: 160 | S47: =Q47-R47 -> 37 | T47: 3000 | U47: =S47*T47 -> 111000 | V47: 0 | W47: 0 | X47: 0 | Y47: 0
A48: שירות - מרתף | B48: 40 | C48: 0.5 | D48: =B48*C48 -> 20 | F48: חצר | G48: =B46-G47 -> 190 | H48: 0.25 | I48: =G48*H48 -> 47.5 | P48: בית שלישי | Q48: 130 | R48: 0 | S48: =Q48-R48 -> 130 | T48: 3000 | U48: =S48*T48 -> 390000 | V48: 0 | W48: 0 | X48: 0 | Y48: 0
A49: מרחבים מוגנים | B49: 12 | C49: 0.9 | D49: =B49*C49 -> 10.8 | F49: מ"ר אקו' שנכלל בהנחה | I49: =I47+I48 -> 207.5 | J49: ='תחשיב לפי שווי שומה (2)'!B8 -> 12000 | K49: =I49*J49 -> 2490000 | L49: 0.2925 | M49: =K49*L49 -> 728325 | P49: יח"ד הורים | Q49: 55 | R49: 0 | S49: =Q49-R49 -> 55 | T49: 3000 | U49: =S49*T49 -> 165000 | V49: 0 | W49: 0 | X49: 0 | Y49: 0
A50: מסחן | B50: 11 | C50: 0.5 | D50: =B50*C50 -> 5.5 | F50: מ"ר אקו' שלא נכלל בהנחה | I50: =D56-I49 -> 79.3 | J50: =J49 -> 12000 | K50: =I50*J50 -> 951600 | L50: 0.33 | M50: =K50*L50 -> 314028 | P50: סה"כ | S50: =SUM(S46:S49) -> 362 | T50: 3000 | U50: =SUM(U46:U49) -> 1086000 | V50: 0 | W50: 0 | X50: 0 | Y50: 0
A51: סככת חניה | B51: 30 | C51: 0.35 | D51: =B51*C51 -> 10.5 | M51: =SUM(M49:M50) -> 1042353 | O51: היוון | P51: היוון | Q51: 0.0375 | S51: 375 | T51: 240000 | U51: =T51 -> 240000 | V51: 0 | W51: 0 | X51: 0.06 | Y51: =U51*6% -> 14400
...

Sheet תחשיבי הסדרה
D2: מס' מבנה | E2: סיווג המבנה | F2: שטח במ"ר | G2: עלות הסדרה | H2: סה"כ | I2: דמי שימוש | J2: היטל השבחה
D4: 1
D6: 2
D8: 3
D10: 4
D12: 5
D14: 6
D16: 7
D18: 8
D20: 9
D22: 10
D24: 11
D26: סה"כ | H26: =SUM(H4:H25) -> 0 | I26: =SUM(I4:I25) -> 0 | J26: =SUM(J4:J25) -> 0

Sheet ניתוח איזור לעסקאות דמה
B2: שומת
B3: שווי מ"ר אקו'
B4: אחוז שנתי
B5: שנים להיוון
B6: שווי עדכני
B7: שווי לשומה | C7: =M24 -> 12000
B9: תחשיב לפי מכירות בהרחבה
B10: תאריך | C10: גו"ח | D10: מחיר עסקה | E10: שטח המגרש | F10: שטח בנוי | G10: שנת בניה | H10: התאמה למועד קובע | I10: בניכוי יזמי 5% | J10: עלויות בניה למ"ר | K10: יתרה לקרע כולל | L10: שטח אקו' | M10: שווי מתואם כולל מעמ ופיתוח
D14: ניתוח מגרשי מגורים בית אלעזרי ממכרז מיום 12/02/2025
D15: מס"ד | E15: גוש חלקה | F15: מס' מגרש | G15: תב"ע | H15: מחיר זכיה | I15: בתוספת מע"מ | J15: עלויות פיתוח | K15: סה"כ מחיר זכיה למגרש | L15: שטח מגרש במ"ר | M15: שווי מ"ר מבונה אקו'
D16: 1 | E16: 4718 - 64 | F16: 526 | G16: בר/2/13 | H16: 3900770 | I16: =H16*1.18 -> 4602908.6 | J16: 148086 | K16: =I16+J16 -> 4750994.6 | L16: 499 | M16: =G38 -> 14468.198
D17: 2 | E17: 4717 - 21 | F17: 529 | G17: בר/2/13 | H17: 3311111 | I17: =H17*1.18 -> 3907111 | J17: 148086 | K17: =I17+J17 -> 4055197 | L17: 499 | M17: =M38 -> 12349.287
D18: 3 | E18: 4716 - 101 | F18: 577א | G18: בר/2/13 | H18: 3350000 | I18: =H18*1.18 -> 3953000 | J18: 148086 | K18: =I18+J18 -> 4101086 | L18: 506 | M18: =G51 -> 12422.828
D19: 4 | E19: 4713 - 78 | F19: 623 | G19: בר/2/13 | H19: 3701555 | I19: =H19*1.18 -> 4367834.9 | J19: 148086 | K19: =I19+J19 -> 4515920.9 | L19: 512 | M19: =M51 -> 13617.553
D20: ממוצע | M20: =AVERAGE(M16:M19) -> 13214.466
D21: בהתאמה לבעלות / 0.97 | M21: =M20/0.97 -> 13623.161
D22: מקדם בינוי בנחלה והיקף עסקה | M22: 0.85
D23: שווי מ"ר בנחלה | M23: =M21*M22 -> 11579.687
D24: לשומה | M24: 12000
D28: ניתוח שטח אקו' מס"ד 1 | H28: שטח מגרש | J28: ניתוח שטח אקו' מס"ד 2 | N28: שטח מגרש
D29: מהות | E29: שטח | F29: מקדם | G29: סה"כ | H29: =L16 -> 499 | J29: מהות | K29: שטח | L29: מקדם | M29: סה"כ | N29: =L17 -> 499
D30: עיקרי | E30: 220 | F30: 1 | G30: =F30*E30 -> 220 | J30: עיקרי | K30: 220 | L30: 1 | M30: =L30*K30 -> 220
D31: ממ"ד | E31: 7.5 | F31: 0.9 | G31: =F31*E31 -> 6.75 | J31: ממ"ד | K31: 7.5 | L31: 0.9 | M31: =L31*K31 -> 6.75
D32: מחסן | E32: 15 | F32: 0.5 | G32: =F32*E32 -> 7.5 | J32: מחסן | K32: 15 | L32: 0.5 | M32: =L32*K32 -> 7.5
D33: חניה | E33: 25 | F33: 0.35 | G33: =F33*E33 -> 8.75 | J33: חניה | K33: 25 | L33: 0.35 | M33: =L33*K33 -> 8.75
D34: תכסית | E34: =E30/2+E31+E32+E33 -> 157.5 | F34: - | G34: 0 | J34: תכסית | K34: =K30/2+K31+K32+K33 -> 157.5 | L34: - | M34: 0
D35: חצר | E35: =H29-E34 -> 341.5 | F35: 0.25 | G35: =F35*E35 -> 85.375 | J35: חצר | K35: =N29-K34 -> 341.5 | L35: 0.25 | M35: =L35*K35 -> 85.375
D36: סה"כ שטח אקו' | G36: =SUM(G30:G35) -> 328.375 | J36: סה"כ שטח אקו' | M36: =SUM(M30:M35) -> 328.375
D37: מחיר זכיה במגרש | G37: =K16 -> 4750994.6 | J37: מחיר זכיה במגרש | M37: =K17 -> 4055197
D38: שווי מ"ר מבונה אקו' | G38: =G37/G36 -> 14468.198 | J38: שווי מ"ר מבונה אקו' | M38: =M37/M36 -> 12349.287
D41: ניתוח שטח אקו' מס"ד 3 | H41: שטח מגרש | J41: ניתוח שטח אקו' מס"ד 4 | N41: שטח מגרש
D42: מהות | E42: שטח | F42: מקדם | G42: סה"כ | H42: =L18 -> 506 | J42: מהות | K42: שטח | L42: מקדם | M42: סה"כ | N42: =L19 -> 512
D43: עיקרי | E43: 220 | F43: 1 | G43: =F43*E43 -> 220 | J43: עיקרי | K43: 220 | L43: 1 | M43: =L43*K43 -> 220
D44: ממ"ד | E44: 7.5 | F44: 0.9 | G44: =F44*E44 -> 6.75 | J44: ממ"ד | K44: 7.5 | L44: 0.9 | M44: =L44*K44 -> 6.75
D45: מחסן | E45: 15 | F45: 0.5 | G45: =F45*E45 -> 7.5 | J45: מחסן | K45: 15 | L45: 0.5 | M45: =L45*K45 -> 7.5
D46: חניה | E46: 25 | F46: 0.35 | G46: =F46*E46 -> 8.75 | J46: חניה | K46: 25 | L46: 0.35 | M46: =L46*K46 -> 8.75
D47: תכסית | E47: =E43/2+E44+E45+E46 -> 157.5 | F47: - | G47: 0 | J47: תכסית | K47: =K43/2+K44+K45+K46 -> 157.5 | L47: - | M47: 0
D48: חצר | E48: =H42-E47 -> 348.5 | F48: 0.25 | G48: =F48*E48 -> 87.125 | J48: חצר | K48: =N42-K47 -> 354.5 | L48: 0.25 | M48: =L48*K48 -> 88.625
D49: סה"כ שטח אקו' | G49: =SUM(G43:G48) -> 330.125 | J49: סה"כ שטח אקו' | M49: =SUM(M43:M48) -> 331.625
D50: מחיר זכיה במגרש | G50: =K18 -> 4101086 | J50: מחיר זכיה במגרש | M50: =K19 -> 4515920.9
...

Sheet חישוב גדלי בתים
A2: קיים | B2: חתימת רמ"י | C2: חתימת ועדה | D2: מבנה 1 - בית מגורים ראשון + שלישי | E2: מבנה 1.1 - פרגולה | F2: מבנה 2 - בית מגורים שני | G2: מבנה 3 -מחסן,מסגריה,משרד פל"ח | H2: מבנה 4 - כלובי תוכים פל"ח | I2: מבנה 5 - אורוות סוסים | J2: מבנה 6 - בית רביעי | K2: מבנה 7 - בית חמישי | L2: מבנה 8 - אחסנה ביתית | M2: מבנים 9-10 0 מחסנים ביתיים | N2: מבנה 11 - מינאז'
A3: מפת מדידה - מפרט רמ"י | E3: 18 | F3: 42 | G3: 187 | H3: 220 | I3: 92 | J3: 63 | K3: 37 | L3: 26 | N3: 452
A4: קומת עמודים בית שלישי | D4: 35 | G4: 61 | M4: 15
A5: שטחי מגורים - קרקע | D5: =133*2-D4 -> 231 | G5: 65 | M5: 14
A6: פרגולה + מרפסת אחורית | D6: 18 | G6: 61
A7: פרגולה קדמית | F7: 24 | J7: 32
A8: פרגולה צידית
A9: בליטת גג
A10: שרות (ממ"ד) | J10: פ
A11: קומת עמודים בהיתר
A12: קומת עמודים ללא היתר
A13: סה"כ מבנה | D13: =SUM(D4:D12) -> 284 | E13: =SUM(E4:E12) -> 0 | F13: =SUM(F3:F12) -> 66 | G13: =SUM(G3:G12) -> 374 | H13: =SUM(H3:H12) -> 220 | I13: =SUM(I3:I12) -> 92 | J13: =SUM(J3:J12) -> 95 | K13: =SUM(K3:K12) -> 37 | L13: =SUM(L3:L12) -> 26 | M13: =SUM(M3:M12) -> 29 | ... S13: =SUM(S3:S12) -> 0
A14: בהיתר | B14: חתימת רמ"י | C14: חתימת ועדה
A15: היתר שנת 1993 | D15: 174.56
A16: היתר שנת 2001 | F16: 42.7
A17: היתר שנת 99
A18: היתר שנת 2000 - חקלאי
A19: היתר שנת 2000 - חקלאי
A20: היתר שנת 01- חקלאי
A24: בהתר | D24: =SUM(D17:D23) -> 0 | E24: =SUM(E17:E23) -> 0 | F24: =SUM(F15:F23) -> 42.7 | G24: =SUM(G15:G23) -> 0 | H24: =SUM(H15:H23) -> 0 | I24: =SUM(I15:I23) -> 0 | J24: =SUM(J15:J23) -> 0 | K24: =SUM(K15:K23) -> 0 | L24: =SUM(L15:L23) -> 0 | M24: =SUM(M15:M23) -> 0 | ... S24: =SUM(S15:S23) -> 0
A25: פערים | D25: =D13-D24 -> 284 | E25: =E13-E24 -> 0 | F25: =F13-F24 -> 23.3 | G25: =G13-G24 -> 374 | H25: =H13-H24 -> 220 | I25: =I13-I24 -> 92 | J25: =J13-J24 -> 95 | K25: =K13-K24 -> 37 | ... S25: =S13-S24 -> 0
A27: פער מרפסות | D27: =D8+D7 -> 0
E28: =E3*9300*5%*7 -> 58590
E29: =375-E24-F24-I24 -> 332.3
A31: דמי היתר ששולמו
A32: בית 1 | E32: =-D13 -> -284
A33: בית 2 | E33: =-E13 -> 0
A34: מחסן | E34: =I24 -> 0
A35: סה"כ | E35: =SUM(E31:E34) -> -284
A36: היוון 3.75 | E36: 375
A37: סה"כ מטרים | E37: =SUM(E35:E36) -> 91
A38: קיים | E38: =-E24-F24-I24 -> -42.7
A39: נותרו לבניה | E39: =SUM(E37:E38) -> 48.3
A43: פערים בית מגורים
A44: קומה תחתונה | D44: היתר | E44: בפועל | F44: הפרש
A45: מגורים | F45: =E45-D45 -> 0
A46: מקלט | F46: =E46-D46 -> 0
A47: סה"כ קומת קרקע | D47: =SUM(D45:D46) -> 0 | E47: =SUM(E45:E46) -> 0 | F47: =E47-D47 -> 0
A49: קומה עליונה | D49: היתר | E49: בפועל | F49: הפרש
A50: מגורים | F50: =E50-D50 -> 0
...

Sheet תבעות
A2: מקור | B2: מס' תבע | C2: תאריך | D2: זכויות
A3: XPLAN | B3: בר/2020 | C3: 39849 | D3: 500 | E3: פל"ח | H3: מדד | I3: שווי ממודד
C4: 2007 | D4: 2.5 | E4: בתים | G4: 2500 | H4: 1.42 | I4: =H4*G4 -> 3550
A5: גובמאפ | B5: בר/3/13 | C5: 36020 | E5: בריכה | F5: פיצול
A6: גובמאפ | B6: בר/13 | C6: 30231 | D6: 2 | E6: בתים
A7: גובמאפ | B7: בר/23 / תגפ | C7: 24463 | D7: 1 | E7: בתים

Sheet גיליון1
B2: טבלאת סיכום עלויות דמי שימוש
B3: דמי שימוש | C3: מגורים | E3: פרגולות
B4: בית ראשון - מבנה 1 | C4: 0 | E4: 0
B5: בית שני - מבנה 4 | C5: 140000 | E5: =6000*2 -> 12000
B6: בית שלישי - מבנה 1 עבור 100 מ"ר | C6: =46500*7 -> 325500 | E6: 0
B7: בית רביעי - מבנה 2 | C7: =13000*7 -> 91000 | E7: =4000*7 -> 28000
B8: בית חמישי - מבנה 5 | C8: =65000*7 -> 455000 | E8: 50000 | J8: V
B9: טבלאת סיכום עלויות הסדרה | J9: X
B10: דמי היתר - להסדרה | C10: מ"ר לתש' עיקרי | D10: תשלום עיקרי | E10: מ"ר פרגולות | F10: תשלום פרגולות
B11: בית ראשון - מבנה 1 | C11: =197-160 -> 37 | D11: =C11*6605 -> 244385 | E11: 35 | F11: =E11*6605/2 -> 115587.5
B12: בית שני - מבנה 4 | C12: 0 | D12: 0 | E12: =147+24-160 -> 11 | F12: =E12*6605/2 -> 36327.5
B13: בית שלישי - מבנה 1 | C13: יוסדר כמבנה אחד עם הבית הראשון
B14: בית רביעי - מבנה 2 | C14: מומלץ לפינוי / הסרה
B15: בית חמישי - מבנה 5 | C15: יוסדר כבית שלישי - יוצג מטה
B17: טבלאת סיכום עלויות
B18: דמי שימוש - 7 שנים | C18: מגורים | E18: פרגולות
B19: בית ראשון - מבנה 1 | C19: 0 | E19: 0
B20: בית שני - מבנה 4 | C20: 70000 | E20: =6000*7 -> 42000
B21: בית שלישי - מבנה 1 | C21: =46500*7 -> 325500 | E21: 0
B22: בית רביעי - מבנה 2 | C22: =13000*7 -> 91000 | E22: =4000*7 -> 28000
B23: בית חמישי - מבנה 5 | C23: =65000*7 -> 455000 | E23: =7000*7 -> 49000
B25: דמי היתר - להסדרה | C25: מ"ר לתש' עיקרי | D25: תשלום עיקרי | E25: מ"ר פרגולות | F25: תשלום פרגולות
B26: בית ראשון - מבנה 1 | C26: =197-160 -> 37 | D26: =C26*6605 -> 244385 | E26: 35 | F26: =E26*6605/2 -> 115587.5
B27: בית שני - מבנה 4 | C27: 0 | D27: =C27*6605 -> 0 | E27: =147+24-160 -> 11 | F27: =E27*6605/2 -> 36327.5
B28: בית שלישי - מבנה 1 | C28: יוסדר כמבנה אחד עם הבית הראשון
B29: בית רביעי - מבנה 2 | C29: 0 | D29: 0 | E29: 0 | F29: 0
B30: בית חמישי - מבנה 5 | C30: 0 | D30: 0 | E30: =139+31-160 -> 10 | F30: =E30*6605/2 -> 33025
B35: טבלאת סיכום עלויות בית שלישי
B36: הדרך אל הבית השלישי | C36: מגורים | E36: פרגולות
B37: עלויות הסדרה | C37: ע"פ שלב 1 - 1,100,000 ₪
B38: היוון 3.75% דמי חכירה | C38: ע"פ שלב 2 - 260,000 ₪
B39: תב"ע | C39: שכ"ט בעלי מקצוע
B40: היתר בניה - דמי היתר | C40: דמי היתר 455,000 ₪ + היטל השבחה

Sheet בקרה
A2: תב"עות | B2: פלח
B3: מגורים
N7: חריגה מקו
A8: עדיפות לאומית | N8: גבול
A9: סיווג | D9: קישור לפרק 4.2 סימן א רשימת איזורי עדיפות | N9: בניין
N10: לא
A15: מיפוי | B15: חריגה מקווים
A19: מבנים | B19: חריגה מקו | C19: היתר | D19: גודל קיים | E19: גודל בהיתר | F19: שימוש | G19: מקדם | H19: שווי שימוש | I19: שיעור דמי שימוש | J19: דמי שימוש לשנה | K19: שיעור דמי היתר | L19: דמי היתר
A20: מבנה 1 - בית ראשון | H20: ='תחשיב לפי שווי שומה (2)'!B8 -> 12000 | I20: 0 | J20: =D20*G20*H20*I20 -> 0 | K20: 0.51 | L20: ='[1]תחשיב לפי שווי שומה (2)'!$B$26*G20 -> 0
A21: מבנה 1 - פרגולה | H21: =H20 -> 12000 | I21: 0 | J21: =D21*G21*H21*I21 -> 0 | K21: 0.51 | L21: ='[1]תחשיב לפי שווי שומה (2)'!$B$26*G21 -> 0
A22: מבנה 7 - יח"ד שניה | H22: =H21 -> 12000 | I22: 0.05 | J22: =D22*G22*H22*I22 -> 0 | K22: 0.51 | L22: ='[1]תחשיב לפי שווי שומה (2)'!$B$26*G22 -> 0
A23: מבנה 4 - יח"ד שלישית | H23: =H22 -> 12000 | I23: 0.05 | J23: =D23*G23*H23*I23 -> 0 | K23: 0.51 | L23: ='[1]תחשיב לפי שווי שומה (2)'!$B$26*G23 -> 0
A24: מבנה 4 - פל"ח | I24: 0.05 | J24: =D24*G24*H24*I24 -> 0 | K24: 0.51 | L24: =H24*K24 -> 0
