Workbook

Sheet תחשיב לפי שווי שומה (2)
A2: מ"ר אקו' נחלה היוון מלא 3 דונם | B2: ='מ"ר אקו'' נחלה'!I14 -> 1087.5
A3: מ"ר אקו' נחלה היוון מלא 2.5 דונם | B3: ='מ"ר אקו'' נחלה'!D14 -> 1037.5
A4: מ"ר אקו' פוטנציאל | B4: ='מ"ר אקו'' נחלה'!D31 -> 262.78961
A5: מ"ר אקו' נחלה 3.75% | B5: ='מ"ר אקו'' נחלה'!D59 -> 806.25
A6: מ"ר אקו' מגרש מפוצל | B6: ='מ"ר אקו'' נחלה'!D46 -> 286.8 | C6: מ"ר ל-29.75% | D6: ='מ"ר אקו'' נחלה'!I39 -> 245
A7: שווי מ"ר אקו' מגורים | B7: ='ניתוח איזור לעסקאות דמה'!C7 -> 28000 | C7: שווי מ"ר משרדים | D7: 2500
C8: שווי מ"ר אחסנה | D8: ='ניתוח איזור לעסקאות דמה'!#REF! -> #REF! | E8: 1.17
B9: מ"ר אקו' | C9: דמי חכירה/ פיצול | D9: עלות אקו' | E9: מע"מ | F9: בש"ח | G9: בניכוי פיתוח
A10: היוון 3.75% | B10: =B5 -> 806.25 | C10: 0.0375 | D10: =C10*B10 -> 30.234375 | E10: 1 | F10: =D10*$B$7*E10 -> 846562.5 | G10: ='מ"ר אקו'' נחלה'!D60*-3.75% -> -6562.5 | H10: =SUM(F10:G10) -> 840000
A11: פיצול - חלק בהנחה | B11: =D6 -> 245 | C11: 0.2925 | D11: =C11*B11 -> 71.6625 | E11: 1 | F11: =D11*$B$7*E11 -> 2006550 | G11: =-'מ"ר אקו'' נחלה'!D47*C11 -> -29250 | H11: =SUM(F11:G11) -> 1977300
A12: פיצול חלק ללא הנחה | B12: =B6-B11 -> 41.8 | C12: 0.33 | D12: =C12*B12 -> 13.794 | E12: 1 | F12: =D12*$B$7*E12 -> 386232 | G12: =G11*53/245 -> -6327.551 | H12: =SUM(F12:G12) -> 379904.45
A13: סה"כ פיצול | B13: =SUM(B11:B12) -> 286.8 | F13: =SUM(F11:F12) -> 2392782 | H13: =SUM(H11:H12) -> 2357204.4
A14: היטל השבחה על פיצול | B14: ='מ"ר אקו'' נחלה'!I39 -> 245 | C14: =C34 -> 0.425 | D14: =B14*C14 -> 104.125 | E14: 1 | F14: =D14*$B$7 -> 2915500
A15: דמי רכישה | B15: ='זיכוי דמי היתר ששולמו'!R34 -> 1157.0896 | C15: 0.2 | D15: =C15*B15 -> 231.41792 | E15: 1 | F15: =D15*$B$7*E15 -> 6479701.8 | G15: -81510 | H15: =SUM(F15:G15) -> 6398191.8
A16: דמי היתר 1 מ"ר מגורים | B16: 1 | C16: 0.91 | D16: =C16*B16 -> 0.91 | E16: 1 | F16: 1486
A17: דמי היתר 1 מ"ר שירות | B17: 0.5 | C17: 0.91 | D17: =C17*B17 -> 0.455 | E17: 1 | F17: =F16/2 -> 743 | G17: =F17*#REF!*5%*1.17 -> #REF!
A18: דמי היתר 1 מ"ר מרתף | B18: 0.7 | C18: 0.91 | D18: =C18*B18 -> 0.637 | E18: 1 | F18: =D18*$B$7*E18 -> 17836
A19: היוון 1 מ"ר חצר נוספים | B19: 0.075 | C19: 0.91 | D19: =C19*B19 -> 0.06825 | E19: 1 | F19: =D19*$B$7*E19 -> 1911
A20: דמי שימוש משרדים 1 מ"ר לשנה | B20: 1 | C20: 0.05 | D20: =C20*B20 -> 0.05 | E20: 1 | F20: =D20*$D$7*E20 -> 125
A21: דמי היתר בריכה 1 מ"ר | B21: 0.3 | C21: 0.91 | D21: =C21*B21 -> 0.273 | E21: 1 | F21: =D21*$B$7*E21 -> 7644
A22: דמי היתר משרד פלח | B22: 1 | C22: 0.91 | D22: =C22*B22 -> 0.91 | E22: 1 | F22: =E22*D22*$D$7 -> 2275
A23: דמי שימוש 1 מ"ר למגורים | B23: 1 | C23: 0.05 | D23: =C23*B23 -> 0.05 | E23: 1 | F23: =D23*E23*B7 -> 1400
A26: מחשבון רמ"י
A28: היטל השבחה פיצול בית שלישי (מגרש ראשון)
B29: עבור מגרש 350 | C29: מקדם | D29: עבור 1 מ"ר אקו'
A30: אחרי מגרש מפוצל | B30: ='מ"ר אקו'' נחלה'!D46*'תחשיב לפי שווי שומה (2)'!$B$7 -> 8030400 | C30: 1 | D30: =C30*$B$7 -> 28000
A31: לפני חצר שולית | B31: =350*$B$7*C31 -> 1470000 | C31: 0.15 | D31: =C31*$B$7 -> 4200
A33: השבחה | B33: =B30-B31 -> 6560400 | C33: =C30-C31 -> 0.85 | D33: =C33*$B$7 -> 23800
A34: היטל | B34: =B33*50% -> 3280200 | C34: =C33*50% -> 0.425 | D34: =C34*$B$7 -> 11900
A36: היטל השבחה פיצול בית שני (מגרש שני)
B37: עבור מגרש 350 | C37: מקדם | D37: עבור 1 מ"ר אקו'
A38: אחרי מגרש מפוצל | B38: ='מ"ר אקו'' נחלה'!D46*'תחשיב לפי שווי שומה (2)'!$B$7 -> 8030400 | C38: 1 | D38: =C38*$B$7 -> 28000
A39: לפני מגרש לא מפוצל | B39: =B38*70% -> 5621280 | C39: 0.7 | D39: =C39*$B$7 -> 19600
A41: השבחה | B41: =B38-B39 -> 2409120 | C41: =C38-C39 -> 0.3 | D41: =C41*$B$7 -> 8400
A42: היטל | B42: =B41*50% -> 1204560 | C42: =C41*50% -> 0.15 | D42: =C42*$B$7 -> 4200

Sheet היטל השבחה בית שלישי
C4: מצב קודם
C5: מהות | D5: שטח | E5: מקדם | F5: סה"כ
C6: חצר שולית | D6: 350 | E6: 0.15 | F6: =E6*D6 -> 52.5
C9: מצב חדש
C10: שטח מגרש | D10: 500
C11: מהות | D11: שטח | E11: מקדם | F11: סה"כ
C12: עיקרי ק.ק | D12: 200 | E12: 1 | F12: =D12*E12 -> 200
C13: ממ"ד | D13: 12.5 | E13: 1 | F13: =D13*E13 -> 12.5
C14: יתרת שירות | D14: 15 | E14: 1 | F14: =D14*E14 -> 15
C15: מרתף | D15: 100 | E15: 0.6 | F15: =D15*E15 -> 60
C16: חצר | D16: =D10-D12-D13-D14 -> 272.5 | E16: 0.25 | F16: =D16*E16 -> 68.125
C17: סה"כ שטח אקו' | F17: =SUM(F12:F16) -> 355.625
C21: סה"כ השבחה | F21: =F17-F6 -> 303.125
C22: היטל השבחה | F22: =F21*0.5 -> 151.5625
C23: שווי מ"ר מבונה אק' | F23: ='תחשיב לפי שווי שומה (2)'!B7 -> 28000
C24: סה"כ היטל השבחה | F24: =F22*F23 -> 4243750
C27: שווי מ"ר בנוי | D27: =28000 -> 28000
C28: בניכוי חצר שולית | D28: =D27*0.85 -> 23800

Sheet מ"ר אקו' נחלה
A2: גודל חלקת מגורים (להיוון) | B2: 2500 | C2: לפי שומת חכמון | F2: גודל חלקת מגורים (להיוון) | G2: 3000
B3: מ"ר | C3: מקדם | D3: אקו' | G3: מ"ר | H3: מקדם | I3: אקו'
A4: עיקרי | B4: 455 | C4: 1 | D4: =C4*B4 -> 455 | F4: =A4 -> עיקרי | G4: =B4 -> 455 | H4: =C4 -> 1 | I4: =H4*G4 -> 455
A5: מרחבים מוגנים | B5: 25 | C5: 0.9 | D5: =C5*B5 -> 22.5 | F5: =A5 -> מרחבים מוגנים | G5: =B5 -> 25 | H5: =C5 -> 0.9 | I5: =H5*G5 -> 22.5
A6: יתרת ש"ש | B6: 30 | C6: 0.4 | D6: =C6*B6 -> 12 | F6: =A6 -> יתרת ש"ש | G6: =B6 -> 30 | H6: =C6 -> 0.4 | I6: =H6*G6 -> 12
A7: מרתף | B7: 200 | C7: 0.5 | D7: =C7*B7 -> 100 | F7: =A7 -> מרתף | G7: =B7 -> 200 | H7: =C7 -> 0.5 | I7: =H7*G7 -> 100
A8: סה"כ תכסית | B8: =SUM(B4:B6) -> 510 | F8: סה"כ תכסית | G8: =SUM(G4:G7) -> 710
A9: סה"כ חצר | B9: =B2-B8 -> 1990 | F9: סה"כ חצר | G9: =G2-G8 -> 2290
A10: חצר אפקטיבית | B10: 1000 | C10: 0.25 | D10: =C10*B10 -> 250 | F10: חצר אפקטיבית | G10: =B10 -> 1000 | H10: 0.25 | I10: =H10*G10 -> 250
A11: יתרת חצר | B11: =B9-B10 -> 990 | C11: 0.2 | D11: =C11*B11 -> 198 | F11: יתרת חצר | G11: =B11 -> 990 | H11: 0.2 | I11: =H11*G11 -> 198
F12: חצר רחוקה מאוד | G12: 500 | H12: 0.1 | I12: =G12*H12 -> 50
A13: סה"כ מ"ר אקו' | B13: =SUM(B4:B11) -> 5200 | D13: =SUM(D4:D12) -> 1037.5 | F13: סה"כ מ"ר אקו' | G13: =SUM(G4:G11) -> 5700 | I13: =SUM(I4:I12) -> 1087.5
A14: סה"כ מ"ר אקו' מעוגל | D14: =D13 -> 1037.5 | F14: סה"כ מ"ר אקו' מעוגל | I14: =I13 -> 1087.5
A15: עלויות פיתוח | D15: 247000 | F15: עלויות פיתוח | I15: 263000
A17: פוטנציאל | B17: 350
A18: שטח מגרש | B18: 500
A19: מהות | B19: שטח | C19: מקדם | D19: סה"כ
A20: עיקרי ק.ק | B20: 200 | C20: 1 | D20: =B20*C20 -> 200
A21: ממ"ד | B21: 12.5 | C21: 1 | D21: =B21*C21 -> 12.5
A22: יתרת שירות | B22: 15 | C22: 1 | D22: =B22*C22 -> 15
A23: מרתף | B23: 100 | C23: 0.6 | D23: =B23*C23 -> 60
A24: חצר | B24: =B18-B20-B21-B22 -> 272.5 | C24: 0.25 | D24: 68.125 | H24: =876+73 -> 949
A25: סה"כ שטח אקו' | D25: =SUM(D20:D24) -> 355.625
G26: =D13+D29 -> 1336.0896
A27: סה"כ שטח אקו' | D27: =D25 -> 355.625
A28: דחייה למימוש | D28: =1/1.06^3 -> 0.83961928
A29: סה"כ לאחר דחיה | D29: =D27*D28 -> 298.58961
A30: ניכוי תשלום דמי היתר | D30: ='זיכוי דמי היתר ששולמו'!L20 -> 35.8
A31: סה"כ | D31: =D29-D30 -> 262.78961
A35: מגרש מפוצל הרחבת אביגדור רק במקום 180 220 עיקרי
A36: גודל מגרש | B36: 350 | C36: לפי שומת זיו כהן בשפיר | F36: חלק ה29.25% | J36: שויי מ"ר
A37: מגורים עיקרי בהרחבה | B37: 220 | C37: 1 | D37: =B37*C37 -> 220 | F37: =A37 -> מגורים עיקרי בהרחבה | G37: 160 | H37: 1 | I37: =G37*H37 -> 160
A38: שירות - מרתף | B38: 40 | C38: 0.5 | D38: =B38*C38 -> 20 | F38: חצר | G38: =500-G37 -> 340 | H38: 0.25 | I38: =G38*H38 -> 85
A39: מרחבים מוגנים | B39: 12 | C39: 0.9 | D39: =B39*C39 -> 10.8 | F39: מ"ר אקו' שנכלל בהנחה | I39: =I37+I38 -> 245 | J39: ='תחשיב לפי שווי שומה (2)'!B7 -> 28000 | K39: =I39*J39 -> 6860000 | L39: 0.2925 | M39: =K39*L39 -> 2006550
A40: מסחן | B40: 11 | C40: 0.5 | D40: =B40*C40 -> 5.5 | F40: מ"ר אקו' שלא נכלל בהנחה | I40: =D46-I39 -> 41.8 | J40: =J39 -> 28000 | K40: =I40*J40 -> 1170400 | L40: 0.33 | M40: =K40*L40 -> 386232
A41: סככת חניה | B41: 30 | C41: 0.35 | D41: =B41*C41 -> 10.5 | M41: =SUM(M39:M40) -> 2392782
A42: מבנה עזר - יתרת שטח | C42: 0.5 | D42: =B42*C42 -> 0
A43: סה"כ תכסית | B43: =SUM(B37:B42)-B38 -> 273
A44: סה"כ חצר | B44: =B36-B43 -> 77
A45: חצר אפקטיבית | B45: 80 | C45: 0.25 | D45: =B45*C45 -> 20
...

Sheet זיכוי דמי היתר ששולמו
I3: מ"ר להיוון | J3: ='מ"ר אקו'' נחלה'!D14+'מ"ר אקו'' נחלה'!D29 -> 1336.0896
C4: בית ראשון בהיתר | I4: מ"ר ששולמו | J4: =F11+F18-160-160 -> 179 | Q4: שווי מ"ר מבונה אקו' | R4: 28000
C5: מהות | D5: שטח | E5: מקדם | F5: סה"כ | J5: =J3-J4 -> 1157.0896 | Q5: שטח אקו' נחלה | R5: ='מ"ר אקו'' נחלה'!D14+'מ"ר אקו'' נחלה'!D29 -> 1336.0896
C6: עיקרי | D6: 179 | E6: 1 | F6: =D6*E6 -> 179 | Q6: תשלום בשיעור 20% | R6: =R4*R5*20% -> 7482101.8
Q7: בניכוי עלויות פיתוח | R7: =R6-80000 -> 7402101.8
C9: שירות | D9: 37 | E9: 0.5 | F9: =D9*E9 -> 18.5 | Q9: דמי היתר ששולמו
C10: מרתף | D10: 135 | E10: 0.5 | F10: =D10*E10 -> 67.5 | Q10: בית קדמי A | R10: שטח | S10: מקדם | T10: סה"כ
C11: סה"כ | F11: =SUM(F6:F10) -> 265 | Q11: עיקרי קומה א' | R11: 179 | S11: 1 | T11: =R11*S11 -> 179
C12: בניכוי 160 פטור | F12: =F11-160 -> 105 | Q12: שירות | R12: 37 | S12: 0.5 | T12: =R12*S12 -> 18.5
Q13: מרתף | R13: 135 | S13: 0.5 | T13: =R13*S13 -> 67.5
C14: בית שני בהיתר | Q14: סה"כ שטח אקו' | T14: =SUM(T11:T13) -> 265
C15: מהות | D15: שטח | E15: מקדם | F15: סה"כ | Q15: שטח פטור | T15: 160
C16: עיקרי | D16: =131+103-15 -> 219 | E16: 1 | F16: =E16*D16 -> 219 | Q16: שולם | T16: =T14-T15 -> 105
C17: שירות | D17: 30 | E17: 0.5 | F17: =E17*D17 -> 15
C18: סה"כ | F18: =SUM(F16:F17) -> 234
C19: בניכוי 160 פטור | F19: =F18-160 -> 74 | I19: סה"כ דמי היתר ששולמו לזיכוי | L19: =F12+F19 -> 179
C20: סה"כ דמי היתר עודפים ששולמו | F20: =F19+F12 -> 179 | I20: זיכוי מתוך הדמי רכישה 20% | L20: =L19*0.2 -> 35.8 | Q20: בית אחורי B | R20: שטח | S20: מקדם | T20: סה"כ
C21: זיכוי מתוך הדמי רכישה 20% | F21: =F20*0.2 -> 35.8 | Q21: עיקרי | R21: 219 | S21: 1 | T21: =S21*R21 -> 219
Q22: שירות | R22: 30 | S22: 0.5 | T22: =S22*R22 -> 15
C23: דמי רכישה | Q23: סה"כ שטח אקו' | T23: =SUM(T21:T22) -> 234
C24: סה"כ שטח אקו' בנחלה | E24: 1336 | Q24: שטח פטור | T24: 160
C25: שטח לתשלום 20% | E25: =E24*0.2 -> 267.2 | Q25: שולם | T25: =T23-T24 -> 74
C26: שווי מ"ר מבונה | E26: =28000 -> 28000 | I26: =E25*E26 -> 7481600
E27: ='תחשיב לפי שווי שומה (2)'!B17 -> 0.5 | Q27: סה"כ שטח נוסף שנרכש | T27: =T25+T16 -> 179
E28: ='תחשיב לפי שווי שומה (2)'!B18 -> 0.7
E29: ='תחשיב לפי שווי שומה (2)'!B19 -> 0.075
E30: ='תחשיב לפי שווי שומה (2)'!B20 -> 1
Q32: שטח אקו' נחלה | R32: =R5 -> 1336.0896
Q33: שטח שנרכש | R33: =T27 -> 179
Q34: יתרת שטח לתשלום לאחר זיכוי | R34: =R32-R33 -> 1157.0896
Q35: שווי מ"ר מבונה אקו' | R35: 28000
D36: תחשיב ההיוון | E36: שווי קרקע | F36: שיעור | G36: סכום | Q36: תשלום בשיעור 20% לאחר זיכוי | R36: =R34*R35*0.2 -> 6479701.8
D37: היוון 20% | E37: =J3*'תחשיב לפי שווי שומה (2)'!B7 -> 37410509 | F37: 0.2 | G37: =E37*F37 -> 7482101.8 | Q37: בניכוי עלויות פיתוח | R37: =R36-80000 -> 6399701.8
D38: שווי דמי היתר ששוולמו | E38: =-T27*'תחשיב לפי שווי שומה (2)'!B7 -> -5012000 | F38: 0.2 | G38: =E38*F38 -> -1002400 | Q38: סה"כ זיכוי | R38: =R7-R37 -> 1002400
D39: ניכוי פיתוח | G39: -79702
D40: תשלום היוון מלא | G40: =SUM(G37:G39) -> 6399999.8

Sheet ניתוח איזור לעסקאות דמה
B2: שומת
B3: שווי מ"ר אקו' | C3: =O15 -> 30314.986
B4: אחוז שנתי
B5: שנים להיוון
B6: שווי עדכני | C6: =O17 -> 27283.488
B7: שווי לשומה | C7: 28000
B9: תחשיב לפי מכירות בהרחבה
B10: תאריך | C10: גו"ח | D10: מחיר עסקה | E10: שטח המגרש | F10: שטח בנוי | G10: שנת בניה | H10: התאמה למועד קובע | I10: בניכוי יזמי 5% | J10: עלויות בניה למ"ר | K10: יתרה לקרע כולל | L10: שטח אקו' | M10: שווי מתואם כולל מעמ ופיתוח
C14: גוש חלקה | D14: יום מכירה | E14: תמורה מוצהרת בש"ח | F14: שווי מכירה בש"ח | G14: מהות | H14: חלק נמכר | I14: ישוב | J14: שנת בניה | K14: שטח חלקה | L14: שטח בנוי | M14: תרומת הבנוי | N14: שווי יתרת מגרש | O14: שווי מ"ר מבונה
C15: 008922-0039 | D15: 45008 | E15: 16000000 | F15: 16000000 | G15: דירת מגורים | H15: 1 | I15: רשפון | J15: 1998 | K15: 497 | L15: 299 | M15: =7000*L15 -> 2093000 | N15: =F15-M15 -> 13907000 | O15: =F32 -> 30314.986
N16: מקדם נחלה | O16: 0.9
C17: תבע | D17: עיקרי | E17: שירות | F17: מרתף | G17: קומות | H17: תכסית | I17: שטח חלקה | N17: מתואם | O17: =O15*O16 -> 27283.488
C18: חש/במ/17/13 | D18: 220 | E18: 60 | F18: קונטור ולא יותר מ140 | G18: 2 | H18: 200 | I18: =K15 -> 497
C20: ניתוח שטח אקו' עסקת ההשוואה
C21: מהות | D21: שטח | E21: מקדם | F21: סה"כ
C22: עיקרי ק.ק | D22: =D18/2-6 -> 104 | E22: 1 | F22: =D22*E22 -> 104
C23: ממ"ד | D23: 12 | E23: 1 | F23: =D23*E23 -> 12
C24: עיקרי ק.א | D24: =D18-D22 -> 116 | E24: 1 | F24: =D24*E24 -> 116
C25: חדר יציאה לגג | D25: 23 | E25: 1.3 | F25: =D25*E25 -> 29.9
C26: יתרת שירות עילי | D26: =E18-D23 -> 48 | E26: 0.5 | F26: =D26*E26 -> 24
C27: מרתף | D27: =D22+D23 -> 116 | E27: 0.6 | F27: =D27*E27 -> 69.6
C28: בריכה | D28: 50 | E28: 0.4 | F28: =D28*E28 -> 20
C29: חצר | D29: =I18-D22-D23-D26 -> 333 | E29: 0.25 | F29: =D29*E29 -> 83.25
C30: סה"כ שטח אקו' | F30: =SUM(F22:F29) -> 458.75
C31: שווי יתרת מגרש | F31: =N15 -> 13907000
C32: שווי מ"ר מבונה אקו' | F32: =F31/F30 -> 30314.986

Sheet חישוב גדלי בתים
A2: קיים | B2: חתימת רמ"י | C2: חתימת ועדה | D2: מבנה מס' 1- בית מגורים | E2: מבנה מס' 2- פרגולה | F2: מבנה מס' 3- מלונות כלבים | G2: מבנה מס' 4-מלונות כלבים | H2: מבנה מס' 5-סככת חניה | I2: מבנה מס' 6-קונטיינר מגורים עובד | J2: מבנה מס' 7- לול תרנגולות | K2: מבנה מס' 8-אורוות סוסים | L2: מבנה מס' 9-סככה | M2: מבנה מס' 10-מכולה
A3: מפת מדידה - מפרט רמ"י | D3: 580 | E3: 15 | F3: 44 | G3: 45 | H3: 85 | I3: 15 | J3: 72 | K3: 152 | L3: 20 | M3: 15
A4: קומת עמודים
A5: שטחי מגורים - קרקע | D5: 429
A6: קומה א' | D6: 153
A7: מרתף | D7: 135
A8: פרגולות | D8: 150
A9: פרגולה קדמית
A10: פרגולה צידית
A11: בליטת גג
A12: שרות (ממ"ד)
A13: קומת עמודים בהיתר
A14: קומת עמודים ללא היתר
A15: סה"כ מבנה | D15: =SUM(D4:D14) -> 867 | E15: =SUM(E3:E14) -> 15 | F15: =SUM(F3:F14) -> 44 | G15: =SUM(G3:G14) -> 45 | H15: =SUM(H3:H14) -> 85 | I15: =SUM(I3:I14) -> 15 | J15: =SUM(J3:J14) -> 72 | K15: =SUM(K3:K14) -> 152 | L15: =SUM(L3:L14) -> 20 | ... S15: =SUM(S3:S14) -> 0
A16: בהיתר | B16: חתימת רמ"י | C16: חתימת ועדה
A17: היתר שנת2010 | B17: V | C17: V
A18: סה"כ מרתף | D18: 135
A19: סה"כ קרקע | D19: 420
A20: סה"כ א' | D20: 103
A21: סה"כ פרגולות | D21: 37
A25: בהתר | D25: =SUM(D18:D24) -> 695 | E25: =SUM(E19:E24) -> 0 | F25: =SUM(F17:F24) -> 0 | G25: =SUM(G17:G24) -> 0 | H25: =SUM(H17:H24) -> 0 | I25: =SUM(I17:I24) -> 0 | J25: =SUM(J17:J24) -> 0 | K25: =SUM(K17:K24) -> 0 | L25: =SUM(L17:L24) -> 0 | M25: =SUM(M17:M24) -> 0 | ... S25: =SUM(S17:S24) -> 0
A26: פערים | D26: =D15-D25 -> 172 | E26: =E15-E25 -> 15 | F26: =F15-F25 -> 44 | G26: =G15-G25 -> 45 | H26: =H15-H25 -> 85 | I26: =I15-I25 -> 15 | J26: =J15-J25 -> 72 | K26: =K15-K25 -> 152 | ... S26: =S15-S25 -> 0
A28: פער מרפסות | D28: =D10+D9 -> 0
E29: =E3*9300*5%*7 -> 48825
E30: =375-E25-F25-I25 -> 375
A32: דמי היתר ששולמו
A33: בית 1 | E33: =-D15 -> -867
A34: בית 2 | E34: =-E15 -> -15
A35: מחסן | E35: =I25 -> 0
A36: סה"כ | E36: =SUM(E32:E35) -> -882
A37: היוון 3.75 | E37: 375
A38: סה"כ מטרים | E38: =SUM(E36:E37) -> -507
A39: קיים | E39: =-E25-F25-I25 -> 0
A40: נותרו לבניה | E40: =SUM(E38:E39) -> -507
A44: פערים בית מגורים
A45: קומה תחתונה | D45: היתר | E45: בפועל | F45: הפרש
A46: מגורים | F46: =E46-D46 -> 0
A47: מקלט | F47: =E47-D47 -> 0
A48: סה"כ קומת קרקע | D48: =SUM(D46:D47) -> 0 | E48: =SUM(E46:E47) -> 0 | F48: =E48-D48 -> 0
A50: קומה עליונה | D50: היתר | E50: בפועל | F50: הפרש
...

Sheet תבעות
A2: מקור | B2: מס' תבע | C2: תאריך | D2: זכויות | F2: היטל השבחה
A5: גובמאפ | B5: חש/13 | C5: 25394 | D5: 1 או 2 מחוברים | E5: בתים
A6: אתר הועדה | B6: חש/6/13 | C6: 32226 | D6: בריכה
A7: תבע עכשיו | B7: חש/10/10 | C7: 32524 | D7: מרתף והגדלת שירות
A8: תבע עכשיו | B8: חש/11/10 | C8: 33528 | D8: 2.5 | E8: בתים
A9: אתר הועדה | B9: חש/מק/36/13 | C9: 40206 | D9: 2.5 | E9: בתים

Sheet גיליון1
B2: טבלאת סיכום עלויות דמי שימוש
B3: דמי שימוש | C3: מגורים | E3: פרגולות
B4: בית ראשון - מבנה 1 | C4: 0 | E4: 0
B5: בית שני - מבנה 4 | C5: 140000 | E5: =6000*2 -> 12000
B6: בית שלישי - מבנה 1 עבור 100 מ"ר | C6: =46500*7 -> 325500 | E6: 0
B7: בית רביעי - מבנה 2 | C7: =13000*7 -> 91000 | E7: =4000*7 -> 28000
B8: בית חמישי - מבנה 5 | C8: =65000*7 -> 455000 | E8: 50000 | J8: V
B9: טבלאת סיכום עלויות הסדרה | J9: X
B10: דמי היתר - להסדרה | C10: מ"ר לתש' עיקרי | D10: תשלום עיקרי | E10: מ"ר פרגולות | F10: תשלום פרגולות
B11: בית ראשון - מבנה 1 | C11: =197-160 -> 37 | D11: =C11*6605 -> 244385 | E11: 35 | F11: =E11*6605/2 -> 115587.5
B12: בית שני - מבנה 4 | C12: 0 | D12: 0 | E12: =147+24-160 -> 11 | F12: =E12*6605/2 -> 36327.5
B13: בית שלישי - מבנה 1 | C13: יוסדר כמבנה אחד עם הבית הראשון
B14: בית רביעי - מבנה 2 | C14: מומלץ לפינוי / הסרה
B15: בית חמישי - מבנה 5 | C15: יוסדר כבית שלישי - יוצג מטה
B17: טבלאת סיכום עלויות
B18: דמי שימוש - 7 שנים | C18: מגורים | E18: פרגולות
B19: בית ראשון - מבנה 1 | C19: 0 | E19: 0
B20: בית שני - מבנה 4 | C20: 70000 | E20: =6000*7 -> 42000
B21: בית שלישי - מבנה 1 | C21: =46500*7 -> 325500 | E21: 0
B22: בית רביעי - מבנה 2 | C22: =13000*7 -> 91000 | E22: =4000*7 -> 28000
B23: בית חמישי - מבנה 5 | C23: =65000*7 -> 455000 | E23: =7000*7 -> 49000
B25: דמי היתר - להסדרה | C25: מ"ר לתש' עיקרי | D25: תשלום עיקרי | E25: מ"ר פרגולות | F25: תשלום פרגולות
B26: בית ראשון - מבנה 1 | C26: =197-160 -> 37 | D26: =C26*6605 -> 244385 | E26: 35 | F26: =E26*6605/2 -> 115587.5
B27: בית שני - מבנה 4 | C27: 0 | D27: =C27*6605 -> 0 | E27: =147+24-160 -> 11 | F27: =E27*6605/2 -> 36327.5
B28: בית שלישי - מבנה 1 | C28: יוסדר כמבנה אחד עם הבית הראשון
B29: בית רביעי - מבנה 2 | C29: 0 | D29: 0 | E29: 0 | F29: 0
B30: בית חמישי - מבנה 5 | C30: 0 | D30: 0 | E30: =139+31-160 -> 10 | F30: =E30*6605/2 -> 33025
B35: טבלאת סיכום עלויות בית שלישי
B36: הדרך אל הבית השלישי | C36: מגורים | E36: פרגולות
B37: עלויות הסדרה | C37: ע"פ שלב 1 - 1,100,000 ₪
B38: היוון 3.75% דמי חכירה | C38: ע"פ שלב 2 - 260,000 ₪
B39: תב"ע | C39: שכ"ט בעלי מקצוע
B40: היתר בניה - דמי היתר | C40: דמי היתר 455,000 ₪ + היטל השבחה

Sheet בקרה
A2: תב"עות | B2: פלח
B3: מגורים
N7: חריגה מקו
A8: עדיפות לאומית | N8: גבול
A9: סיווג | D9: קישור לפרק 4.2 סימן א רשימת איזורי עדיפות | N9: בניין
N10: לא
A15: מיפוי | B15: חריגה מקווים
A19: מבנים | B19: חריגה מקו | C19: היתר | D19: גודל קיים | E19: גודל בהיתר | F19: שימוש | G19: מקדם | H19: שווי שימוש | I19: שיעור דמי שימוש | J19: דמי שימוש לשנה | K19: שיעור דמי היתר | L19: דמי היתר
A20: מבנה 1 - בית ראשון | H20: ='תחשיב לפי שווי שומה (2)'!B7 -> 28000 | I20: 0 | J20: =D20*G20*H20*I20 -> 0 | K20: 0.51 | L20: ='[1]תחשיב לפי שווי שומה (2)'!$B$26*G20 -> 0
A21: מבנה 1 - פרגולה | H21: =H20 -> 28000 | I21: 0 | J21: =D21*G21*H21*I21 -> 0 | K21: 0.51 | L21: ='[1]תחשיב לפי שווי שומה (2)'!$B$26*G21 -> 0
A22: מבנה 7 - יח"ד שניה | H22: =H21 -> 28000 | I22: 0.05 | J22: =D22*G22*H22*I22 -> 0 | K22: 0.51 | L22: ='[1]תחשיב לפי שווי שומה (2)'!$B$26*G22 -> 0
A23: מבנה 4 - יח"ד שלישית | H23: =H22 -> 28000 | I23: 0.05 | J23: =D23*G23*H23*I23 -> 0 | K23: 0.51 | L23: ='[1]תחשיב לפי שווי שומה (2)'!$B$26*G23 -> 0
A24: מבנה 4 - פל"ח | I24: 0.05 | J24: =D24*G24*H24*I24 -> 0 | K24: 0.51 | L24: =H24*K24 -> 0
