Workbook

Sheet תחשיב לפי שווי שומה (2)
A2: מ"ר אקו' נחלה היוון מלא 3 דונם | B2: ='מ"ר אקו'' נחלה'!I14 -> 1114.8
A3: מ"ר אקו' נחלה היוון מלא 2.5 דונם | B3: ='מ"ר אקו'' נחלה'!D14 -> 1064.8
A4: מ"ר אקו' פוטנציאל | B4: ='מ"ר אקו'' נחלה'!D28 -> 0
A5: דמי היתר שנרכשו | B5: ='מ"ר אקו'' נחלה'!D38 -> 61
A6: מ"ר אקו' נחלה 3.75% | B6: ='מ"ר אקו'' נחלה'!D86 -> 806.25
A7: מ"ר אקו' מגרש מפוצל | B7: ='מ"ר אקו'' נחלה'!D57 -> 260.6 | C7: מ"ר ל-29.75% | D7: ='מ"ר אקו'' נחלה'!I50 -> 207.5
A8: שווי מ"ר אקו' מגורים | B8: ='ניתוח איזור לעסקאות דמה'!C7 -> 9700 | C8: שווי מ"ר משרדים | D8: 2500
C9: שווי מ"ר אחסנה | D9: ='ניתוח איזור לעסקאות דמה'!#REF! -> #REF! | E9: 1.17
B10: מ"ר אקו' | C10: דמי חכירה/ פיצול | D10: עלות אקו' | E10: מע"מ | F10: בש"ח | G10: בניכוי פיתוח
A11: היוון 3.75% | B11: =B6 -> 806.25 | C11: 0.0375 | D11: =C11*B11 -> 30.234375 | E11: 1 | F11: =D11*$B$8*E11 -> 293273.44 | G11: ='מ"ר אקו'' נחלה'!D87*-3.75% -> -6562.5 | H11: =SUM(F11:G11) -> 286710.94
A12: פיצול - חלק בהנחה | B12: =D7 -> 207.5 | C12: 0.2925 | D12: =C12*B12 -> 60.69375 | E12: 1 | F12: =D12*$B$8*E12 -> 588729.38 | G12: =-'מ"ר אקו'' נחלה'!D58*C12 -> -29250 | H12: =SUM(F12:G12) -> 559479.38
A13: פיצול חלק ללא הנחה | B13: =B7-B12 -> 53.1 | C13: 0.33 | D13: =C13*B13 -> 17.523 | E13: 1 | F13: =D13*$B$8*E13 -> 169973.1 | G13: =G12*53/245 -> -6327.551 | H13: =SUM(F13:G13) -> 163645.55
A14: סה"כ פיצול | B14: =SUM(B12:B13) -> 260.6 | F14: =SUM(F12:F13) -> 758702.48 | H14: =SUM(H12:H13) -> 723124.92
A15: היטל השבחה על פיצול | B15: ='מ"ר אקו'' נחלה'!I50 -> 207.5 | C15: =C35 -> 0.425 | D15: =B15*C15 -> 88.1875 | E15: 1 | F15: =D15*$B$8 -> 855418.75
A16: דמי רכישה | B16: =B3+B4-B5 -> 1003.8 | C16: 0.33 | D16: =C16*B16 -> 331.254 | E16: 1 | F16: =D16*$B$8*E16 -> 3213163.8 | G16: =-'מ"ר אקו'' נחלה'!D15*C16 -> -81510 | H16: =SUM(F16:G16) -> 3131653.8
A17: דמי היתר 1 מ"ר מגורים | B17: 1 | C17: 0.91 | D17: =C17*B17 -> 0.91 | E17: 1 | F17: 1486
A18: דמי היתר 1 מ"ר שירות | B18: 0.5 | C18: 0.91 | D18: =C18*B18 -> 0.455 | E18: 1 | F18: =F17/2 -> 743 | G18: =F18*#REF!*5%*1.17 -> #REF!
A19: דמי היתר 1 מ"ר מרתף | B19: 0.7 | C19: 0.91 | D19: =C19*B19 -> 0.637 | E19: 1 | F19: =D19*$B$8*E19 -> 6178.9
A20: היוון 1 מ"ר חצר נוספים | B20: 0.075 | C20: 0.91 | D20: =C20*B20 -> 0.06825 | E20: 1 | F20: =D20*$B$8*E20 -> 662.025
A21: דמי שימוש משרדים 1 מ"ר לשנה | B21: 1 | C21: 0.05 | D21: =C21*B21 -> 0.05 | E21: 1 | F21: =D21*$D$8*E21 -> 125
A22: דמי היתר בריכה 1 מ"ר | B22: 0.3 | C22: 0.91 | D22: =C22*B22 -> 0.273 | E22: 1 | F22: =D22*$B$8*E22 -> 2648.1
A23: דמי היתר משרד פלח | B23: 1 | C23: 0.91 | D23: =C23*B23 -> 0.91 | E23: 1 | F23: =E23*D23*$D$8 -> 2275
A24: דמי שימוש 1 מ"ר למגורים | B24: 1 | C24: 0.05 | D24: =C24*B24 -> 0.05 | E24: 1 | F24: =D24*E24*B8 -> 485
A27: מחשבון רמ"י
A29: היטל השבחה פיצול בית שלישי (מגרש ראשון)
B30: עבור מגרש 350 | C30: מקדם | D30: עבור 1 מ"ר אקו'
A31: אחרי מגרש מפוצל | B31: ='מ"ר אקו'' נחלה'!D57*'תחשיב לפי שווי שומה (2)'!$B$8 -> 2527820 | C31: 1 | D31: =C31*$B$8 -> 9700
A32: לפני חצר שולית | B32: =350*$B$8*C32 -> 509250 | C32: 0.15 | D32: =C32*$B$8 -> 1455
A34: השבחה | B34: =B31-B32 -> 2018570 | C34: =C31-C32 -> 0.85 | D34: =C34*$B$8 -> 8245
A35: היטל | B35: =B34*50% -> 1009285 | C35: =C34*50% -> 0.425 | D35: =C35*$B$8 -> 4122.5
A37: היטל השבחה פיצול בית שני (מגרש שני)
B38: עבור מגרש 350 | C38: מקדם | D38: עבור 1 מ"ר אקו'
A39: אחרי מגרש מפוצל | B39: ='מ"ר אקו'' נחלה'!D57*'תחשיב לפי שווי שומה (2)'!$B$8 -> 2527820 | C39: 1 | D39: =C39*$B$8 -> 9700
A40: לפני מגרש לא מפוצל | B40: =B39*70% -> 1769474 | C40: 0.7 | D40: =C40*$B$8 -> 6790
A42: השבחה | B42: =B39-B40 -> 758346 | C42: =C39-C40 -> 0.3 | D42: =C42*$B$8 -> 2910
A43: היטל | B43: =B42*50% -> 379173 | C43: =C42*50% -> 0.15 | D43: =C43*$B$8 -> 1455

Sheet סיכום עלויות פיצולים
H9: סיכום עלויות פיצול/ים לאחר הסדרה
H10: סוג תשלום | J10: פיצול מגרש ריק (זכות בית שלישי) - היוון 3.75% | L10: פיצול מגרש ריק (זכות בית שלישי)+ בית שני קיים - היוון מלא 33%
H12: דמי היוון 3.75%/33% | J12: 290000 | L12: 3100000
H14: תשלום בעבור פיצול | J14: 840000 | L14: -
H16: מס רכישה | J16: =(J14+J12)*0.06 -> 67800 | L16: =L12*6% -> 186000
H18: דמי היתר לרכוש במשק | J18: 1130000 | L18: -
H20: סה"כ | J20: =SUM(J12:K19) -> 2327800 | L20: =SUM(L12:M19) -> 3286000
H22: היטל השבחה - בעת מכר | J22: 1140000 | L22: =1140000+430000 -> 1570000
H28: דמי היתר לרכוש במשק לאחר פיצול
H29: זכויות בסיס | K29: 375
H30: מהות | I30: בפועל | J30: בסיס | K30: נרכש
H31: בית ראשון | I31: 180 | J31: 160 | K31: =I31-J31 -> 20
H32: יחידה צמודת קיר | I32: 55 | J32: 55 | K32: =I32-J32 -> 0
H33: בית שני | I33: 247 | J33: 160 | K33: =I33-J33 -> 87
H34: נרכש בעבר | K34: 7
H35: סה"כ נרכש | K35: =SUM(K31:K34) -> 114
H36: סה"כ חוזה לאחר הסדרה | K36: =K35+K29 -> 489
H37: פיצול | K37: =-160 -> -160
H38: חוזה לאחר פיצול | K38: =K36+K37 -> 329
H39: בנוי בפועל | K39: =247+180+55 -> 482
H40: שטח לרכוש | K40: =K39-K38 -> 153
H41: דמי היתר | K41: 7400
H42: סה"כ לרכוש | K42: =K41*K40 -> 1132200

Sheet מ"ר אקו' נחלה
A2: גודל חלקת מגורים (להיוון) | B2: 2500 | C2: לפי שומת חכמון | F2: גודל חלקת מגורים (להיוון) | G2: 3000
B3: מ"ר | C3: מקדם | D3: אקו' | G3: מ"ר | H3: מקדם | I3: אקו'
A4: עיקרי | B4: 575 | C4: 1 | D4: =C4*B4 -> 575 | F4: =A4 -> עיקרי | G4: =B4 -> 575 | H4: =C4 -> 1 | I4: =H4*G4 -> 575
A5: מרחבים מוגנים | B5: 36 | C5: 0.9 | D5: =C5*B5 -> 32.4 | F5: =A5 -> מרחבים מוגנים | G5: =B5 -> 36 | H5: =C5 -> 0.9 | I5: =H5*G5 -> 32.4
A6: יתרת ש"ש | B6: =184-B5 -> 148 | C6: 0.4 | D6: =C6*B6 -> 59.2 | F6: =A6 -> יתרת ש"ש | G6: =B6 -> 148 | H6: =C6 -> 0.4 | I6: =H6*G6 -> 59.2
A7: מבנה עזר - יתרת שטח | C7: 0.5 | D7: =C7*B7 -> 0 | F7: =A7 -> מבנה עזר - יתרת שטח | G7: =B7 -> 0 | H7: =C7 -> 0.5 | I7: =H7*G7 -> 0
A8: סה"כ תכסית | B8: =SUM(B4:B7) -> 759 | F8: סה"כ תכסית | G8: =SUM(G4:G7) -> 759
A9: סה"כ חצר | B9: =B2-B8 -> 1741 | F9: סה"כ חצר | G9: =G2-G8 -> 2241
A10: חצר אפקטיבית | B10: 1000 | C10: 0.25 | D10: =C10*B10 -> 250 | F10: חצר אפקטיבית | G10: =B10 -> 1000 | H10: 0.25 | I10: =H10*G10 -> 250
A11: יתרת חצר | B11: =B9-B10 -> 741 | C11: 0.2 | D11: =C11*B11 -> 148.2 | F11: יתרת חצר | G11: =B11 -> 741 | H11: 0.2 | I11: =H11*G11 -> 148.2
F12: חצר רחוקה מאוד | G12: 500 | H12: 0.1 | I12: =G12*H12 -> 50
A13: סה"כ מ"ר אקו' | B13: =SUM(B4:B11) -> 5000 | D13: =SUM(D4:D12) -> 1064.8 | F13: סה"כ מ"ר אקו' | G13: =SUM(G4:G11) -> 5500 | I13: =SUM(I4:I12) -> 1114.8
A14: סה"כ מ"ר אקו' מעוגל | D14: =D13 -> 1064.8 | F14: סה"כ מ"ר אקו' מעוגל | I14: =I13 -> 1114.8
A15: עלויות פיתוח | D15: 247000 | F15: עלויות פיתוח | I15: 263000
A17: פוטנציאל | B17: 2500 | C17: לפי ברנס
B18: מ"ר | C18: מקדם | D18: אקו'
A19: עיקרי | B19: 85 | C19: 1 | D19: =C19*B19 -> 85
A20: ממ"ד | B20: 12 | C20: 0.9 | D20: =C20*B20 -> 10.8
A21: ש"ש עיליים | B21: 47.5 | C21: 0.5 | D21: =C21*B21 -> 23.75
A22: ש"ש תת"ק | B22: 180 | C22: 0.3 | D22: =C22*B22 -> 54
H24: =876+73 -> 949
A25: הפסד חצר שולית | B25: -145 | C25: 0.2 | D25: =B25*C25 -> -29 | H25: =H24+137 -> 1086
A27: דחיה למימוש
A28: סה"כ מ"ר אקו' מעוגל
A30: דמי היתר שנרכשו
A31: גודל בית ראשון בהיתר | D31: 186
A32: שטח פטור | D32: 160
A33: שטח שנרכש
A34: גודל בית שני בהיתר | D34: 221
A35: שטח פטור | D35: 160
A36: שטח שנרכש | D36: =D34-D35 -> 61
A38: סה"כ שטח שנרכש | D38: =D36+D33 -> 61
A41: סה"כ שטח אקו' לחישוב דמי רכישה | D41: =D14+D28-D38 -> 1003.8
A45: זכות בית שלישי
A46: מגרש מפוצל הרחבת אביגדור רק במקום 180 220 עיקרי | O46: תחשיבי פיצול | P46: סעיף | Q46: מ"ר בנוי | R46: פטור | S46: זכויות חוזיות | T46: עלות לרמ"י ליח' | U46: סה"כ רמ"י | V46: עלות ליח' | W46: היטל השבחה | X46: עלות ליח' | Y46: מס רכישה
A47: גודל מגרש | B47: 350 | C47: לפי שומת זיו כהן בשפיר | F47: חלק ה29.25% | J47: שויי מ"ר | O47: הסדרה | P47: בית 1 | Q47: 300 | R47: 160 | S47: =Q47-R47 -> 140 | T47: 3000 | U47: =S47*T47 -> 420000 | V47: 0 | W47: =S47*V47 -> 0 | X47: 0 | Y47: 0
A48: מגורים עיקרי בהרחבה | B48: 180 | C48: 1 | D48: =B48*C48 -> 180 | F48: =A48 -> מגורים עיקרי בהרחבה | G48: 160 | H48: 1 | I48: =G48*H48 -> 160 | P48: בית 2 | Q48: 197 | R48: 160 | S48: =Q48-R48 -> 37 | T48: 3000 | U48: =S48*T48 -> 111000 | V48: 0 | W48: 0 | X48: 0 | Y48: 0
D49: =B49*C49 -> 0 | F49: חצר | G49: =B47-G48 -> 190 | H49: 0.25 | I49: =G49*H49 -> 47.5 | P49: בית שלישי | Q49: 130 | R49: 0 | S49: =Q49-R49 -> 130 | T49: 3000 | U49: =S49*T49 -> 390000 | V49: 0 | W49: 0 | X49: 0 | Y49: 0
A50: מרחבים מוגנים | B50: 12 | C50: 0.9 | D50: =B50*C50 -> 10.8 | F50: מ"ר אקו' שנכלל בהנחה | I50: =I48+I49 -> 207.5 | J50: ='ניתוח איזור לעסקאות דמה'!E35 -> 10714.892 | K50: =I50*J50 -> 2223340 | L50: 0.2925 | M50: =K50*L50 -> 650326.96 | P50: יח"ד הורים | Q50: 55 | R50: 0 | S50: =Q50-R50 -> 55 | T50: 3000 | U50: =S50*T50 -> 165000 | V50: 0 | W50: 0 | X50: 0 | Y50: 0
A51: מחסן | B51: 10 | C51: 0.5 | D51: =B51*C51 -> 5 | F51: מ"ר אקו' שלא נכלל בהנחה | I51: =D57-I50 -> 53.1 | J51: =J50 -> 10714.892 | K51: =I51*J51 -> 568960.75 | L51: 0.33 | M51: =K51*L51 -> 187757.05 | P51: סה"כ | S51: =SUM(S47:S50) -> 362 | T51: 3000 | U51: =SUM(U47:U50) -> 1086000 | V51: 0 | W51: 0 | X51: 0 | Y51: 0
...

Sheet תחשיבי הסדרה
D2: מס' מבנה | E2: סיווג המבנה | F2: שטח במ"ר | G2: עלות הסדרה | H2: סה"כ | I2: דמי שימוש | J2: היטל השבחה
D4: 1
D6: 2
D8: 3
D10: 4
D12: 5
D14: 6
D16: 7
D18: 8
D20: 9
D22: 10
D24: 11
D26: סה"כ | H26: =SUM(H4:H25) -> 0 | I26: =SUM(I4:I25) -> 0 | J26: =SUM(J4:J25) -> 0

Sheet ניתוח איזור לעסקאות דמה
B2: שומת
B3: שווי מ"ר אקו'
B4: אחוז שנתי
B5: שנים להיוון
B6: שווי עדכני
B7: שווי לשומה | C7: =E38 -> 9700
B9: תחשיב לפי מכירות בהרחבה
B10: תאריך | C10: גו"ח | D10: מחיר עסקה | E10: שטח המגרש | F10: שטח בנוי | G10: שנת בניה | H10: התאמה למועד קובע | I10: בניכוי יזמי 5% | J10: עלויות בניה למ"ר | K10: יתרה לקרע כולל | L10: שטח אקו' | M10: שווי מתואם כולל מעמ ופיתוח
B24: ניתוח שטח אקו | F24: שטח מגרש
B25: מהות | C25: שטח | D25: מקדם | E25: סה"כ | F25: 500
B26: עיקרי ק.ק | C26: =200/2-3.5 -> 96.5 | D26: 1 | E26: =D26*C26 -> 96.5
B27: ממ"ד | C27: 7 | D27: 0.9 | E27: =D27*C27 -> 6.3
B28: עיקרי ק.א | C28: =200-C26 -> 103.5 | D28: 1 | E28: =D28*C28 -> 103.5
B29: יתרת ש"ש | C29: =40-C27 -> 33 | D29: 0.5 | E29: =D29*C29 -> 16.5
B30: מרתף | C30: 50 | D30: 0.5 | E30: =D30*C30 -> 25
B31: חצר | C31: =F25-C26-C27-C29 -> 363.5 | D31: 0.25 | E31: =D31*C31 -> 90.875
B32: סה"כ שטח אקו' | E32: =SUM(E26:E31) -> 338.675
B33: שווי מגרש מתואם זמן 10% | E33: =3200000*1.1 -> 3520000
B34: שווי מ"ר | E34: =E33/E32 -> 10393.445
B35: בהתאמה לבעלות / 0.97 | E35: =E34/0.97 -> 10714.892
B36: מקדם לנחלה | E36: 0.9
B37: שווי מתואם | E37: =E36*E35 -> 9643.4026
B38: לשומה | E38: 9700

Sheet חישוב גדלי בתים
A2: קיים | B2: חתימת רמ"י | C2: חתימת ועדה | D2: מבנה 1 - בית מגורים שני | E2: מבנה 1.1 - מחסן | F2: מבנה 2 - בית מגורים ראשון | G2: מבנה 2.1 - ממ"ד | H2: מבנה 3 - מבנה חקלאי | I2: מבנה 4 - מבנה חקלאי
A3: מפת מדידה - מפרט רמ"י | D3: =150+48*2 -> 246 | E3: 18 | F3: =107+76*2 -> 259 | G3: 7 | H3: 103 | I3: 28
A4: קומת עמודים
A5: שטחי מגורים - קרקע
A6: פרגולה + מרפסת אחורית | F6: 47
A7: פרגולה קדמית | D7: 33
A8: פרגולה צידית
A9: בליטת גג
A10: שרות (ממ"ד)
A11: קומת עמודים בהיתר
A12: קומת עמודים ללא היתר
A13: סה"כ מבנה | D13: =SUM(D4:D12) -> 33 | E13: =SUM(E4:E12) -> 0 | F13: =SUM(F3:F12) -> 306 | G13: =SUM(G4:G12) -> 0 | H13: =SUM(H3:H12) -> 103 | I13: =SUM(I3:I12) -> 28 | J13: =SUM(J3:J12) -> 0 | K13: =SUM(K3:K12) -> 0 | L13: =SUM(L3:L12) -> 0 | M13: =SUM(M3:M12) -> 0 | N13: =SUM(N3:N12) -> 0 | O13: =SUM(O3:O12) -> 0 | ... S13: =SUM(S3:S12) -> 0
A14: בהיתר | B14: חתימת רמ"י | C14: חתימת ועדה
A15: היתר שנת 78
A16: היתר שנת 98 - חלקאי
A17: היתר שנת 2010 | B17: V | C17: V | D17: 221.14
A18: היתר שנת 2000 - חקלאי
A19: היתר שנת 2000 - חקלאי
A20: היתר שנת 01- חקלאי
A24: בהתר | D24: =SUM(D17:D23) -> 221.14 | E24: =SUM(E17:E23) -> 0 | F24: =SUM(F15:F23) -> 0 | G24: =SUM(G15:G23) -> 0 | H24: =SUM(H15:H23) -> 0 | I24: =SUM(I15:I23) -> 0 | J24: =SUM(J15:J23) -> 0 | K24: =SUM(K15:K23) -> 0 | L24: =SUM(L15:L23) -> 0 | M24: =SUM(M15:M23) -> 0 | ... S24: =SUM(S15:S23) -> 0
A25: פערים | D25: =D13-D24 -> -188.14 | E25: =E13-E24 -> 0 | F25: =F13-F24 -> 306 | G25: =G13-G24 -> 0 | H25: =H13-H24 -> 103 | I25: =I13-I24 -> 28 | J25: =J13-J24 -> 0 | K25: =K13-K24 -> 0 | ... S25: =S13-S24 -> 0
A27: פער מרפסות | D27: =D8+D7 -> 33
E28: =E3*9300*5%*7 -> 58590
E29: =375-E24-F24-I24 -> 375
A31: דמי היתר ששולמו
A32: בית 1 | E32: =-D13 -> -33
A33: בית 2 | E33: =-E13 -> 0
A34: מחסן | E34: =I24 -> 0
A35: סה"כ | E35: =SUM(E31:E34) -> -33
A36: היוון 3.75 | E36: 375
A37: סה"כ מטרים | E37: =SUM(E35:E36) -> 342
A38: קיים | E38: =-E24-F24-I24 -> 0
A39: נותרו לבניה | E39: =SUM(E37:E38) -> 342
A43: פערים בית מגורים
A44: קומה תחתונה | D44: היתר | E44: בפועל | F44: הפרש
A45: מגורים | F45: =E45-D45 -> 0
A46: מקלט | F46: =E46-D46 -> 0
A47: סה"כ קומת קרקע | D47: =SUM(D45:D46) -> 0 | E47: =SUM(E45:E46) -> 0 | F47: =E47-D47 -> 0
A49: קומה עליונה | D49: היתר | E49: בפועל | F49: הפרש
A50: מגורים | F50: =E50-D50 -> 0
...

Sheet תבעות
A2: מקור | B2: מס' תבע | C2: תאריך | D2: זכויות
A3: XPLAN | B3: 616-0902908 | C3: 45565 | D3: 3.5 | E3: בתים
A4: XPLAN | B4: 634-0829846 | C4: 45344 | D4: 500 | E4: פל"ח | F4: פיצול
A5: אתר הועדה | C5: 2004 | D5: בריכה
A6: גובמאפ | B6: 112/03/8 | C6: 27098 | D6: 2 | E6: בתים

Sheet גיליון1
B2: טבלאת סיכום עלויות דמי שימוש
B3: דמי שימוש | C3: מגורים | E3: פרגולות
B4: בית ראשון - מבנה 1 | C4: 0 | E4: 0
B5: בית שני - מבנה 4 | C5: 140000 | E5: =6000*2 -> 12000
B6: בית שלישי - מבנה 1 עבור 100 מ"ר | C6: =46500*7 -> 325500 | E6: 0
B7: בית רביעי - מבנה 2 | C7: =13000*7 -> 91000 | E7: =4000*7 -> 28000
B8: בית חמישי - מבנה 5 | C8: =65000*7 -> 455000 | E8: 50000 | J8: V
B9: טבלאת סיכום עלויות הסדרה | J9: X
B10: דמי היתר - להסדרה | C10: מ"ר לתש' עיקרי | D10: תשלום עיקרי | E10: מ"ר פרגולות | F10: תשלום פרגולות
B11: בית ראשון - מבנה 1 | C11: =197-160 -> 37 | D11: =C11*6605 -> 244385 | E11: 35 | F11: =E11*6605/2 -> 115587.5
B12: בית שני - מבנה 4 | C12: 0 | D12: 0 | E12: =147+24-160 -> 11 | F12: =E12*6605/2 -> 36327.5
B13: בית שלישי - מבנה 1 | C13: יוסדר כמבנה אחד עם הבית הראשון
B14: בית רביעי - מבנה 2 | C14: מומלץ לפינוי / הסרה
B15: בית חמישי - מבנה 5 | C15: יוסדר כבית שלישי - יוצג מטה
B17: טבלאת סיכום עלויות
B18: דמי שימוש - 7 שנים | C18: מגורים | E18: פרגולות
B19: בית ראשון - מבנה 1 | C19: 0 | E19: 0
B20: בית שני - מבנה 4 | C20: 70000 | E20: =6000*7 -> 42000
B21: בית שלישי - מבנה 1 | C21: =46500*7 -> 325500 | E21: 0
B22: בית רביעי - מבנה 2 | C22: =13000*7 -> 91000 | E22: =4000*7 -> 28000
B23: בית חמישי - מבנה 5 | C23: =65000*7 -> 455000 | E23: =7000*7 -> 49000
B25: דמי היתר - להסדרה | C25: מ"ר לתש' עיקרי | D25: תשלום עיקרי | E25: מ"ר פרגולות | F25: תשלום פרגולות
B26: בית ראשון - מבנה 1 | C26: =197-160 -> 37 | D26: =C26*6605 -> 244385 | E26: 35 | F26: =E26*6605/2 -> 115587.5
B27: בית שני - מבנה 4 | C27: 0 | D27: =C27*6605 -> 0 | E27: =147+24-160 -> 11 | F27: =E27*6605/2 -> 36327.5
B28: בית שלישי - מבנה 1 | C28: יוסדר כמבנה אחד עם הבית הראשון
B29: בית רביעי - מבנה 2 | C29: 0 | D29: 0 | E29: 0 | F29: 0
B30: בית חמישי - מבנה 5 | C30: 0 | D30: 0 | E30: =139+31-160 -> 10 | F30: =E30*6605/2 -> 33025
B35: טבלאת סיכום עלויות בית שלישי
B36: הדרך אל הבית השלישי | C36: מגורים | E36: פרגולות
B37: עלויות הסדרה | C37: ע"פ שלב 1 - 1,100,000 ₪
B38: היוון 3.75% דמי חכירה | C38: ע"פ שלב 2 - 260,000 ₪
B39: תב"ע | C39: שכ"ט בעלי מקצוע
B40: היתר בניה - דמי היתר | C40: דמי היתר 455,000 ₪ + היטל השבחה

Sheet בקרה
A2: תב"עות | B2: פלח
B3: מגורים
N7: חריגה מקו
A8: עדיפות לאומית | N8: גבול
A9: סיווג | D9: קישור לפרק 4.2 סימן א רשימת איזורי עדיפות | N9: בניין
N10: לא
A15: מיפוי | B15: חריגה מקווים
A19: מבנים | B19: חריגה מקו | C19: היתר | D19: גודל קיים | E19: גודל בהיתר | F19: שימוש | G19: מקדם | H19: שווי שימוש | I19: שיעור דמי שימוש | J19: דמי שימוש לשנה | K19: שיעור דמי היתר | L19: דמי היתר
A20: מבנה 1 - בית ראשון | H20: ='תחשיב לפי שווי שומה (2)'!B8 -> 9700 | I20: 0 | J20: =D20*G20*H20*I20 -> 0 | K20: 0.51 | L20: ='[1]תחשיב לפי שווי שומה (2)'!$B$26*G20 -> 0
A21: מבנה 1 - פרגולה | H21: =H20 -> 9700 | I21: 0 | J21: =D21*G21*H21*I21 -> 0 | K21: 0.51 | L21: ='[1]תחשיב לפי שווי שומה (2)'!$B$26*G21 -> 0
A22: מבנה 7 - יח"ד שניה | H22: =H21 -> 9700 | I22: 0.05 | J22: =D22*G22*H22*I22 -> 0 | K22: 0.51 | L22: ='[1]תחשיב לפי שווי שומה (2)'!$B$26*G22 -> 0
A23: מבנה 4 - יח"ד שלישית | H23: =H22 -> 9700 | I23: 0.05 | J23: =D23*G23*H23*I23 -> 0 | K23: 0.51 | L23: ='[1]תחשיב לפי שווי שומה (2)'!$B$26*G23 -> 0
A24: מבנה 4 - פל"ח | I24: 0.05 | J24: =D24*G24*H24*I24 -> 0 | K24: 0.51 | L24: =H24*K24 -> 0
