Workbook

Sheet תחשיב לפי שווי שומה (2)
A2: מ"ר אקו' נחלה היוון מלא 3 דונם | B2: ='מ"ר אקו'' נחלה'!I14 -> 1015
A3: מ"ר אקו' נחלה היוון מלא 2.5 דונם | B3: ='מ"ר אקו'' נחלה'!D14 -> 965
A4: מ"ר אקו' פוטנציאל | B4: ='מ"ר אקו'' נחלה'!D27 -> 166.84406
A5: דמי היתר שנרכשו | B5: ='מ"ר אקו'' נחלה'!D40 -> 0
A6: מ"ר אקו' נחלה 3.75% | B6: ='מ"ר אקו'' נחלה'!D72 -> 806.25
A7: מ"ר אקו' מגרש מפוצל | B7: ='מ"ר אקו'' נחלה'!D59 -> 341.3 | C7: מ"ר ל-29.75% | D7: ='מ"ר אקו'' נחלה'!I52 -> 245
A8: שווי מ"ר אקו' מגורים | B8: ='ניתוח איזור לעסקאות דמה'!C7 -> 8000 | C8: שווי מ"ר משרדים | D8: 2500
C9: שווי מ"ר אחסנה | D9: ='ניתוח איזור לעסקאות דמה'!#REF! -> #REF! | E9: 1.17
B10: מ"ר אקו' | C10: דמי חכירה/ פיצול | D10: עלות אקו' | E10: מע"מ | F10: בש"ח | G10: בניכוי פיתוח
A11: היוון 3.75% | B11: =B6 -> 806.25 | C11: 0.0375 | D11: =C11*B11 -> 30.234375 | E11: 1 | F11: =D11*$B$8*E11 -> 241875 | G11: ='מ"ר אקו'' נחלה'!D73*-3.75% -> -6562.5 | H11: =SUM(F11:G11) -> 235312.5
A12: פיצול - חלק בהנחה | B12: =D7 -> 245 | C12: 0.2925 | D12: =C12*B12 -> 71.6625 | E12: 1 | F12: =D12*$B$8*E12 -> 573300 | G12: =-'מ"ר אקו'' נחלה'!D60*C12 -> -29250 | H12: =SUM(F12:G12) -> 544050
A13: פיצול חלק ללא הנחה | B13: =B7-B12 -> 96.3 | C13: 0.33 | D13: =C13*B13 -> 31.779 | E13: 1 | F13: =D13*$B$8*E13 -> 254232 | G13: =G12*53/245 -> -6327.551 | H13: =SUM(F13:G13) -> 247904.45
A14: סה"כ פיצול | B14: =SUM(B12:B13) -> 341.3 | F14: =SUM(F12:F13) -> 827532 | H14: =SUM(H12:H13) -> 791954.45
A15: היטל השבחה על פיצול | B15: ='מ"ר אקו'' נחלה'!I52 -> 245 | C15: =C35 -> 0.425 | D15: =B15*C15 -> 104.125 | E15: 1 | F15: =D15*$B$8 -> 833000
A16: דמי רכישה | B16: =B3+B4-B5 -> 1131.8441 | C16: 0.33 | D16: =C16*B16 -> 373.50854 | E16: 1 | F16: =D16*$B$8*E16 -> 2988068.3 | G16: =-'מ"ר אקו'' נחלה'!D15*C16 -> -81510 | H16: =SUM(F16:G16) -> 2906558.3
A17: דמי היתר 1 מ"ר מגורים | B17: 1 | C17: 0.91 | D17: =C17*B17 -> 0.91 | E17: 1 | F17: 1486
A18: דמי היתר 1 מ"ר שירות | B18: 0.5 | C18: 0.91 | D18: =C18*B18 -> 0.455 | E18: 1 | F18: =F17/2 -> 743 | G18: =F18*#REF!*5%*1.17 -> #REF!
A19: דמי היתר 1 מ"ר מרתף | B19: 0.7 | C19: 0.91 | D19: =C19*B19 -> 0.637 | E19: 1 | F19: =D19*$B$8*E19 -> 5096
A20: היוון 1 מ"ר חצר נוספים | B20: 0.075 | C20: 0.91 | D20: =C20*B20 -> 0.06825 | E20: 1 | F20: =D20*$B$8*E20 -> 546
A21: דמי שימוש משרדים 1 מ"ר לשנה | B21: 1 | C21: 0.05 | D21: =C21*B21 -> 0.05 | E21: 1 | F21: =D21*$D$8*E21 -> 125
A22: דמי היתר בריכה 1 מ"ר | B22: 0.3 | C22: 0.91 | D22: =C22*B22 -> 0.273 | E22: 1 | F22: =D22*$B$8*E22 -> 2184
A23: דמי היתר משרד פלח | B23: 1 | C23: 0.91 | D23: =C23*B23 -> 0.91 | E23: 1 | F23: =E23*D23*$D$8 -> 2275
A24: דמי שימוש 1 מ"ר למגורים | B24: 1 | C24: 0.05 | D24: =C24*B24 -> 0.05 | E24: 1 | F24: =D24*E24*B8 -> 400
A27: מחשבון רמ"י
A29: היטל השבחה פיצול בית שלישי (מגרש ראשון)
B30: עבור מגרש 350 | C30: מקדם | D30: עבור 1 מ"ר אקו'
A31: אחרי מגרש מפוצל | B31: ='מ"ר אקו'' נחלה'!D59*'תחשיב לפי שווי שומה (2)'!$B$8 -> 2730400 | C31: 1 | D31: =C31*$B$8 -> 8000
A32: לפני חצר שולית | B32: =350*$B$8*C32 -> 420000 | C32: 0.15 | D32: =C32*$B$8 -> 1200
A34: השבחה | B34: =B31-B32 -> 2310400 | C34: =C31-C32 -> 0.85 | D34: =C34*$B$8 -> 6800
A35: היטל | B35: =B34*50% -> 1155200 | C35: =C34*50% -> 0.425 | D35: =C35*$B$8 -> 3400
A37: היטל השבחה פיצול בית שני (מגרש שני)
B38: עבור מגרש 350 | C38: מקדם | D38: עבור 1 מ"ר אקו'
A39: אחרי מגרש מפוצל | B39: ='מ"ר אקו'' נחלה'!D59*'תחשיב לפי שווי שומה (2)'!$B$8 -> 2730400 | C39: 1 | D39: =C39*$B$8 -> 8000
A40: לפני מגרש לא מפוצל | B40: =B39*70% -> 1911280 | C40: 0.7 | D40: =C40*$B$8 -> 5600
A42: השבחה | B42: =B39-B40 -> 819120 | C42: =C39-C40 -> 0.3 | D42: =C42*$B$8 -> 2400
A43: היטל | B43: =B42*50% -> 409560 | C43: =C42*50% -> 0.15 | D43: =C43*$B$8 -> 1200

Sheet סיכום עלויות פיצולים
I9: סיכום עלויות פיצול/ים לאחר הסדרה
I10: סוג תשלום | K10: פיצול בית קיים | M10: פיצול מגרש ריק + בית קיים | O10: דמי רכישה
I12: דמי היוון 3.75%/33% | K12: =240000 -> 240000 | M12: =240000 -> 240000 | O12: 2700000
I14: תשלום בעבור פיצול | K14: =1000000 -> 1000000 | M14: 1730000 | O14: -
I16: מס רכישה | K16: =(K14+K12)*0.06 -> 74400 | M16: =(M14+M12)*0.06 -> 118200 | O16: =O12*0.06 -> 162000
I18: דמי היתר לרכוש במשק | K18: - | M18: 144000 | O18: -
I20: סה"כ | K20: =SUM(K12:L19) -> 1314400 | M20: =SUM(M12:N19) -> 2232200 | O20: =SUM(O12:P19) -> 2862000
I22: היטל השבחה - בעת מכר | K22: 500000 | M22: 1500000 | O22: כמפורט בכל אפשרות
A27: מס' מבנה | B27: שימוש | C27: מ"ר | D27: הסדרה | E27: קנס לכל שנה
A28: מבנה 1 | B28: בית של יוסי | C28: 160 | D28: 0 | F28: קיים 120 להרחיב ל-140
A29: מבנה 2 | B29: בית של יצחק | C29: 266 | D29: =(266-175)*6700 -> 609700 | F29: להקטין להיתר או לשלם 6,700 למ"ר
A30: מבנה 3 | B30: קלינקיה | C30: 60 | D30: =C30*2500 -> 150000 | E30: 24000 | F30: פל"ח קליניקה
A31: מבנה 5 | B31: מושכר | C31: פינוי | D31: 0 | F31: לפנות בכדי להימנע מקנס
A32: מבנה 6 | B32: חניה עם סנטף | C32: 34 | D32: 0 | F32: לפנות שוכר ולהחליף לסנטף
A33: מבנה 4 | B33: מחסן | C33: 60 | D33: =40*2500 -> 100000 | F33: 20 מחסן ביתי 40 פל"ח ולקיניקה
A34: מבנה 6 | B34: לול | C34: 766 | D34: 0 | E34: 20000 | F34: להגיש כקיים בהיתר
D35: =SUM(D28:D34) -> 859700 | E35: =SUM(E28:E34) -> 44000

Sheet מ"ר אקו' נחלה
A2: גודל חלקת מגורים (להיוון) | B2: 2500 | C2: לפי שומת חכמון | F2: גודל חלקת מגורים (להיוון) | G2: 3000
B3: מ"ר | C3: מקדם | D3: אקו' | G3: מ"ר | H3: מקדם | I3: אקו'
A4: עיקרי | B4: 450 | C4: 1 | D4: =C4*B4 -> 450 | F4: =A4 -> עיקרי | G4: =B4 -> 450 | H4: =C4 -> 1 | I4: =H4*G4 -> 450
A5: מרחבים מוגנים | B5: 25 | C5: 0.9 | D5: =C5*B5 -> 22.5 | F5: =A5 -> מרחבים מוגנים | G5: =B5 -> 25 | H5: =C5 -> 0.9 | I5: =H5*G5 -> 22.5
A6: יתרת ש"ש | B6: =150-B5 -> 125 | C6: 0.5 | D6: =C6*B6 -> 62.5 | F6: =A6 -> יתרת ש"ש | G6: =B6 -> 125 | H6: =C6 -> 0.5 | I6: =H6*G6 -> 62.5
F7: =A7 -> 0 | G7: =B7 -> 0 | H7: =C7 -> 0 | I7: =H7*G7 -> 0
A8: סה"כ תכסית | B8: =SUM(B4:B6) -> 600 | F8: סה"כ תכסית | G8: =SUM(G4:G7) -> 600
A9: סה"כ חצר | B9: =B2-B8 -> 1900 | F9: סה"כ חצר | G9: =G2-G8 -> 2400
A10: חצר אפקטיבית | B10: 1000 | C10: 0.25 | D10: =C10*B10 -> 250 | F10: חצר אפקטיבית | G10: =B10 -> 1000 | H10: 0.25 | I10: =H10*G10 -> 250
A11: יתרת חצר | B11: =B9-B10 -> 900 | C11: 0.2 | D11: =C11*B11 -> 180 | F11: יתרת חצר | G11: =B11 -> 900 | H11: 0.2 | I11: =H11*G11 -> 180
F12: חצר רחוקה מאוד | G12: 500 | H12: 0.1 | I12: =G12*H12 -> 50
A13: סה"כ מ"ר אקו' | D13: =SUM(D4:D12) -> 965 | F13: סה"כ מ"ר אקו' | G13: =SUM(G4:G11) -> 5500 | I13: =SUM(I4:I12) -> 1015
A14: סה"כ מ"ר אקו' מעוגל | D14: =D13 -> 965 | F14: סה"כ מ"ר אקו' מעוגל | I14: =I13 -> 1015
A15: עלויות פיתוח | D15: 247000 | F15: עלויות פיתוח | I15: 263000
A17: פוטנציאל | B17: 2500 | C17: לפי ברנס
B18: מ"ר | C18: מקדם | D18: אקו'
A19: עיקרי | B19: 200 | C19: 1 | D19: =C19*B19 -> 200
A20: ממ"ד | B20: 12 | C20: 0.9 | D20: =C20*B20 -> 10.8
A21: ש"ש עיליים | B21: =60-B20 -> 48 | C21: 0.5 | D21: =C21*B21 -> 24
A22: ש"ש תת"ק | B22: 50 | C22: 0.4 | D22: =C22*B22 -> 20
A24: הפסד חצר שולית | B24: =-B19-B20-B21 -> -260 | C24: 0.2 | D24: =B24*C24 -> -52
A25: סה"כ | D25: =SUM(D19:D24) -> 202.8
A26: דחיה למימוש | D26: =1/1.05^4 -> 0.82270247
A27: סה"כ מ"ר אקו' מעוגל | D27: =D25*D26 -> 166.84406
A29: דמי היתר שנרכשו
A30: גודל בית ראשון בהיתר | D30: 186
A31: שטח פטור | D31: 160
A32: שטח שנרכש
A33: גודל בית שני בהיתר | D33: 240
A37: שטח פטור | D37: 160
A38: שטח שנרכש
A40: סה"כ שטח שנרכש | D40: =D38+D32 -> 0
A43: סה"כ שטח אקו' לחישוב דמי רכישה | D43: =D14+D27-D40 -> 1131.8441
A48: מגרש מפוצל הרחבת אביגדור רק במקום 180 220 עיקרי | O48: תחשיבי פיצול | P48: סעיף | Q48: מ"ר בנוי | R48: פטור | S48: זכויות חוזיות | T48: עלות לרמ"י ליח' | U48: סה"כ רמ"י | V48: עלות ליח' | W48: היטל השבחה | X48: עלות ליח' | Y48: מס רכישה
A49: גודל מגרש | B49: 500 | C49: לפי שומת זיו כהן בשפיר | F49: חלק ה29.25% | J49: שויי מ"ר | O49: הסדרה | P49: בית 1 | Q49: 300 | R49: 160 | S49: =Q49-R49 -> 140 | T49: 3000 | U49: =S49*T49 -> 420000 | V49: 0 | W49: =S49*V49 -> 0 | X49: 0 | Y49: 0
A50: מגורים עיקרי בהרחבה | B50: 200 | C50: 1 | D50: =B50*C50 -> 200 | F50: =A50 -> מגורים עיקרי בהרחבה | G50: 160 | H50: 1 | I50: =G50*H50 -> 160 | P50: בית 2 | Q50: 197 | R50: 160 | S50: =Q50-R50 -> 37 | T50: 3000 | U50: =S50*T50 -> 111000 | V50: 0 | W50: 0 | X50: 0 | Y50: 0
A51: ממ"ד | B51: 12 | C51: 0.9 | D51: =B51*C51 -> 10.8 | F51: חצר | G51: =B49-G50 -> 340 | H51: 0.25 | I51: =G51*H51 -> 85 | P51: בית שלישי | Q51: 130 | R51: 0 | S51: =Q51-R51 -> 130 | T51: 3000 | U51: =S51*T51 -> 390000 | V51: 0 | W51: 0 | X51: 0 | Y51: 0
A52: ש"ש עיליים | B52: 48 | C52: 0.5 | D52: =B52*C52 -> 24 | F52: מ"ר אקו' שנכלל בהנחה | I52: =I50+I51 -> 245 | J52: ='ניתוח איזור לעסקאות דמה'!E29 -> 8773.4231 | K52: =I52*J52 -> 2149488.7 | L52: 0.2925 | M52: =K52*L52 -> 628725.43 | P52: יח"ד הורים | Q52: 55 | R52: 0 | S52: =Q52-R52 -> 55 | T52: 3000 | U52: =S52*T52 -> 165000 | V52: 0 | W52: 0 | X52: 0 | Y52: 0
A53: ש"ש תת"ק | B53: 50 | C53: 0.4 | D53: =B53*C53 -> 20 | F53: מ"ר אקו' שלא נכלל בהנחה | I53: =D59-I52 -> 96.3 | J53: =J52 -> 8773.4231 | K53: =I53*J53 -> 844880.64 | L53: 0.33 | M53: =K53*L53 -> 278810.61 | P53: סה"כ | S53: =SUM(S49:S52) -> 362 | T53: 3000 | U53: =SUM(U49:U52) -> 1086000 | V53: 0 | W53: 0 | X53: 0 | Y53: 0
M54: =SUM(M52:M53) -> 907536.04 | O54: היוון | P54: היוון | Q54: 0.0375 | S54: 375 | T54: 240000 | U54: =T54 -> 240000 | V54: 0 | W54: 0 | X54: 0.06 | Y54: =U54*6% -> 14400
...

Sheet ניתוח איזור לעסקאות דמה
B2: שומת
B3: שווי מ"ר אקו'
B4: אחוז שנתי
B5: שנים להיוון
B6: שווי עדכני
B7: שווי לשומה | C7: =E32 -> 8000
B9: תחשיב לפי מכירות בהרחבה
B10: תאריך | C10: גו"ח | D10: מחיר עסקה | E10: שטח המגרש | F10: שטח בנוי | G10: התאמה למועד קובע | H10: בניכוי יזמי 5% | I10: עלויות בניה למ"ר | J10: יתרה לקרע כולל | K10: שטח אקו' | L10: שווי מתואם כולל מעמ ופיתוח
B13: גוש חלקה | C13: יום מכירה | D13: תמורה מוצהרת בש"ח | E13: בניכוי יזמות 5% | F13: מהות | G13: ישוב | H13: שנת בניה | I13: שטח | J13: שטח מגרש | K13: תרומת הבנוי למ"ר | L13: סה"כ | M13: יתרת המגרש | N13: מקדם התאמה לזמן | O13: שווי מתואם
B14: 002242-0037 | C14: 45074 | D14: 4000000 | E14: =D14/1.05 -> 3809523.8 | F14: קוטג' חד משפחתי | G14: חצב | H14: 2005 | I14: 220 | J14: 514 | K14: 7000 | L14: =K14*I14 -> 1540000 | M14: =E14-L14 -> 2269523.8 | N14: =1.07^2.5 -> 1.1842938 | O14: =N14*M14 -> 2687782.9
B18: ניתוח שטח אקו' | F18: שטח המגרש
B19: מהות | C19: שטח | D19: מקדם | E19: סה"כ | F19: =J14 -> 514
B20: עיקרי | C20: 200 | D20: 1 | E20: =C20*D20 -> 200
B21: ממ"ד | C21: 7 | D21: 0.9 | E21: =C21*D21 -> 6.3
B22: יתרת ש"ש | C22: 30 | D22: 0.5 | E22: =C22*D22 -> 15
B23: מרתף | C23: 50 | D23: 0.4 | E23: =C23*D23 -> 20
B24: תכסית | C24: =F19*42% -> 215.88 | E24: =C24*D24 -> 0
B25: חצר | C25: =F19-C24 -> 298.12 | D25: 0.25 | E25: =C25*D25 -> 74.53
B26: סה"כ שטח אקו' | E26: =SUM(E20:E25) -> 315.83
B27: שווי מגרש מתואם | E27: =O14 -> 2687782.9
B28: שווי מ"ר | E28: =E27/E26 -> 8510.2204
B29: בהתאמה לבעלות /0.97 | E29: =E28/0.97 -> 8773.4231
B30: מקדם התאמה לנחלה | E30: 0.9
B31: שווי מ"ר בנחלה | E31: =E30*E29 -> 7896.0808
B32: לשומה | E32: 8000

Sheet חישוב גדלי בתים
A2: קיים | B2: חתימת רמ"י | C2: חתימת ועדה | D2: מבנה 1 - בית מגורים ראשון | E2: מבנה 2 - בית מגורים שני | F2: מבנה 2.1 - מקלט | G2: מבנה 3 - בית מגורים שלישי | H2: מבנה 4 - מחסן חקלאי | I2: מבנה 5 - בית מגורים רביעי | J2: מבנה 6 - מחסן אלומיניום
A3: מפת מדידה - מפרט רמ"י | D3: 93 | E3: 267 | F3: 11.8 | G3: 60 | H3: 137 | I3: 29 | J3: 786
A4: קומת עמודים
A5: שטחי מגורים - קרקע | D5: 93
A6: פרגולה + מרפסת אחורית
A7: פרגולה קדמית | D7: 26 | E7: 60 | G7: 12
A8: מרפסת מקורה
A9: בליטת גג
A10: שרות (ממ"ד)
A11: קומת עמודים בהיתר
A12: קומת עמודים ללא היתר
A13: סה"כ מבנה | D13: =SUM(D4:D12) -> 119 | E13: =SUM(E3:E12) -> 327 | F13: =SUM(F3:F12) -> 11.8 | G13: =SUM(G3:G12) -> 72 | H13: =SUM(H3:H12) -> 137 | I13: =SUM(I3:I12) -> 29 | J13: =SUM(J3:J12) -> 786 | K13: =SUM(K3:K12) -> 0 | L13: =SUM(L3:L12) -> 0 | ... S13: =SUM(S3:S12) -> 0
A14: בהיתר | B14: חתימת רמ"י | C14: חתימת ועדה
A15: היתר שנת 70 | B15: V | C15: V | D15: 88.99
A16: היתר שנת 83 | B16: V | C16: V | J16: 720
A17: היתר שנת 86 | B17: V | C17: V | E17: =158.39+9.84+7 -> 175.23
A21: בהתר | D21: =SUM(D18:D20) -> 0 | E21: =SUM(E15:E20) -> 175.23 | F21: =SUM(F15:F20) -> 0 | G21: =SUM(G15:G20) -> 0 | H21: =SUM(H15:H20) -> 0 | I21: =SUM(I15:I20) -> 0 | J21: =SUM(J15:J20) -> 720 | K21: =SUM(K15:K20) -> 0 | L21: =SUM(L15:L20) -> 0 | ... S21: =SUM(S15:S20) -> 0
A22: פערים | D22: =D13-D21 -> 119 | E22: =E13-E21 -> 151.77 | F22: =F13-F21 -> 11.8 | G22: =G13-G21 -> 72 | H22: =H13-H21 -> 137 | I22: =I13-I21 -> 29 | J22: =J13-J21 -> 66 | K22: =K13-K21 -> 0 | ... S22: =S13-S21 -> 0
A24: פער מרפסות | D24: =D8+D7 -> 26
E25: =E3*9300*5%*7 -> 869085
E26: =375-E21-F21-I21 -> 199.77
A28: דמי היתר ששולמו
A29: בית 1 | E29: =-D13 -> -119
A30: בית 2 | E30: =-E13 -> -327
A31: מחסן | E31: =I21 -> 0
A32: סה"כ | E32: =SUM(E28:E31) -> -446
A33: היוון 3.75 | E33: 375
A34: סה"כ מטרים | E34: =SUM(E32:E33) -> -71
A35: קיים | E35: =-E21-F21-I21 -> -175.23
A36: נותרו לבניה | E36: =SUM(E34:E35) -> -246.23
A40: פערים בית מגורים
A41: קומה תחתונה | D41: היתר | E41: בפועל | F41: הפרש
A42: מגורים | F42: =E42-D42 -> 0
A43: מקלט | F43: =E43-D43 -> 0
A44: סה"כ קומת קרקע | D44: =SUM(D42:D43) -> 0 | E44: =SUM(E42:E43) -> 0 | F44: =E44-D44 -> 0
A46: קומה עליונה | D46: היתר | E46: בפועל | F46: הפרש
A47: מגורים | F47: =E47-D47 -> 0
A48: מקלט | F48: =E48-D48 -> 0
A49: סה"כ קומת קרקע | D49: =SUM(D47:D48) -> 0 | E49: =SUM(E47:E48) -> 0 | F49: =E49-D49 -> 0
A51: סה"כ | D51: =D49+D44 -> 0 | E51: =E49+E44 -> 0 | F51: =F49+F44 -> 0

Sheet תבעות
A2: מקור | B2: מס' תבע | C2: תאריך | D2: זכויות
A3: XPLAN | B3: 616-0770735 | C3: 45111 | D3: 500 | E3: פלח
A4: אתר וועדה | B4: 59/101/02/8 | C4: 38165 | D4: 150 | E4: בריכה
A5: גובמאפ | B5: ד/693 | C5: 25807 | D5: 450+150 | E5: 2 בתים

Sheet גיליון1
B2: טבלאת סיכום עלויות דמי שימוש
B3: דמי שימוש | C3: מגורים | E3: פרגולות
B4: בית ראשון - מבנה 1 | C4: 0 | E4: 0
B5: בית שני - מבנה 4 | C5: 140000 | E5: =6000*2 -> 12000
B6: בית שלישי - מבנה 1 עבור 100 מ"ר | C6: =46500*7 -> 325500 | E6: 0
B7: בית רביעי - מבנה 2 | C7: =13000*7 -> 91000 | E7: =4000*7 -> 28000
B8: בית חמישי - מבנה 5 | C8: =65000*7 -> 455000 | E8: 50000 | J8: V
B9: טבלאת סיכום עלויות הסדרה | J9: X
B10: דמי היתר - להסדרה | C10: מ"ר לתש' עיקרי | D10: תשלום עיקרי | E10: מ"ר פרגולות | F10: תשלום פרגולות
B11: בית ראשון - מבנה 1 | C11: =197-160 -> 37 | D11: =C11*6605 -> 244385 | E11: 35 | F11: =E11*6605/2 -> 115587.5
B12: בית שני - מבנה 4 | C12: 0 | D12: 0 | E12: =147+24-160 -> 11 | F12: =E12*6605/2 -> 36327.5
B13: בית שלישי - מבנה 1 | C13: יוסדר כמבנה אחד עם הבית הראשון
B14: בית רביעי - מבנה 2 | C14: מומלץ לפינוי / הסרה
B15: בית חמישי - מבנה 5 | C15: יוסדר כבית שלישי - יוצג מטה
B17: טבלאת סיכום עלויות
B18: דמי שימוש - 7 שנים | C18: מגורים | E18: פרגולות
B19: בית ראשון - מבנה 1 | C19: 0 | E19: 0
B20: בית שני - מבנה 4 | C20: 70000 | E20: =6000*7 -> 42000
B21: בית שלישי - מבנה 1 | C21: =46500*7 -> 325500 | E21: 0
B22: בית רביעי - מבנה 2 | C22: =13000*7 -> 91000 | E22: =4000*7 -> 28000
B23: בית חמישי - מבנה 5 | C23: =65000*7 -> 455000 | E23: =7000*7 -> 49000
B25: דמי היתר - להסדרה | C25: מ"ר לתש' עיקרי | D25: תשלום עיקרי | E25: מ"ר פרגולות | F25: תשלום פרגולות
B26: בית ראשון - מבנה 1 | C26: =197-160 -> 37 | D26: =C26*6605 -> 244385 | E26: 35 | F26: =E26*6605/2 -> 115587.5
B27: בית שני - מבנה 4 | C27: 0 | D27: =C27*6605 -> 0 | E27: =147+24-160 -> 11 | F27: =E27*6605/2 -> 36327.5
B28: בית שלישי - מבנה 1 | C28: יוסדר כמבנה אחד עם הבית הראשון
B29: בית רביעי - מבנה 2 | C29: 0 | D29: 0 | E29: 0 | F29: 0
B30: בית חמישי - מבנה 5 | C30: 0 | D30: 0 | E30: =139+31-160 -> 10 | F30: =E30*6605/2 -> 33025
B35: טבלאת סיכום עלויות בית שלישי
B36: הדרך אל הבית השלישי | C36: מגורים | E36: פרגולות
B37: עלויות הסדרה | C37: ע"פ שלב 1 - 1,100,000 ₪
B38: היוון 3.75% דמי חכירה | C38: ע"פ שלב 2 - 260,000 ₪
B39: תב"ע | C39: שכ"ט בעלי מקצוע
B40: היתר בניה - דמי היתר | C40: דמי היתר 455,000 ₪ + היטל השבחה

Sheet בקרה
A2: תב"עות | B2: פלח
B3: מגורים
N7: חריגה מקו
A8: עדיפות לאומית | N8: גבול
A9: סיווג | D9: קישור לפרק 4.2 סימן א רשימת איזורי עדיפות | N9: בניין
N10: לא
A15: מיפוי | B15: חריגה מקווים
A19: מבנים | B19: חריגה מקו | C19: היתר | D19: גודל קיים | E19: גודל בהיתר | F19: שימוש | G19: מקדם | H19: שווי שימוש | I19: שיעור דמי שימוש | J19: דמי שימוש לשנה | K19: שיעור דמי היתר | L19: דמי היתר
A20: מבנה 1 - בית ראשון | H20: ='תחשיב לפי שווי שומה (2)'!B8 -> 8000 | I20: 0 | J20: =D20*G20*H20*I20 -> 0 | K20: 0.51 | L20: ='[1]תחשיב לפי שווי שומה (2)'!$B$26*G20 -> 0
A21: מבנה 1 - פרגולה | H21: =H20 -> 8000 | I21: 0 | J21: =D21*G21*H21*I21 -> 0 | K21: 0.51 | L21: ='[1]תחשיב לפי שווי שומה (2)'!$B$26*G21 -> 0
A22: מבנה 7 - יח"ד שניה | H22: =H21 -> 8000 | I22: 0.05 | J22: =D22*G22*H22*I22 -> 0 | K22: 0.51 | L22: ='[1]תחשיב לפי שווי שומה (2)'!$B$26*G22 -> 0
A23: מבנה 4 - יח"ד שלישית | H23: =H22 -> 8000 | I23: 0.05 | J23: =D23*G23*H23*I23 -> 0 | K23: 0.51 | L23: ='[1]תחשיב לפי שווי שומה (2)'!$B$26*G23 -> 0
A24: מבנה 4 - פל"ח | I24: 0.05 | J24: =D24*G24*H24*I24 -> 0 | K24: 0.51 | L24: =H24*K24 -> 0
