Workbook

Sheet תחשיב לפי שווי שומה (2)
A2: מ"ר אקו' נחלה היוון מלא 3 דונם | B2: ='מ"ר אקו'' נחלה'!I14 -> 1084.4
A3: מ"ר אקו' נחלה היוון מלא 2.5 דונם | B3: ='מ"ר אקו'' נחלה'!D14 -> 1034.4
A4: מ"ר אקו' פוטנציאל | B4: ='מ"ר אקו'' נחלה'!D28 -> 0
A5: דמי היתר שנרכשו | B5: ='מ"ר אקו'' נחלה'!D38 -> 11
A6: מ"ר אקו' נחלה 3.75% | B6: ='מ"ר אקו'' נחלה'!D70 -> 806.25
A7: מ"ר אקו' מגרש מפוצל | B7: ='מ"ר אקו'' נחלה'!D57 -> 273.8 | C7: מ"ר ל-29.75% | D7: ='מ"ר אקו'' נחלה'!I50 -> 207.5
A8: שווי מ"ר אקו' מגורים | B8: ='ניתוח איזור לעסקאות דמה'!C7 -> 11000 | C8: שווי מ"ר משרדים | D8: 2500
C9: שווי מ"ר אחסנה | D9: ='ניתוח איזור לעסקאות דמה'!#REF! -> #REF! | E9: 1.17
B10: מ"ר אקו' | C10: דמי חכירה/ פיצול | D10: עלות אקו' | E10: מע"מ | F10: בש"ח | G10: בניכוי פיתוח
A11: היוון 3.75% | B11: =B6 -> 806.25 | C11: 0.0375 | D11: =C11*B11 -> 30.234375 | E11: 1 | F11: =D11*$B$8*E11 -> 332578.12 | G11: ='מ"ר אקו'' נחלה'!D71*-3.75% -> -6562.5 | H11: =SUM(F11:G11) -> 326015.62
A12: פיצול - חלק בהנחה | B12: =D7 -> 207.5 | C12: 0.2925 | D12: =C12*B12 -> 60.69375 | E12: 1 | F12: =D12*$B$8*E12 -> 667631.25 | G12: =-'מ"ר אקו'' נחלה'!D58*C12 -> -29250 | H12: =SUM(F12:G12) -> 638381.25
A13: פיצול חלק ללא הנחה | B13: =B7-B12 -> 66.3 | C13: 0.33 | D13: =C13*B13 -> 21.879 | E13: 1 | F13: =D13*$B$8*E13 -> 240669 | G13: =G12*53/245 -> -6327.551 | H13: =SUM(F13:G13) -> 234341.45
A14: סה"כ פיצול | B14: =SUM(B12:B13) -> 273.8 | F14: =SUM(F12:F13) -> 908300.25 | H14: =SUM(H12:H13) -> 872722.7
A15: היטל השבחה על פיצול | B15: ='מ"ר אקו'' נחלה'!I50 -> 207.5 | C15: =C35 -> 0.425 | D15: =B15*C15 -> 88.1875 | E15: 1 | F15: =D15*$B$8 -> 970062.5
A16: דמי רכישה | B16: =B3+B4-B5 -> 1023.4 | C16: 0.33 | D16: =C16*B16 -> 337.722 | E16: 1 | F16: =D16*$B$8*E16 -> 3714942 | G16: =-'מ"ר אקו'' נחלה'!D15*C16 -> -81510 | H16: =SUM(F16:G16) -> 3633432
A17: דמי היתר 1 מ"ר מגורים | B17: 1 | C17: 0.91 | D17: =C17*B17 -> 0.91 | E17: 1 | F17: 1486
A18: דמי היתר 1 מ"ר שירות | B18: 0.5 | C18: 0.91 | D18: =C18*B18 -> 0.455 | E18: 1 | F18: =F17/2 -> 743 | G18: =F18*#REF!*5%*1.17 -> #REF!
A19: דמי היתר 1 מ"ר מרתף | B19: 0.7 | C19: 0.91 | D19: =C19*B19 -> 0.637 | E19: 1 | F19: =D19*$B$8*E19 -> 7007
A20: היוון 1 מ"ר חצר נוספים | B20: 0.075 | C20: 0.91 | D20: =C20*B20 -> 0.06825 | E20: 1 | F20: =D20*$B$8*E20 -> 750.75
A21: דמי שימוש משרדים 1 מ"ר לשנה | B21: 1 | C21: 0.05 | D21: =C21*B21 -> 0.05 | E21: 1 | F21: =D21*$D$8*E21 -> 125
A22: דמי היתר בריכה 1 מ"ר | B22: 0.3 | C22: 0.91 | D22: =C22*B22 -> 0.273 | E22: 1 | F22: =D22*$B$8*E22 -> 3003
A23: דמי היתר משרד פלח | B23: 1 | C23: 0.91 | D23: =C23*B23 -> 0.91 | E23: 1 | F23: =E23*D23*$D$8 -> 2275
A24: דמי שימוש 1 מ"ר למגורים | B24: 1 | C24: 0.05 | D24: =C24*B24 -> 0.05 | E24: 1 | F24: =D24*E24*B8 -> 550
A27: מחשבון רמ"י
A29: היטל השבחה פיצול בית שלישי (מגרש ראשון)
B30: עבור מגרש 350 | C30: מקדם | D30: עבור 1 מ"ר אקו'
A31: אחרי מגרש מפוצל | B31: ='מ"ר אקו'' נחלה'!D57*'תחשיב לפי שווי שומה (2)'!$B$8 -> 3011800 | C31: 1 | D31: =C31*$B$8 -> 11000
A32: לפני חצר שולית | B32: =350*$B$8*C32 -> 577500 | C32: 0.15 | D32: =C32*$B$8 -> 1650
A34: השבחה | B34: =B31-B32 -> 2434300 | C34: =C31-C32 -> 0.85 | D34: =C34*$B$8 -> 9350
A35: היטל | B35: =B34*50% -> 1217150 | C35: =C34*50% -> 0.425 | D35: =C35*$B$8 -> 4675
A37: היטל השבחה פיצול בית שני (מגרש שני)
B38: עבור מגרש 350 | C38: מקדם | D38: עבור 1 מ"ר אקו'
A39: אחרי מגרש מפוצל | B39: ='מ"ר אקו'' נחלה'!D57*'תחשיב לפי שווי שומה (2)'!$B$8 -> 3011800 | C39: 1 | D39: =C39*$B$8 -> 11000
A40: לפני מגרש לא מפוצל | B40: =B39*70% -> 2108260 | C40: 0.7 | D40: =C40*$B$8 -> 7700
A42: השבחה | B42: =B39-B40 -> 903540 | C42: =C39-C40 -> 0.3 | D42: =C42*$B$8 -> 3300
A43: היטל | B43: =B42*50% -> 451770 | C43: =C42*50% -> 0.15 | D43: =C43*$B$8 -> 1650

Sheet סיכום עלויות פיצולים
F9: סיכום עלויות פיצול מגרש ריק + בית קיים לאחר הסדרה
F10: סוג תשלום | H10: מסלול היוון 3.75% | J10: מסלול דמי רכישה 33%
F12: דמי היוון 3.75%/33% | H12: 330000 | J12: 3600000
F14: תשלום בעבור פיצול | H14: 2000000 | J14: -
F16: מס רכישה | H16: =(H14+H12)*0.06 -> 139800 | J16: =J12*0.06 -> 216000
F18: דמי היתר לרכוש במשק | H18: 1030000 | J18: -
F20: סה"כ | H20: =SUM(H12:I19) -> 3499800 | J20: =SUM(J12:K19) -> 3816000
F22: היטל השבחה - בעת מכר | H22: =1350000+380000 -> 1730000 | J22: =H22 -> 1730000
H27: =160+27 -> 187
H28: =H27*5500 -> 1028500
F29: דמי היתר לרכוש במשק | J29: דמי היתר לרכוש במשק
F30: זכויות בסיס | G30: 375 | J30: זכויות בסיס | K30: 375
F31: נרכש בעבר | G31: 11 | J31: נרכש בעבר | K31: 11
F32: סה"כ חוזה חכירה | G32: =G31+G30 -> 386 | J32: סה"כ חוזה חכירה | K32: =K31+K30 -> 386
F33: גרעון 2 פיצולים | G33: =-320 -> -320 | J33: גרעון 2 פיצולים | K33: =-160 -> -160
F34: סה"כ חוזה לאחר פיצולים | G34: =G32+G33 -> 66 | J34: סה"כ חוזה לאחר פיצולים | K34: =K32+K33 -> 226
F35: שטח בנוי במשק | G35: 253 | J35: שטח בנוי במשק | K35: =253-102 -> 151
F36: שטח לרכוש | G36: =G35-G34 -> 187 | J36: שטח לרכוש | K36: =K35-K34 -> -75
F37: ערך מ"ר | G37: 5500 | J37: ערך מ"ר | K37: 5500
F38: סה"כ לרכוש | G38: =G36*G37 -> 1028500 | J38: סה"כ לרכוש | K38: =K36*K37 -> -412500
F39: היתר

Sheet מ"ר אקו' נחלה
A2: גודל חלקת מגורים (להיוון) | B2: 2500 | C2: לפי שומת חכמון | F2: גודל חלקת מגורים (להיוון) | G2: 3000
B3: מ"ר | C3: מקדם | D3: אקו' | G3: מ"ר | H3: מקדם | I3: אקו'
A4: עיקרי | B4: 475 | C4: 1 | D4: =C4*B4 -> 475 | F4: =A4 -> עיקרי | G4: =B4 -> 475 | H4: =C4 -> 1 | I4: =H4*G4 -> 475
A5: מרחבים מוגנים | B5: 36 | C5: 0.9 | D5: =C5*B5 -> 32.4 | F5: =A5 -> מרחבים מוגנים | G5: =B5 -> 36 | H5: =C5 -> 0.9 | I5: =H5*G5 -> 32.4
A6: יתרת ש"ש | B6: =60-B5 -> 24 | C6: 0.5 | D6: =C6*B6 -> 12 | F6: =A6 -> יתרת ש"ש | G6: =B6 -> 24 | H6: =C6 -> 0.5 | I6: =H6*G6 -> 12
A7: מרתפים | B7: 180 | C7: 0.4 | D7: =C7*B7 -> 72 | F7: =A7 -> מרתפים | G7: =B7 -> 180 | H7: =C7 -> 0.4 | I7: =H7*G7 -> 72
A8: סה"כ תכסית | B8: =SUM(B4:B6) -> 535 | F8: סה"כ תכסית | G8: =SUM(G4:G7) -> 715
A9: סה"כ חצר | B9: =B2-B8 -> 1965 | F9: סה"כ חצר | G9: =G2-G8 -> 2285
A10: חצר אפקטיבית | B10: 1000 | C10: 0.25 | D10: =C10*B10 -> 250 | F10: חצר אפקטיבית | G10: =B10 -> 1000 | H10: 0.25 | I10: =H10*G10 -> 250
A11: יתרת חצר | B11: =B9-B10 -> 965 | C11: 0.2 | D11: =C11*B11 -> 193 | F11: יתרת חצר | G11: =B11 -> 965 | H11: 0.2 | I11: =H11*G11 -> 193
F12: חצר רחוקה מאוד | G12: 500 | H12: 0.1 | I12: =G12*H12 -> 50
A13: סה"כ מ"ר אקו' | B13: =SUM(B4:B11) -> 5180 | D13: =SUM(D4:D12) -> 1034.4 | F13: סה"כ מ"ר אקו' | G13: =SUM(G4:G11) -> 5680 | I13: =SUM(I4:I12) -> 1084.4
A14: סה"כ מ"ר אקו' מעוגל | D14: =D13 -> 1034.4 | F14: סה"כ מ"ר אקו' מעוגל | I14: =I13 -> 1084.4
A15: עלויות פיתוח | D15: 247000 | F15: עלויות פיתוח | I15: 263000
H24: =876+73 -> 949
H25: =H24+137 -> 1086
A30: דמי היתר שנרכשו
A31: גודל בית ראשון בהיתר
A32: שטח פטור | D32: 160
A33: שטח שנרכש
A34: גודל בית שני בהיתר | D34: 171
A35: שטח פטור | D35: 160
A36: שטח שנרכש | D36: =D34-D35 -> 11
A38: סה"כ שטח שנרכש | D38: =D36+D33 -> 11
A41: סה"כ שטח אקו' לחישוב דמי רכישה | D41: =D14+D28-D38 -> 1023.4
A46: מגרש מפוצל הרחבת אביגדור רק במקום 180 220 עיקרי | O46: תחשיבי פיצול | P46: סעיף | Q46: מ"ר בנוי | R46: פטור | S46: זכויות חוזיות | T46: עלות לרמ"י ליח' | U46: סה"כ רמ"י | V46: עלות ליח' | W46: היטל השבחה | X46: עלות ליח' | Y46: מס רכישה
A47: גודל מגרש | B47: 350 | C47: לפי שומת זיו כהן בשפיר | F47: חלק ה29.25% | J47: שויי מ"ר | O47: הסדרה | P47: בית 1 | Q47: 300 | R47: 160 | S47: =Q47-R47 -> 140 | T47: 3000 | U47: =S47*T47 -> 420000 | V47: 0 | W47: =S47*V47 -> 0 | X47: 0 | Y47: 0
A48: מגורים עיקרי בהרחבה | B48: 200 | C48: 1 | D48: =B48*C48 -> 200 | F48: =A48 -> מגורים עיקרי בהרחבה | G48: 160 | H48: 1 | I48: =G48*H48 -> 160 | P48: בית 2 | Q48: 197 | R48: 160 | S48: =Q48-R48 -> 37 | T48: 3000 | U48: =S48*T48 -> 111000 | V48: 0 | W48: 0 | X48: 0 | Y48: 0
D49: =B49*C49 -> 0 | F49: חצר | G49: =B47-G48 -> 190 | H49: 0.25 | I49: =G49*H49 -> 47.5 | P49: בית שלישי | Q49: 130 | R49: 0 | S49: =Q49-R49 -> 130 | T49: 3000 | U49: =S49*T49 -> 390000 | V49: 0 | W49: 0 | X49: 0 | Y49: 0
A50: מרחבים מוגנים | B50: 12 | C50: 0.9 | D50: =B50*C50 -> 10.8 | F50: מ"ר אקו' שנכלל בהנחה | I50: =I48+I49 -> 207.5 | J50: ='ניתוח איזור לעסקאות דמה'!P18 -> 11900.954 | K50: =I50*J50 -> 2469447.9 | L50: 0.2925 | M50: =K50*L50 -> 722313.52 | P50: יח"ד הורים | Q50: 55 | R50: 0 | S50: =Q50-R50 -> 55 | T50: 3000 | U50: =S50*T50 -> 165000 | V50: 0 | W50: 0 | X50: 0 | Y50: 0
A51: יתרת ש"ש | B51: =24/3 -> 8 | C51: 0.5 | D51: =B51*C51 -> 4 | F51: מ"ר אקו' שלא נכלל בהנחה | I51: =D57-I50 -> 66.3 | J51: =J50 -> 11900.954 | K51: =I51*J51 -> 789033.24 | L51: 0.33 | M51: =K51*L51 -> 260380.97 | P51: סה"כ | S51: =SUM(S47:S50) -> 362 | T51: 3000 | U51: =SUM(U47:U50) -> 1086000 | V51: 0 | W51: 0 | X51: 0 | Y51: 0
M52: =SUM(M50:M51) -> 982694.49 | O52: היוון | P52: היוון | Q52: 0.0375 | S52: 375 | T52: 240000 | U52: =T52 -> 240000 | V52: 0 | W52: 0 | X52: 0.06 | Y52: =U52*6% -> 14400
P53: חוזה חכירה לאחר הסדרה והיוון | S53: =SUM(S51:S52) -> 737 | Y53: 0
A54: סה"כ תכסית | B54: =(B48+B50)/2+B51 -> 114 | O54: פיצול | P54: פיצול בית 1 | S54: -160 | T54: 950000 | U54: =T54 -> 950000 | V54: 450000 | W54: =V54 -> 450000 | X54: 0.06 | Y54: =U54*6% -> 57000
A55: סה"כ חצר | B55: =B47-B54 -> 236 | P55: חוזה חכירה לאחר פיצול | S55: =SUM(S53:S54) -> 577
A56: חצר אפקטיבית | B56: =B55 -> 236 | C56: 0.25 | D56: =B56*C56 -> 59 | O56: רכישת דמי היתר בעקבות פיצול | P56: מצב בנוי לאחר פיצול | S56: =-Q48-Q49-Q50 -> -382 | W56: 0 | X56: 0 | Y56: 0
A57: סה"כ מ"ר אקו' | D57: =SUM(D48:D56) -> 273.8 | P57: יתרת זכויות / רכישת דמי היתר | S57: =SUM(S55:S56) -> 195 | T57: 0 | U57: 0 | W57: 0 | X57: 0 | Y57: 0
A58: הוצאות פיתוח | D58: 100000 | T58: סה"כ רמ"י | U58: =SUM(U51:U57) -> 2276000 | V58: סה"כ היטל השבחה | W58: =SUM(W47:W57) -> 450000 | X58: סה"כ מס רכישה | Y58: =SUM(Y51:Y57) -> 71400
A60: לפי שומת הררי 2021 | B60: 2500 | F60: =A60 -> לפי שומת הררי 2021 | G60: 3000
A61: היוון 3.75% | B61: מ"ר | C61: מקדם | D61: אקו' | F61: היוון 3.75% | G61: מ"ר | H61: מקדם | I61: אקו'
...

Sheet תחשיבי הסדרה
A1: אפשרות 1 - הסדרה כיחידה וחצי
A2: מס' מבנה | B2: שם מבנה | C2: פעולה | D2: גודל | E2: דמי היתר | F2: היטל השבחה | G2: סה"כ למבנה | H2: דמי שימוש
A3: 1 | B3: בית של ניר | C3: הסדרה בית ראשון | D3: 198 | G3: =SUM(E3:F3) -> 0
A4: 1 | B4: בית של רועי | C4: הסדרה כיחידה צמודת קיר | D4: 55 | E4: 435000 | G4: =SUM(E4:F4) -> 435000
A5: 3 עד 5 | B5: צימרים קדמיים | C5: פינוי | D5: 0 | E5: 0 | F5: 0 | G5: =SUM(E5:F5) -> 0 | H5: 100000
A6: 6,7,8,9,12 | B6: מתחם צימרים | C6: הסדרה | D6: =32+30+3+30+10+31+28+8 -> 172 | E6: =D6*2500+350000 -> 780000 | F6: 0 | G6: =SUM(E6:F6) -> 780000 | H6: 260000 | I6: כולל רכישת חצר
A7: 10,11 | B7: משרד ומבנה חקלאי | C7: הסדרה | D7: =91+25 -> 116 | E7: 0 | F7: 0 | G7: =SUM(E7:F7) -> 0 | H7: 0
A8: 13 | B8: מגורי עובדים | C8: לפינוי | D8: 0 | E8: 0 | F8: 0 | G8: =SUM(E8:F8) -> 0 | H8: 0
A9: 15,16,17,18 | B9: מבני חקלאות | C9: להסדרה | D9: =39+14+127+27+48 -> 255 | E9: 0 | F9: 0 | G9: =SUM(E9:F9) -> 0 | H9: 0
A10: 19 עד 23 | B10: מתחם ספא | C10: לפינוי | D10: 0 | E10: 0 | F10: 0 | G10: =SUM(E10:F10) -> 0 | H10: 0
D11: 0 | E11: 0 | F11: 0 | G11: =SUM(E11:F11) -> 0
A12: סה"כ הסדרה | E12: =SUM(E3:E11) -> 1215000 | F12: =SUM(F3:F11) -> 0 | G12: =SUM(G3:G11) -> 1215000 | H12: =SUM(H3:H11) -> 360000
F13: היוון | G13: 330000
F14: תב"ע | G14: ייתכן וידרש
F15: סה"כ פרויקט הסדרה | G15: =SUM(G12:G14) -> 1545000 | H15: =SUM(H12:H13) -> 360000 | I15: =SUM(G15:H15) -> 1905000
F17: פיצול מגרש ריק | G17: 1200000
D18: 375 | F18: היטל השבחה בעת בניה או מכר | G18: 1500000
C19: הסדרה של בית וחצי | D19: =27+55+11 -> 93 | F19: סה"כ עבור פיצול מגרש ריק | G19: =SUM(G17:G18) -> 2700000
C20: חוזה חכירה | D20: =D18+D19 -> 468
C21: מצב בנוי | D21: =D4+D3 -> 253
C22: יתרה לפני פיצול | D22: =D20-D21 -> 215
C23: פיצול | D23: -160
C24: יתרה | D24: =D22+D23 -> 55
A28: אפשרות 2 להסדיר כ-2 בתים
A29: מס' מבנה | B29: שם מבנה | C29: פעולה | D29: גודל | E29: דמי היתר | F29: היטל השבחה | G29: סה"כ למבנה | H29: דמי שימוש
A30: 1 | B30: בית של ניר | C30: הסדרה בית ראשון | D30: 151 | G30: =SUM(E30:F30) -> 0
A31: 1 | B31: בית של רועי | C31: הסדרה כיחידה צמודת קיר | D31: 102 | E31: 0 | G31: =SUM(E31:F31) -> 0
A32: 3 עד 5 | B32: צימרים קדמיים | C32: פינוי | D32: 0 | E32: 0 | F32: 0 | G32: =SUM(E32:F32) -> 0 | H32: 100000
A33: 6,7,8,9,12 | B33: מתחם צימרים | C33: הסדרה | D33: =32+30+3+30+10+31+28+8 -> 172 | E33: =D33*2500+350000 -> 780000 | F33: 0 | G33: =SUM(E33:F33) -> 780000 | H33: 260000
A34: 10,11 | B34: משרד ומבנה חקלאי | C34: הסדרה | D34: =91+25 -> 116 | E34: 0 | F34: 0 | G34: =SUM(E34:F34) -> 0 | H34: 0
A35: 13 | B35: מגורי עובדים | C35: לפינוי | D35: 0 | E35: 0 | F35: 0 | G35: =SUM(E35:F35) -> 0 | H35: 0
A36: 15,16,17,18 | B36: מבני חקלאות | C36: להסדרה | D36: =39+14+127+27+48 -> 255 | E36: 0 | F36: 0 | G36: =SUM(E36:F36) -> 0 | H36: 0
A37: 19 עד 23 | B37: מתחם ספא | C37: לפינוי | D37: 0 | E37: 0 | F37: 0 | G37: =SUM(E37:F37) -> 0 | H37: 0
D38: 0 | E38: 0 | F38: 0 | G38: =SUM(E38:F38) -> 0
A39: סה"כ הסדרה | E39: =SUM(E30:E38) -> 780000 | F39: =SUM(F30:F38) -> 0 | G39: =SUM(G30:G38) -> 780000 | H39: =SUM(H30:H38) -> 360000 | I39: =SUM(G39:H39) -> 1140000 | J39: =(G39+H39)/1.18 -> 966101.69
F40: היוון | G40: 330000
F41: תב"ע | G41: ייתכן וידרש
F42: סה"כ פרויקט הסדרה | G42: =SUM(G39:G41) -> 1110000 | H42: =SUM(H39:H40) -> 360000 | I42: =SUM(G42:H42) -> 1470000
F44: פיצול מגרש ריק | G44: 1400000
F45: היטל השבחה בעת בניה או מכר | G45: 1500000
...

Sheet חישוב גדלי בתים
A2: קיים | B2: חתימת רמ"י | C2: חתימת ועדה | D2: מבנה 1 - בית מגורים ראשון | E2: מבנה 2 - בית מגורים שני | F2: מבנים 3-5 - צימרים | G2: מבנים 6 - 12 - מתחם צימרים | H2: מבנה 13 - מגורי עובדים | I2: מבנה 14 - סככה חקלאית | J2: מבנה 15 - מגורי עובדים | K2: מבנה 16 - אורווה | L2: מבנים 17 - 18 - מבנים חקלאיים | M2: מבנים 19 -22 - מבני מתחם ספא | N2: מבנה 23 - בריכה
A3: מפת מדידה - מפרט רמ"י | D3: 151 | E3: 102 | F3: 35 | G3: 32 | H3: 14 | I3: 39 | J3: 14 | K3: 127 | L3: 27 | M3: 100 | N3: 22
A4: קומת עמודים | F4: 38 | G4: 30 | L4: 48 | M4: 4
A5: שטחי מגורים - קרקע | F5: 37 | G5: 34+21 | M5: 58
A6: פרגולה + מרפסת אחורית | G6: 31+13 | M6: 10
A7: פרגולה קדמית | E7: 12 | G7: 27+13 | H7: 14
A8: פרגולה צידית | G8: 91
A9: בליטת גג | G9: 25
A10: שרות (ממ"ד)
A11: קומת עמודים בהיתר
A12: קומת עמודים ללא היתר
A13: סה"כ מבנה | D13: =SUM(D3:D12) -> 151 | E13: =SUM(E4:E12) -> 12 | F13: =SUM(F3:F12) -> 110 | G13: =SUM(G3:G12) -> 178 | H13: =SUM(H3:H12) -> 28 | I13: =SUM(I3:I12) -> 39 | J13: =SUM(J3:J12) -> 14 | K13: =SUM(K3:K12) -> 127 | L13: =SUM(L3:L12) -> 75 | M13: =SUM(M3:M12) -> 172 | ... S13: =SUM(S3:S12) -> 0
A14: בהיתר | B14: חתימת רמ"י | C14: חתימת ועדה
A15: היתר שנת 73 | D15: 74.9 + 14.5
A16: היתר שנת 2012 | E16: 171.17
A17: היתר שנת 99
A18: היתר שנת 2000 - חקלאי
A19: היתר שנת 2000 - חקלאי
A20: היתר שנת 01- חקלאי
A24: בהתר | D24: =SUM(D17:D23) -> 0 | E24: =SUM(E17:E23) -> 0 | F24: =SUM(F15:F23) -> 0 | G24: =SUM(G15:G23) -> 0 | H24: =SUM(H15:H23) -> 0 | I24: =SUM(I15:I23) -> 0 | J24: =SUM(J15:J23) -> 0 | K24: =SUM(K15:K23) -> 0 | L24: =SUM(L15:L23) -> 0 | M24: =SUM(M15:M23) -> 0 | ... S24: =SUM(S15:S23) -> 0
A25: פערים | D25: =D13-D24 -> 151 | E25: =E13-E24 -> 12 | F25: =F13-F24 -> 110 | G25: =G13-G24 -> 178 | H25: =H13-H24 -> 28 | I25: =I13-I24 -> 39 | J25: =J13-J24 -> 14 | K25: =K13-K24 -> 127 | ... S25: =S13-S24 -> 0
A27: פער מרפסות | D27: =D8+D7 -> 0
E28: =E3*9300*5%*7 -> 332010
E29: =375-E24-F24-I24 -> 375
A31: דמי היתר ששולמו
A32: בית 1 | E32: =-D13 -> -151
A33: בית 2 | E33: =-E13 -> -12
A34: מחסן | E34: =I24 -> 0
A35: סה"כ | E35: =SUM(E31:E34) -> -163
A36: היוון 3.75 | E36: 375
A37: סה"כ מטרים | E37: =SUM(E35:E36) -> 212
A38: קיים | E38: =-E24-F24-I24 -> 0
A39: נותרו לבניה | E39: =SUM(E37:E38) -> 212
A43: פערים בית מגורים
A44: קומה תחתונה | D44: היתר | E44: בפועל | F44: הפרש
A45: מגורים | F45: =E45-D45 -> 0
A46: מקלט | F46: =E46-D46 -> 0
A47: סה"כ קומת קרקע | D47: =SUM(D45:D46) -> 0 | E47: =SUM(E45:E46) -> 0 | F47: =E47-D47 -> 0
A49: קומה עליונה | D49: היתר | E49: בפועל | F49: הפרש
A50: מגורים | F50: =E50-D50 -> 0
...

Sheet ניתוח איזור לעסקאות דמה
B2: שומת
B3: שווי מ"ר אקו'
B4: אחוז שנתי
B5: שנים להיוון
B6: שווי עדכני
B7: שווי לשומה | C7: =P21 -> 11000
B9: תחשיב לפי מכירות בהרחבה
B10: תאריך | C10: גו"ח | D10: מחיר עסקה | E10: שטח המגרש | F10: שטח בנוי | G10: שנת בניה | H10: התאמה למועד קובע | I10: בניכוי יזמי 5% | J10: עלויות בניה למ"ר | K10: יתרה לקרע כולל | L10: שטח אקו' | M10: שווי מתואם כולל מעמ ופיתוח
B14: מס"ד | C14: גוש חלקה | D14: יום מכירה | E14: יישוב | F14: תמורה מוצהרת בש"ח | G14: בניכוי רווח יזמי 5% | H14: שנת בניה | I14: שטח מגרש | J14: שטח בנוי ע"פ היתר | K14: תרומת הבנוי | L14: שווי יתרת קרקע | M14: מקדם בתאמה לזמן | N14: שווי מגרש מתואם | O14: שטח מבונה אקו' | P14: שווי מ"ר מבונה אקו'
B15: 1 | C15: 005007-0090 | D15: 45963 | E15: נווה מבטח | F15: 5700000 | G15: =F15/1.05 -> 5428571.4 | H15: 1998 | I15: 801 | J15: 135 | K15: =J15*7500 -> 1012500 | L15: =G15-K15 -> 4416071.4 | M15: 1 | N15: =L15*M15 -> 4416071.4 | O15: =F32 -> 380.925 | P15: =N15/O15 -> 11593.021
B16: 2 | C16: 005007-0061 | D16: 45644 | E16: נווה מבטח | F16: 5600000 | G16: =F16/1.05 -> 5333333.3 | H16: 1994 | I16: 750 | J16: =186+5 -> 191 | K16: =J16*7000 -> 1337000 | L16: =G16-K16 -> 3996333.3 | M16: 1.07 | N16: =L16*M16 -> 4276076.7 | O16: =L32 -> 372 | P16: =N16/O16 -> 11494.83
B17: ממוצע | P17: =AVERAGE(P15:P16) -> 11543.925
B18: בהתאמה לבעלות /0.97 | P18: =P17/0.97 -> 11900.954
B19: מקדם התאמה לנחלה | P19: 0.9
B20: שווי מ"ר לנחלה | P20: =P18*P19 -> 10710.858
B21: לשומה | P21: 11000
C25: ניתוח שטח אקו' מס"ד 1 | G25: שטח מגרש | I25: ניתוח שטח אקו' מס"ד 1 | M25: שטח מגרש
C26: מהות | D26: שטח | E26: מקדם | F26: סה"כ | G26: =I15 -> 801 | I26: מהות | J26: שטח | K26: מקדם | L26: סה"כ | M26: =I16 -> 750
C27: עיקרי | D27: 225 | E27: 1 | F27: =E27*D27 -> 225 | I27: עיקרי | J27: 225 | K27: 1 | L27: =K27*J27 -> 225
C28: ממ"ד | D28: 5 | E28: 0.9 | F28: =E28*D28 -> 4.5 | I28: ממ"ד | J28: 5 | K28: 0.9 | L28: =K28*J28 -> 4.5
C29: יתרת שירות | D29: 22.5 | E29: 0.5 | F29: =E29*D29 -> 11.25 | I29: יתרת שירות | J29: 22.5 | K29: 0.5 | L29: =K29*J29 -> 11.25
C30: תכסית | D30: =G26*30% -> 240.3 | E30: - | F30: - | I30: תכסית | J30: =M26*30% -> 225 | K30: - | L30: -
C31: חצר | D31: =G26-D30 -> 560.7 | E31: 0.25 | F31: =E31*D31 -> 140.175 | I31: חצר | J31: =M26-J30 -> 525 | K31: 0.25 | L31: =K31*J31 -> 131.25
C32: סה"כ שטח אקו' | F32: =SUM(F27:F31) -> 380.925 | I32: סה"כ שטח אקו' | L32: =SUM(L27:L31) -> 372

Sheet תבעות
A2: מקור | B2: מס' תבע | C2: תאריך | D2: זכויות
A3: XPLAN | B3: 634-0829846 | C3: 45344 | D3: 500 | E3: פל"ח
A4: גובמאפ | B4: 634-0454967 | C4: 44271 | D4: 3.5 | E4: בתים | F4: פיצול
A5: גובמאפ | B5: 3/222/06/6 | C5: 40000 | D5: 2.5 | E5: בתים
A6: גובמאפ | B6: 222/03/6 | C6: 33248 | D6: 2 | E6: בתים

Sheet גיליון1
B2: טבלאת סיכום עלויות דמי שימוש
B3: דמי שימוש | C3: מגורים | E3: פרגולות
B4: בית ראשון - מבנה 1 | C4: 0 | E4: 0
B5: בית שני - מבנה 4 | C5: 140000 | E5: =6000*2 -> 12000
B6: בית שלישי - מבנה 1 עבור 100 מ"ר | C6: =46500*7 -> 325500 | E6: 0
B7: בית רביעי - מבנה 2 | C7: =13000*7 -> 91000 | E7: =4000*7 -> 28000
B8: בית חמישי - מבנה 5 | C8: =65000*7 -> 455000 | E8: 50000 | J8: V
B9: טבלאת סיכום עלויות הסדרה | J9: X
B10: דמי היתר - להסדרה | C10: מ"ר לתש' עיקרי | D10: תשלום עיקרי | E10: מ"ר פרגולות | F10: תשלום פרגולות
B11: בית ראשון - מבנה 1 | C11: =197-160 -> 37 | D11: =C11*6605 -> 244385 | E11: 35 | F11: =E11*6605/2 -> 115587.5
B12: בית שני - מבנה 4 | C12: 0 | D12: 0 | E12: =147+24-160 -> 11 | F12: =E12*6605/2 -> 36327.5
B13: בית שלישי - מבנה 1 | C13: יוסדר כמבנה אחד עם הבית הראשון
B14: בית רביעי - מבנה 2 | C14: מומלץ לפינוי / הסרה
B15: בית חמישי - מבנה 5 | C15: יוסדר כבית שלישי - יוצג מטה
B17: טבלאת סיכום עלויות
B18: דמי שימוש - 7 שנים | C18: מגורים | E18: פרגולות
B19: בית ראשון - מבנה 1 | C19: 0 | E19: 0
B20: בית שני - מבנה 4 | C20: 70000 | E20: =6000*7 -> 42000
B21: בית שלישי - מבנה 1 | C21: =46500*7 -> 325500 | E21: 0
B22: בית רביעי - מבנה 2 | C22: =13000*7 -> 91000 | E22: =4000*7 -> 28000
B23: בית חמישי - מבנה 5 | C23: =65000*7 -> 455000 | E23: =7000*7 -> 49000
B25: דמי היתר - להסדרה | C25: מ"ר לתש' עיקרי | D25: תשלום עיקרי | E25: מ"ר פרגולות | F25: תשלום פרגולות
B26: בית ראשון - מבנה 1 | C26: =197-160 -> 37 | D26: =C26*6605 -> 244385 | E26: 35 | F26: =E26*6605/2 -> 115587.5
B27: בית שני - מבנה 4 | C27: 0 | D27: =C27*6605 -> 0 | E27: =147+24-160 -> 11 | F27: =E27*6605/2 -> 36327.5
B28: בית שלישי - מבנה 1 | C28: יוסדר כמבנה אחד עם הבית הראשון
B29: בית רביעי - מבנה 2 | C29: 0 | D29: 0 | E29: 0 | F29: 0
B30: בית חמישי - מבנה 5 | C30: 0 | D30: 0 | E30: =139+31-160 -> 10 | F30: =E30*6605/2 -> 33025
B35: טבלאת סיכום עלויות בית שלישי
B36: הדרך אל הבית השלישי | C36: מגורים | E36: פרגולות
B37: עלויות הסדרה | C37: ע"פ שלב 1 - 1,100,000 ₪
B38: היוון 3.75% דמי חכירה | C38: ע"פ שלב 2 - 260,000 ₪
B39: תב"ע | C39: שכ"ט בעלי מקצוע
B40: היתר בניה - דמי היתר | C40: דמי היתר 455,000 ₪ + היטל השבחה

Sheet בקרה
A2: תב"עות | B2: פלח
B3: מגורים
N7: חריגה מקו
A8: עדיפות לאומית | N8: גבול
A9: סיווג | D9: קישור לפרק 4.2 סימן א רשימת איזורי עדיפות | N9: בניין
N10: לא
A15: מיפוי | B15: חריגה מקווים
A19: מבנים | B19: חריגה מקו | C19: היתר | D19: גודל קיים | E19: גודל בהיתר | F19: שימוש | G19: מקדם | H19: שווי שימוש | I19: שיעור דמי שימוש | J19: דמי שימוש לשנה | K19: שיעור דמי היתר | L19: דמי היתר
A20: מבנה 1 - בית ראשון | H20: ='תחשיב לפי שווי שומה (2)'!B8 -> 11000 | I20: 0 | J20: =D20*G20*H20*I20 -> 0 | K20: 0.51 | L20: ='[1]תחשיב לפי שווי שומה (2)'!$B$26*G20 -> 0
A21: מבנה 1 - פרגולה | H21: =H20 -> 11000 | I21: 0 | J21: =D21*G21*H21*I21 -> 0 | K21: 0.51 | L21: ='[1]תחשיב לפי שווי שומה (2)'!$B$26*G21 -> 0
A22: מבנה 7 - יח"ד שניה | H22: =H21 -> 11000 | I22: 0.05 | J22: =D22*G22*H22*I22 -> 0 | K22: 0.51 | L22: ='[1]תחשיב לפי שווי שומה (2)'!$B$26*G22 -> 0
A23: מבנה 4 - יח"ד שלישית | H23: =H22 -> 11000 | I23: 0.05 | J23: =D23*G23*H23*I23 -> 0 | K23: 0.51 | L23: ='[1]תחשיב לפי שווי שומה (2)'!$B$26*G23 -> 0
A24: מבנה 4 - פל"ח | I24: 0.05 | J24: =D24*G24*H24*I24 -> 0 | K24: 0.51 | L24: =H24*K24 -> 0
