Workbook

Sheet תחשיב לפי שווי שומה (2)
A2: מ"ר אקו' נחלה היוון מלא 3 דונם | B2: ='מ"ר אקו'' נחלה'!I14 -> 1022.5
A3: מ"ר אקו' נחלה היוון מלא 2.5 דונם | B3: ='מ"ר אקו'' נחלה'!D14 -> 972.5
A4: מ"ר אקו' פוטנציאל | B4: ='מ"ר אקו'' נחלה'!D28 -> 144.55
A5: דמי היתר שנרכשו | B5: ='מ"ר אקו'' נחלה'!D38 -> 106
A6: מ"ר אקו' נחלה 3.75% | B6: ='מ"ר אקו'' נחלה'!D70 -> 806.25
A7: מ"ר אקו' מגרש מפוצל | B7: ='מ"ר אקו'' נחלה'!D57 -> 286.8 | C7: מ"ר ל-29.75% | D7: ='מ"ר אקו'' נחלה'!I50 -> 207.5
A8: שווי מ"ר אקו' מגורים | B8: ='ניתוח איזור לעסקאות דמה'!C7 -> 18000 | C8: שווי מ"ר משרדים | D8: 2500
C9: שווי מ"ר אחסנה | D9: ='ניתוח איזור לעסקאות דמה'!#REF! -> #REF! | E9: 1.17
B10: מ"ר אקו' | C10: דמי חכירה/ פיצול | D10: עלות אקו' | E10: מע"מ | F10: בש"ח | G10: בניכוי פיתוח
A11: היוון 3.75% | B11: =B6 -> 806.25 | C11: 0.0375 | D11: =C11*B11 -> 30.234375 | E11: 1 | F11: =D11*$B$8*E11 -> 544218.75 | G11: ='מ"ר אקו'' נחלה'!D71*-3.75% -> -6562.5 | H11: =SUM(F11:G11) -> 537656.25
A12: פיצול - חלק בהנחה | B12: =D7 -> 207.5 | C12: 0.2925 | D12: =C12*B12 -> 60.69375 | E12: 1 | F12: =D12*$B$8*E12 -> 1092487.5 | G12: =-'מ"ר אקו'' נחלה'!D58*C12 -> -29250 | H12: =SUM(F12:G12) -> 1063237.5
A13: פיצול חלק ללא הנחה | B13: =B7-B12 -> 79.3 | C13: 0.33 | D13: =C13*B13 -> 26.169 | E13: 1 | F13: =D13*$B$8*E13 -> 471042 | G13: =G12*53/245 -> -6327.551 | H13: =SUM(F13:G13) -> 464714.45
A14: סה"כ פיצול | B14: =SUM(B12:B13) -> 286.8 | F14: =SUM(F12:F13) -> 1563529.5 | H14: =SUM(H12:H13) -> 1527951.9
A15: היטל השבחה על פיצול | B15: ='מ"ר אקו'' נחלה'!I50 -> 207.5 | C15: =C35 -> 0.425 | D15: =B15*C15 -> 88.1875 | E15: 1 | F15: =D15*$B$8 -> 1587375
A16: דמי רכישה | B16: =B3+B4-B5 -> 1011.05 | C16: 0.33 | D16: =C16*B16 -> 333.6465 | E16: 1 | F16: =D16*$B$8*E16 -> 6005637 | G16: =-'מ"ר אקו'' נחלה'!D15*C16 -> -81510 | H16: =SUM(F16:G16) -> 5924127
A17: דמי היתר 1 מ"ר מגורים | B17: 1 | C17: 0.91 | D17: =C17*B17 -> 0.91 | E17: 1 | F17: 1486
A18: דמי היתר 1 מ"ר שירות | B18: 0.5 | C18: 0.91 | D18: =C18*B18 -> 0.455 | E18: 1 | F18: =F17/2 -> 743 | G18: =F18*#REF!*5%*1.17 -> #REF!
A19: דמי היתר 1 מ"ר מרתף | B19: 0.7 | C19: 0.91 | D19: =C19*B19 -> 0.637 | E19: 1 | F19: =D19*$B$8*E19 -> 11466
A20: היוון 1 מ"ר חצר נוספים | B20: 0.075 | C20: 0.91 | D20: =C20*B20 -> 0.06825 | E20: 1 | F20: =D20*$B$8*E20 -> 1228.5
A21: דמי שימוש משרדים 1 מ"ר לשנה | B21: 1 | C21: 0.05 | D21: =C21*B21 -> 0.05 | E21: 1 | F21: =D21*$D$8*E21 -> 125
A22: דמי היתר בריכה 1 מ"ר | B22: 0.3 | C22: 0.91 | D22: =C22*B22 -> 0.273 | E22: 1 | F22: =D22*$B$8*E22 -> 4914
A23: דמי היתר משרד פלח | B23: 1 | C23: 0.91 | D23: =C23*B23 -> 0.91 | E23: 1 | F23: =E23*D23*$D$8 -> 2275
A24: דמי שימוש 1 מ"ר למגורים | B24: 1 | C24: 0.05 | D24: =C24*B24 -> 0.05 | E24: 1 | F24: =D24*E24*B8 -> 900
A27: מחשבון רמ"י
A29: היטל השבחה פיצול בית שלישי (מגרש ראשון)
B30: עבור מגרש 350 | C30: מקדם | D30: עבור 1 מ"ר אקו'
A31: אחרי מגרש מפוצל | B31: ='מ"ר אקו'' נחלה'!D57*'תחשיב לפי שווי שומה (2)'!$B$8 -> 5162400 | C31: 1 | D31: =C31*$B$8 -> 18000
A32: לפני חצר שולית | B32: =350*$B$8*C32 -> 945000 | C32: 0.15 | D32: =C32*$B$8 -> 2700
A34: השבחה | B34: =B31-B32 -> 4217400 | C34: =C31-C32 -> 0.85 | D34: =C34*$B$8 -> 15300
A35: היטל | B35: =B34*50% -> 2108700 | C35: =C34*50% -> 0.425 | D35: =C35*$B$8 -> 7650
A37: היטל השבחה פיצול בית שני (מגרש שני)
B38: עבור מגרש 350 | C38: מקדם | D38: עבור 1 מ"ר אקו'
A39: אחרי מגרש מפוצל | B39: ='מ"ר אקו'' נחלה'!D57*'תחשיב לפי שווי שומה (2)'!$B$8 -> 5162400 | C39: 1 | D39: =C39*$B$8 -> 18000
A40: לפני מגרש לא מפוצל | B40: =B39*70% -> 3613680 | C40: 0.7 | D40: =C40*$B$8 -> 12600
A42: השבחה | B42: =B39-B40 -> 1548720 | C42: =C39-C40 -> 0.3 | D42: =C42*$B$8 -> 5400
A43: היטל | B43: =B42*50% -> 774360 | C43: =C42*50% -> 0.15 | D43: =C43*$B$8 -> 2700

Sheet סיכום עלויות פיצולים
H9: סיכום עלויות פיצול/ים לאחר הסדרה
H10: סוג תשלום | J10: פיצול בית קיים | L10: פיצול מגרש ריק + בית קיים | N10: דמי רכישה
H12: דמי היוון 3.75%/33% | J12: =240000 -> 240000 | L12: =240000 -> 240000 | N12: 2700000
H14: תשלום בעבור פיצול | J14: =1000000 -> 1000000 | L14: 1730000 | N14: -
H16: מס רכישה | J16: =(J14+J12)*0.06 -> 74400 | L16: =(L14+L12)*0.06 -> 118200 | N16: =N12*0.06 -> 162000
H18: דמי היתר לרכוש במשק | J18: - | L18: 144000 | N18: -
H20: סה"כ | J20: =SUM(J12:K19) -> 1314400 | L20: =SUM(L12:M19) -> 2232200 | N20: =SUM(N12:O19) -> 2862000
H22: היטל השבחה - בעת מכר | J22: 500000 | L22: 1500000 | N22: כמפורט בכל אפשרות

Sheet מ"ר אקו' נחלה
A2: גודל חלקת מגורים (להיוון) | B2: 2500 | C2: לפי שומת חכמון | F2: גודל חלקת מגורים (להיוון) | G2: 3000
B3: מ"ר | C3: מקדם | D3: אקו' | G3: מ"ר | H3: מקדם | I3: אקו'
A4: עיקרי | B4: 450 | C4: 1 | D4: =C4*B4 -> 450 | F4: =A4 -> עיקרי | G4: =B4 -> 450 | H4: =C4 -> 1 | I4: =H4*G4 -> 450
A5: מרחבים מוגנים | B5: 25 | C5: 0.9 | D5: =C5*B5 -> 22.5 | F5: =A5 -> מרחבים מוגנים | G5: =B5 -> 25 | H5: =C5 -> 0.9 | I5: =H5*G5 -> 22.5
A6: יתרת ש"ש | B6: 125 | C6: 0.4 | D6: =C6*B6 -> 50 | F6: =A6 -> יתרת ש"ש | G6: =B6 -> 125 | H6: =C6 -> 0.4 | I6: =H6*G6 -> 50
A7: מבנה עזר - יתרת שטח | C7: 0.5 | D7: =C7*B7 -> 0 | F7: =A7 -> מבנה עזר - יתרת שטח | G7: =B7 -> 0 | H7: =C7 -> 0.5 | I7: =H7*G7 -> 0
A8: סה"כ תכסית | B8: =SUM(B4:B7) -> 600 | F8: סה"כ תכסית | G8: =SUM(G4:G7) -> 600
A9: סה"כ חצר | B9: =B2-B8 -> 1900 | F9: סה"כ חצר | G9: =G2-G8 -> 2400
A10: חצר אפקטיבית | B10: 1000 | C10: 0.25 | D10: =C10*B10 -> 250 | F10: חצר אפקטיבית | G10: =B10 -> 1000 | H10: 0.25 | I10: =H10*G10 -> 250
A11: יתרת חצר | B11: 1000 | C11: 0.2 | D11: =C11*B11 -> 200 | F11: יתרת חצר | G11: =B11 -> 1000 | H11: 0.2 | I11: =H11*G11 -> 200
F12: חצר רחוקה מאוד | G12: 500 | H12: 0.1 | I12: =G12*H12 -> 50
A13: סה"כ מ"ר אקו' | B13: =SUM(B4:B11) -> 5100 | D13: =SUM(D4:D12) -> 972.5 | F13: סה"כ מ"ר אקו' | G13: =SUM(G4:G11) -> 5600 | I13: =SUM(I4:I12) -> 1022.5
A14: סה"כ מ"ר אקו' מעוגל | D14: =D13 -> 972.5 | F14: סה"כ מ"ר אקו' מעוגל | I14: =I13 -> 1022.5
A15: עלויות פיתוח | D15: 247000 | F15: עלויות פיתוח | I15: 263000
A17: פוטנציאל | B17: 2500 | C17: לפי ברנס
B18: מ"ר | C18: מקדם | D18: אקו'
A19: עיקרי | B19: 85 | C19: 1 | D19: =C19*B19 -> 85
A20: ממ"ד | B20: 12 | C20: 0.9 | D20: =C20*B20 -> 10.8
A21: ש"ש עיליים | B21: 47.5 | C21: 0.5 | D21: =C21*B21 -> 23.75
A22: ש"ש תת"ק | B22: 180 | C22: 0.3 | D22: =C22*B22 -> 54
H24: =876+73 -> 949
A25: הפסד חצר שולית | B25: -145 | C25: 0.2 | D25: =B25*C25 -> -29 | H25: =H24+137 -> 1086
A27: דחיה למימוש
A28: סה"כ מ"ר אקו' מעוגל | D28: =SUM(D19:D27) -> 144.55
A30: דמי היתר שנרכשו
A31: גודל בית ראשון בהיתר | D31: 186
A32: שטח פטור | D32: 160
A33: שטח שנרכש | D33: =D31-D32 -> 26
A34: גודל בית שני בהיתר | D34: 240
A35: שטח פטור | D35: 160
A36: שטח שנרכש | D36: =D34-D35 -> 80
A38: סה"כ שטח שנרכש | D38: =D36+D33 -> 106
A41: סה"כ שטח אקו' לחישוב דמי רכישה | D41: =D14+D28-D38 -> 1011.05
A46: מגרש מפוצל הרחבת אביגדור רק במקום 180 220 עיקרי
A47: גודל מגרש | B47: 350 | C47: לפי שומת זיו כהן בשפיר | F47: חלק ה29.25% | J47: שויי מ"ר
A48: מגורים עיקרי בהרחבה | B48: 220 | C48: 1 | D48: =B48*C48 -> 220 | F48: =A48 -> מגורים עיקרי בהרחבה | G48: 160 | H48: 1 | I48: =G48*H48 -> 160
A49: שירות - מרתף | B49: 40 | C49: 0.5 | D49: =B49*C49 -> 20 | F49: חצר | G49: =B47-G48 -> 190 | H49: 0.25 | I49: =G49*H49 -> 47.5
A50: מרחבים מוגנים | B50: 12 | C50: 0.9 | D50: =B50*C50 -> 10.8 | F50: מ"ר אקו' שנכלל בהנחה | I50: =I48+I49 -> 207.5 | J50: ='תחשיב לפי שווי שומה (2)'!B8 -> 18000 | K50: =I50*J50 -> 3735000 | L50: 0.2925 | M50: =K50*L50 -> 1092487.5
A51: מסחן | B51: 11 | C51: 0.5 | D51: =B51*C51 -> 5.5 | F51: מ"ר אקו' שלא נכלל בהנחה | I51: =D57-I50 -> 79.3 | J51: =J50 -> 18000 | K51: =I51*J51 -> 1427400 | L51: 0.33 | M51: =K51*L51 -> 471042
A52: סככת חניה | B52: 30 | C52: 0.35 | D52: =B52*C52 -> 10.5 | M52: =SUM(M50:M51) -> 1563529.5
...

Sheet ניתוח איזור לעסקאות דמה
B2: שומת
B3: שווי מ"ר אקו'
B4: אחוז שנתי
B5: שנים להיוון
B6: שווי עדכני
B7: שווי לשומה | C7: =F54 -> 18000
B9: תחשיב לפי מכירות בהרחבה
B10: תאריך | C10: גו"ח | D10: מחיר עסקה | E10: שטח המגרש | F10: שטח בנוי | G10: שנת בניה | H10: התאמה למועד קובע | I10: בניכוי יזמי 5% | J10: עלויות בניה למ"ר | K10: יתרה לקרע כולל | L10: שטח אקו' | M10: שווי מתואם כולל מעמ ופיתוח
E47: שווי מר"מ שומה הרחבה | F47: 18000
E48: שנים | F48: 1.25
E49: מקדם לשנה | F49: 1.07
E50: מקדם משוקלל | F50: =F49^F48 -> 1.0882526
E51: שווי מתואם | F51: =F50*F47 -> 19588.547
E52: מקדם לשומה | F52: 0.9
E53: שווי מתואם | F53: =F52*F51 -> 17629.692
E54: לשומה | F54: 18000

Sheet חישוב גדלי בתים
A2: קיים | B2: חתימת רמ"י | C2: חתימת ועדה | D2: מבנה 1 - בית מגורים
A3: מפת מדידה - מפרט רמ"י | D3: 427
A4: קומת עמודים
A5: שטחי מגורים - קרקע | D5: 116
A6: פרגולה + מרפסת אחורית | D6: 18
A7: פרגולה קדמית
A8: פרגולה צידית
A9: בליטת גג
A10: שרות (ממ"ד)
A11: קומת עמודים בהיתר
A12: קומת עמודים ללא היתר
A13: סה"כ מבנה | D13: =SUM(D4:D12) -> 134 | E13: =SUM(E4:E12) -> 0 | F13: =SUM(F3:F12) -> 0 | G13: =SUM(G3:G12) -> 0 | H13: =SUM(H3:H12) -> 0 | I13: =SUM(I3:I12) -> 0 | J13: =SUM(J3:J12) -> 0 | K13: =SUM(K3:K12) -> 0 | L13: =SUM(L3:L12) -> 0 | M13: =SUM(M3:M12) -> 0 | ... S13: =SUM(S3:S12) -> 0
A14: בהיתר | B14: חתימת רמ"י | C14: חתימת ועדה
A15: היתר שנת 78 | E15: 93.5
A16: היתר שנת 98 - חלקאי
A17: היתר שנת 99 | D17: 117.64
A18: היתר שנת 2000 - חקלאי
A19: היתר שנת 2000 - חקלאי
A20: היתר שנת 01- חקלאי
A24: בהתר | D24: =SUM(D17:D23) -> 117.64 | E24: =SUM(E17:E23) -> 0 | F24: =SUM(F15:F23) -> 0 | G24: =SUM(G15:G23) -> 0 | H24: =SUM(H15:H23) -> 0 | I24: =SUM(I15:I23) -> 0 | J24: =SUM(J15:J23) -> 0 | K24: =SUM(K15:K23) -> 0 | L24: =SUM(L15:L23) -> 0 | M24: =SUM(M15:M23) -> 0 | ... S24: =SUM(S15:S23) -> 0
A25: פערים | D25: =D13-D24 -> 16.36 | E25: =E13-E24 -> 0 | F25: =F13-F24 -> 0 | G25: =G13-G24 -> 0 | H25: =H13-H24 -> 0 | I25: =I13-I24 -> 0 | J25: =J13-J24 -> 0 | K25: =K13-K24 -> 0 | ... S25: =S13-S24 -> 0
A27: פער מרפסות | D27: =D8+D7 -> 0
E28: =E3*9300*5%*7 -> 0
E29: =375-E24-F24-I24 -> 375
A31: דמי היתר ששולמו
A32: בית 1 | E32: =-D13 -> -134
A33: בית 2 | E33: =-E13 -> 0
A34: מחסן | E34: =I24 -> 0
A35: סה"כ | E35: =SUM(E31:E34) -> -134
A36: היוון 3.75 | E36: 375
A37: סה"כ מטרים | E37: =SUM(E35:E36) -> 241
A38: קיים | E38: =-E24-F24-I24 -> 0
A39: נותרו לבניה | E39: =SUM(E37:E38) -> 241
A43: פערים בית מגורים
A44: קומה תחתונה | D44: היתר | E44: בפועל | F44: הפרש
A45: מגורים | F45: =E45-D45 -> 0
A46: מקלט | F46: =E46-D46 -> 0
A47: סה"כ קומת קרקע | D47: =SUM(D45:D46) -> 0 | E47: =SUM(E45:E46) -> 0 | F47: =E47-D47 -> 0
A49: קומה עליונה | D49: היתר | E49: בפועל | F49: הפרש
A50: מגורים | F50: =E50-D50 -> 0
...

Sheet תבעות
A2: מקור | B2: מס' תבע | C2: תאריך | D2: זכויות
A3: תבע עכשיו | B3: חש/15/10 | C3: 37847 | D3: 500 | E3: פל"ח
B4: חש/12/21 | C4: 35761 | D4: 0.12 | E4: בריכה
A5: גובמאפ | B5: חש/11/10 | C5: 33528 | D5: 2.5 | E5: בתים | F5: 450
A6: גובמאפ | B6: חש/10/10 | C6: 32524 | D6: 2 | E6: בתים | F6: + 30 מ"ר ש"ש לכל יח"ד | G6: חניה + מרתף
A7: שומת רמי | B7: חש/7/21 | C7: 29958 | D7: 2 | E7: בתים | F7: 350
B8: חש/5/21 | C8: 28117 | D8: 2 | E8: בתים | F8: 300

Sheet גיליון1
B2: טבלאת סיכום עלויות דמי שימוש
B3: דמי שימוש | C3: מגורים | E3: פרגולות
B4: בית ראשון - מבנה 1 | C4: 0 | E4: 0
B5: בית שני - מבנה 4 | C5: 140000 | E5: =6000*2 -> 12000
B6: בית שלישי - מבנה 1 עבור 100 מ"ר | C6: =46500*7 -> 325500 | E6: 0
B7: בית רביעי - מבנה 2 | C7: =13000*7 -> 91000 | E7: =4000*7 -> 28000
B8: בית חמישי - מבנה 5 | C8: =65000*7 -> 455000 | E8: 50000 | J8: V
B9: טבלאת סיכום עלויות הסדרה | J9: X
B10: דמי היתר - להסדרה | C10: מ"ר לתש' עיקרי | D10: תשלום עיקרי | E10: מ"ר פרגולות | F10: תשלום פרגולות
B11: בית ראשון - מבנה 1 | C11: =197-160 -> 37 | D11: =C11*6605 -> 244385 | E11: 35 | F11: =E11*6605/2 -> 115587.5
B12: בית שני - מבנה 4 | C12: 0 | D12: 0 | E12: =147+24-160 -> 11 | F12: =E12*6605/2 -> 36327.5
B13: בית שלישי - מבנה 1 | C13: יוסדר כמבנה אחד עם הבית הראשון
B14: בית רביעי - מבנה 2 | C14: מומלץ לפינוי / הסרה
B15: בית חמישי - מבנה 5 | C15: יוסדר כבית שלישי - יוצג מטה
B17: טבלאת סיכום עלויות
B18: דמי שימוש - 7 שנים | C18: מגורים | E18: פרגולות
B19: בית ראשון - מבנה 1 | C19: 0 | E19: 0
B20: בית שני - מבנה 4 | C20: 70000 | E20: =6000*7 -> 42000
B21: בית שלישי - מבנה 1 | C21: =46500*7 -> 325500 | E21: 0
B22: בית רביעי - מבנה 2 | C22: =13000*7 -> 91000 | E22: =4000*7 -> 28000
B23: בית חמישי - מבנה 5 | C23: =65000*7 -> 455000 | E23: =7000*7 -> 49000
B25: דמי היתר - להסדרה | C25: מ"ר לתש' עיקרי | D25: תשלום עיקרי | E25: מ"ר פרגולות | F25: תשלום פרגולות
B26: בית ראשון - מבנה 1 | C26: =197-160 -> 37 | D26: =C26*6605 -> 244385 | E26: 35 | F26: =E26*6605/2 -> 115587.5
B27: בית שני - מבנה 4 | C27: 0 | D27: =C27*6605 -> 0 | E27: =147+24-160 -> 11 | F27: =E27*6605/2 -> 36327.5
B28: בית שלישי - מבנה 1 | C28: יוסדר כמבנה אחד עם הבית הראשון
B29: בית רביעי - מבנה 2 | C29: 0 | D29: 0 | E29: 0 | F29: 0
B30: בית חמישי - מבנה 5 | C30: 0 | D30: 0 | E30: =139+31-160 -> 10 | F30: =E30*6605/2 -> 33025
B35: טבלאת סיכום עלויות בית שלישי
B36: הדרך אל הבית השלישי | C36: מגורים | E36: פרגולות
B37: עלויות הסדרה | C37: ע"פ שלב 1 - 1,100,000 ₪
B38: היוון 3.75% דמי חכירה | C38: ע"פ שלב 2 - 260,000 ₪
B39: תב"ע | C39: שכ"ט בעלי מקצוע
B40: היתר בניה - דמי היתר | C40: דמי היתר 455,000 ₪ + היטל השבחה

Sheet בקרה
A2: תב"עות | B2: פלח
B3: מגורים
N7: חריגה מקו
A8: עדיפות לאומית | N8: גבול
A9: סיווג | D9: קישור לפרק 4.2 סימן א רשימת איזורי עדיפות | N9: בניין
N10: לא
A15: מיפוי | B15: חריגה מקווים
A19: מבנים | B19: חריגה מקו | C19: היתר | D19: גודל קיים | E19: גודל בהיתר | F19: שימוש | G19: מקדם | H19: שווי שימוש | I19: שיעור דמי שימוש | J19: דמי שימוש לשנה | K19: שיעור דמי היתר | L19: דמי היתר
A20: מבנה 1 - בית ראשון | H20: ='תחשיב לפי שווי שומה (2)'!B8 -> 18000 | I20: 0 | J20: =D20*G20*H20*I20 -> 0 | K20: 0.51 | L20: ='[1]תחשיב לפי שווי שומה (2)'!$B$26*G20 -> 0
A21: מבנה 1 - פרגולה | H21: =H20 -> 18000 | I21: 0 | J21: =D21*G21*H21*I21 -> 0 | K21: 0.51 | L21: ='[1]תחשיב לפי שווי שומה (2)'!$B$26*G21 -> 0
A22: מבנה 7 - יח"ד שניה | H22: =H21 -> 18000 | I22: 0.05 | J22: =D22*G22*H22*I22 -> 0 | K22: 0.51 | L22: ='[1]תחשיב לפי שווי שומה (2)'!$B$26*G22 -> 0
A23: מבנה 4 - יח"ד שלישית | H23: =H22 -> 18000 | I23: 0.05 | J23: =D23*G23*H23*I23 -> 0 | K23: 0.51 | L23: ='[1]תחשיב לפי שווי שומה (2)'!$B$26*G23 -> 0
A24: מבנה 4 - פל"ח | I24: 0.05 | J24: =D24*G24*H24*I24 -> 0 | K24: 0.51 | L24: =H24*K24 -> 0
